Workbook

Sheet 05-01-2026 
A3: FV | E3: rto: 210 | F3: 46027 | I3: COMPRA
A5: CANTIDAD | B5: UNIDAD | C5: PRODUCTO | D5: PRECIO | E5: TOTAL | F5: TOTAL + IVA | I5: PRECIO | J5: TOTAL | K5: DIFERENCIA
A6: 1 | B6: CAJÓN | C6: HUEVOS | D6: 52000 | E6: =A6*D6 -> 52000 | F6: =E6*1.21 -> 62920 | I6: 45000 | J6: =I6*A6 -> 45000 | K6: =F6-J6 -> 17920
A7: 4 | B7: CAJA | C7: MANZANA VERDE | D7: 77000 | E7: =A7*D7 -> 308000 | F7: =E7*1.105 -> 340340 | I7: 38000 | J7: =I7*A7 -> 152000 | K7: =F7-J7 -> 188340
A8: 2 | B8: CAJÓN | C8: DURAZNO | D8: 42000 | E8: =A8*D8 -> 84000 | F8: =E8*1.105 -> 92820 | I8: 38000 | J8: =I8*A8 -> 76000 | K8: =F8-J8 -> 16820
A9: 2 | B9: CAJA | C9: MELÓN | D9: 30000 | E9: =A9*D9 -> 60000 | F9: =E9*1.105 -> 66300 | I9: 22000 | J9: =I9*A9 -> 44000 | K9: =F9-J9 -> 22300
A10: 30 | B10: KG | C10: SANDÍA | D10: 1500 | E10: =A10*D10 -> 45000 | F10: =E10*1.105 -> 49725 | I10: 600 | J10: =I10*A10 -> 18000 | K10: =F10-J10 -> 31725
A11: 4 | B11: CAJA | C11: BANANA | D11: 46000 | E11: =A11*D11 -> 184000 | F11: =E11*1.105 -> 203320 | I11: 37000 | J11: =I11*A11 -> 148000 | K11: =F11-J11 -> 55320
A12: 2 | B12: CAJÓN | C12: NARANJA | D12: 23000 | E12: =A12*D12 -> 46000 | F12: =E12*1.105 -> 50830 | I12: 13000 | J12: =I12*A12 -> 26000 | K12: =F12-J12 -> 24830
A13: 2 | B13: CAJÓN | C13: CIRUELAS | D13: 45000 | E13: =A13*D13 -> 90000 | F13: =E13*1.105 -> 99450 | I13: 38000 | J13: =I13*A13 -> 76000 | K13: =F13-J13 -> 23450
A14: 1 | B14: CAJÓN | C14: LIMÓN | D14: 48000 | E14: =A14*D14 -> 48000 | F14: =E14*1.105 -> 53040 | I14: 40000 | J14: =I14*A14 -> 40000 | K14: =F14-J14 -> 13040
A15: 1 | B15: CAJÓN | C15: MORRÓN ROJO | D15: 20000 | E15: =A15*D15 -> 20000 | F15: =E15*1.105 -> 22100 | I15: 15000 | J15: =I15*A15 -> 15000 | K15: =F15-J15 -> 7100
A16: 1 | B16: CAJÓN | C16: MORRÓN VERDE | D16: 19000 | E16: =A16*D16 -> 19000 | F16: =E16*1.105 -> 20995 | I16: 14000 | J16: =I16*A16 -> 14000 | K16: =F16-J16 -> 6995
A17: 2 | B17: CAJÓN | C17: ZAPALLITO REDONDO | D17: 13000 | E17: =A17*D17 -> 26000 | F17: =E17*1.105 -> 28730 | I17: 10000 | J17: =I17*A17 -> 20000 | K17: =F17-J17 -> 8730
A18: 2 | B18: PAQUETE | C18: BROTES DE SOJA | D18: 3000 | E18: =A18*D18 -> 6000 | F18: =E18*1.105 -> 6630 | I18: 1800 | J18: =I18*A18 -> 3600 | K18: =F18-J18 -> 3030
... A26: 2 | B26: KG | C26: JENGIBRE | D26: 5000 | E26: =A26*D26 -> 10000 | F26: =E26*1.105 -> 11050 | I26: 4000 | J26: =I26*A26 -> 8000 | K26: =F26-J26 -> 3050
A27: 15 | B27: UNIDAD | C27: PALTA | D27: 1300 | E27: =A27*D27 -> 19500 | F27: =E27*1.105 -> 21547.5 | I27: =50000/70 -> 714.28571 | J27: =I27*A27 -> 10714.286 | K27: =F27-J27 -> 10833.214
A28: 6 | B28: BANDEJA | C28: ARÁNDANOS | D28: 2500 | E28: =A28*D28 -> 15000 | F28: =E28*1.105 -> 16575 | I28: =16000/12 -> 1333.3333 | J28: =I28*A28 -> 8000 | K28: =F28-J28 -> 8575
A29: 5 | B29: KG | C29: CHAMPIÑÓN | D29: 20000 | E29: =A29*D29 -> 100000 | F29: =E29*1.105 -> 110500 | I29: =75000/5 -> 15000 | J29: =I29*A29 -> 75000 | K29: =F29-J29 -> 35500
A30: 2 | B30: CAJON | C30: TOMATE REDONDO | D30: 32000 | E30: =A30*D30 -> 64000 | F30: =E30*1.105 -> 70720 | G30: BOLSA | J30: =I30*A30 -> 0 | K30: =F30-J30 -> 70720
A31: 1 | B31: CAJA | C31: BANANA | D31: 46000 | E31: =A31*D31 -> 46000 | F31: =E31*1.105 -> 50830 | G31: BOLSA | J31: =I31*A31 -> 0 | K31: =F31-J31 -> 50830
A32: 0.5 | B32: CAJON | C32: HUEVOS | D32: 52000 | E32: =A32*D32 -> 26000 | F32: =E32*1.21 -> 31460 | G32: BOLSA | J32: =I32*A32 -> 0 | K32: =F32-J32 -> 31460
A33: 1 | B33: CAJON | C33: TOMATE CHERRY | D33: 35000 | E33: =A33*D33 -> 35000 | F33: =E33*1.105 -> 38675 | G33: BOLSA | J33: =I33*A33 -> 0 | K33: =F33-J33 -> 38675
A34: 1 | B34: CAJON | C34: PEPINO | D34: 16000 | E34: =A34*D34 -> 16000 | F34: =E34*1.105 -> 17680 | G34: BOLSA | J34: =I34*A34 -> 0 | K34: =F34-J34 -> 17680
A35: 1 | B35: CAJON | C35: MORRON VERDE | D35: 19000 | E35: =A35*D35 -> 19000 | F35: =E35*1.105 -> 20995 | G35: BOLSA | J35: =I35*A35 -> 0 | K35: =F35-J35 -> 20995
A36: 1 | B36: CAJON | C36: MORRON ROJO | D36: 20000 | E36: =A36*D36 -> 20000 | F36: =E36*1.105 -> 22100 | G36: BOLSA | J36: =I36*A36 -> 0 | K36: =F36-J36 -> 22100
A37: 1 | B37: CAJON | C37: LIMON | D37: 48000 | E37: =A37*D37 -> 48000 | F37: =E37*1.105 -> 53040 | G37: BOLSA | J37: =I37*A37 -> 0 | K37: =F37-J37 -> 53040
A38: 1 | B38: CAJON | C38: MANZANA VERDE | D38: 77000 | E38: =A38*D38 -> 77000 | F38: =E38*1.105 -> 85085 | G38: BOLSA PROPIA | J38: =I38*A38 -> 0 | K38: =F38-J38 -> 85085
E40: =SUM(E6:E38) -> 1723500 | F40: =SUM(F6:F38) -> 1912657.5 | K40: =SUM(K6:K38) -> 949343.21 | L40: =K40/F40 -> 0.49634773
A43: BRASOV | D43: rto: 1 | E43: 46027 | I43: COMPRA
A45: CANTIDAD | B45: UNIDAD | C45: PRODUCTO | D45: PRECIO | E45: TOTAL | I45: PRECIO | J45: TOTAL | K45: DIFERENCIA
A46: 2 | B46: UNIDAD | C46: APIO | D46: 1500 | E46: =A46*D46 -> 3000 | I46: 1000 | J46: =I46*A46 -> 2000 | K46: =E46-J46 -> 1000
A47: 1 | B47: BANDEJA | C47: CHERRY | D47: 17500 | E47: =A47*D47 -> 17500 | I47: 13000 | J47: =I47*A47 -> 13000 | K47: =E47-J47 -> 4500
A48: 2 | B48: ATADO | C48: CIBOULETTE | D48: 3000 | E48: =A48*D48 -> 6000 | I48: 2000 | J48: =I48*A48 -> 4000 | K48: =E48-J48 -> 2000
A49: 2 | B49: CAJA | C49: LIMÓN | D49: 45000 | E49: =A49*D49 -> 90000 | I49: 40000 | J49: =I49*A49 -> 80000 | K49: =E49-J49 -> 10000
A50: 2 | B50: CAJÓN | C50: NARANJA | D50: 16000 | E50: =A50*D50 -> 32000 | I50: 13000 | J50: =I50*A50 -> 26000 | K50: =E50-J50 -> 6000
A51: 1 | B51: CAJÓN | C51: LECHUGA MORADA | D51: 12000 | E51: =A51*D51 -> 12000 | I51: 7000 | J51: =I51*A51 -> 7000 | K51: =E51-J51 -> 5000
A52: 1 | B52: CAJA | C52: PALTA | D52: 60000 | E52: =A52*D52 -> 60000 | I52: 50000 | J52: =I52*A52 -> 50000 | K52: =E52-J52 -> 10000
A53: 2 | B53: ATADO | C53: PEREJIL | D53: 4000 | E53: =A53*D53 -> 8000 | I53: 2000 | J53: =I53*A53 -> 4000 | K53: =E53-J53 -> 4000
A54: 1 | B54: CAJÓN | C54: TOMATE REDONDO | D54: 35000 | E54: =A54*D54 -> 35000 | I54: 30000 | J54: =I54*A54 -> 30000 | K54: =E54-J54 -> 5000
...

Sheet 06-01-2026 
A3: FV | E3: rto: 211 | F3: 46028 | I3: COMPRA
A5: CANTIDAD | B5: UNIDAD | C5: PRODUCTO | D5: PRECIO | E5: TOTAL | F5: TOTAL + IVA | I5: PRECIO | J5: TOTAL | K5: DIFERENCIA
A6: 5 | B6: ATADO | C6: ALBAHACA | D6: 1000 | E6: =A6*D6 -> 5000 | F6: =E6*1.105 -> 5525 | I6: =3500/6 -> 583.33333 | J6: =I6*A6 -> 2916.6667 | K6: =F6-J6 -> 2608.3333
A7: 10 | B7: ATADO | C7: ROMERO | D7: 3000 | E7: =A7*D7 -> 30000 | F7: =E7*1.105 -> 33150 | I7: 1000 | J7: =I7*A7 -> 10000 | K7: =F7-J7 -> 23150
A8: 10 | B8: ATADO | C8: TOMILLO | D8: 3000 | E8: =A8*D8 -> 30000 | F8: =E8*1.105 -> 33150 | I8: 2000 | J8: =I8*A8 -> 20000 | K8: =F8-J8 -> 13150
A9: 2 | B9: CAJA | C9: MANZANA VERDE | D9: 77000 | E9: =A9*D9 -> 154000 | F9: =E9*1.105 -> 170170 | I9: 38000 | J9: =I9*A9 -> 76000 | K9: =F9-J9 -> 94170
A10: 1 | B10: CAJON | C10: CIRUELAS | D10: 45000 | E10: =A10*D10 -> 45000 | F10: =E10*1.105 -> 49725 | I10: 38000 | J10: =I10*A10 -> 38000 | K10: =F10-J10 -> 11725
A11: 1 | B11: CAJON | C11: NARANJA | D11: 23000 | E11: =A11*D11 -> 23000 | F11: =E11*1.105 -> 25415 | I11: 18000 | J11: =I11*A11 -> 18000 | K11: =F11-J11 -> 7415
A12: 2 | B12: CAJA | C12: BANANA | D12: 46000 | E12: =A12*D12 -> 92000 | F12: =E12*1.105 -> 101660 | I12: 36000 | J12: =I12*A12 -> 72000 | K12: =F12-J12 -> 29660
A13: 1 | B13: CAJON | C13: TOMATE REDONDO | D13: 32000 | E13: =A13*D13 -> 32000 | F13: =E13*1.105 -> 35360 | I13: 28000 | J13: =I13*A13 -> 28000 | K13: =F13-J13 -> 7360
A14: 1 | B14: CAJA | C14: MANZANA VERDE | D14: 77000 | E14: =A14*D14 -> 77000 | F14: =E14*1.105 -> 85085 | G14: BOLSA | I14: 0 | J14: =I14*A14 -> 0 | K14: =F14-J14 -> 85085
A15: 1 | B15: CAJA | C15: BANANA | D15: 46000 | E15: =A15*D15 -> 46000 | F15: =E15*1.105 -> 50830 | G15: BOLSA | I15: 0 | J15: =I15*A15 -> 0 | K15: =F15-J15 -> 50830
A16: 1 | B16: CAJON | C16: TOMATE REDONDO | D16: 32000 | E16: =A16*D16 -> 32000 | F16: =E16*1.105 -> 35360 | G16: BOLSA PROPIA | I16: 0 | J16: =I16*A16 -> 0 | K16: =F16-J16 -> 35360
E18: =SUM(E6:E16) -> 566000 | F18: =SUM(F6:F16) -> 625430 | K18: =SUM(K6:K16) -> 360513.33 | L18: =K18/F18 -> 0.57642475
A22: RAKUS CAFE - PADUA | D22: rto: 12 | E22: 46028
A24: CANTIDAD | B24: UNIDAD | C24: PRODUCTO | D24: PRECIO | E24: TOTAL | I24: PRECIO | J24: TOTAL | K24: DIFERENCIA
A25: 1 | B25: KG | C25: REMOLACHA | D25: 1800 | E25: =A25*D25 -> 1800 | I25: 1000 | J25: =I25*A25 -> 1000 | K25: =E25-J25 -> 800
A26: 1 | B26: CAJON | C26: HUEVO N1 | D26: 54000 | E26: =A26*D26 -> 54000 | I26: 45000 | J26: =I26*A26 -> 45000 | K26: =E26-J26 -> 9000
A27: 1 | B27: UNIDAD | C27: REPOLLO BLANCO | D27: 2000 | E27: =A27*D27 -> 2000 | I27: 1000 | J27: =I27*A27 -> 1000 | K27: =E27-J27 -> 1000
A28: 10 | B28: UNIDAD | C28: PALTA | D28: 1400 | E28: =A28*D28 -> 14000 | I28: 781 | J28: =I28*A28 -> 7810 | K28: =E28-J28 -> 6190
A29: 1 | B29: ATADO | C29: MENTA | D29: 3000 | E29: =A29*D29 -> 3000 | I29: 2000 | J29: =I29*A29 -> 2000 | K29: =E29-J29 -> 1000
A30: 0.5 | B30: KG | C30: JENGIBRE | D30: 5000 | E30: =A30*D30 -> 2500 | I30: 4000 | J30: =I30*A30 -> 2000 | K30: =E30-J30 -> 500
A31: 1 | B31: KG | C31: LIMA | D31: 4000 | E31: =A31*D31 -> 4000 | I31: 3000 | J31: =I31*A31 -> 3000 | K31: =E31-J31 -> 1000
A32: 1 | B32: CAJON | C32: NARANJA | D32: 20000 | E32: =A32*D32 -> 20000 | I32: 18000 | J32: =I32*A32 -> 18000 | K32: =E32-J32 -> 2000
A33: 1 | B33: BOLSA | C33: PAPA | D33: 16000 | E33: =A33*D33 -> 16000 | I33: 13000 | J33: =I33*A33 -> 13000 | K33: =E33-J33 -> 3000
A34: 1 | B34: ATADO | C34: PEREJIL | D34: 3500 | E34: =A34*D34 -> 3500 | I34: 2000 | J34: =I34*A34 -> 2000 | K34: =E34-J34 -> 1500
A35: 1 | B35: KG | C35: LEC CRIOLLA | D35: 3500 | E35: =A35*D35 -> 3500 | I35: 3000 | J35: =I35*A35 -> 3000 | K35: =E35-J35 -> 500
A36: 6 | B36: ATADOS | C36: RUCULA | D36: 800 | E36: =A36*D36 -> 4800 | I36: =5000/12 -> 416.66667 | J36: =I36*A36 -> 2500 | K36: =E36-J36 -> 2300
A37: 1 | B37: ATADO | C37: CEB VERDEO | D37: 4000 | E37: =A37*D37 -> 4000 | I37: 3000 | J37: =I37*A37 -> 3000 | K37: =E37-J37 -> 1000
A38: 4 | B38: CUBETAS | C38: ARANDANOS | D38: 2000 | E38: =A38*D38 -> 8000 | I38: 1333 | J38: =I38*A38 -> 5332 | K38: =E38-J38 -> 2668
A39: 3 | B39: ATADOS | C39: ALBAHACA | D39: 1000 | E39: =A39*D39 -> 3000 | I39: =3500/6 -> 583.33333 | J39: =I39*A39 -> 1750 | K39: =E39-J39 -> 1250
E41: =SUM(E25:E39) -> 144100 | K41: =SUM(K25:K39) -> 33708 | L41: =K41/E41 -> 0.23392089
A47: TOTAL DIA | B47: =E41+F18 -> 769530
A49: GANANCIA | B49: =K41+K18 -> 394221.33
A51: % | B51: =B49/B47 -> 0.51228845
A53: BULTOS COMPRADOS | C53: 18
B58: EFECTIVO | C58: MERCADO PAGO | D58: BANCO GALCIA | E58: BANCO RIO | F58: CHEQUES
B59: ='05-01-2026 '!B260 -> 2778150 | C59: ='05-01-2026 '!C260 -> 236114.49 | D59: ='05-01-2026 '!D260 -> 1401865.7 | F59: ='05-01-2026 '!F260 -> 8500000
A61: INGRESOS
A62: COBR. CTA. CTE | B62: 0 | C62: 0 | D62: 0 | E62: 0 | F62: 0
...

Sheet 07-01-2026 
A3: FV | E3: rto: 212 | F3: 46029 | I3: COMPRA
A5: CANTIDAD | B5: UNIDAD | C5: PRODUCTO | D5: PRECIO | E5: TOTAL | F5: TOTAL + IVA | I5: PRECIO | J5: TOTAL | K5: DIFERENCIA
A6: 0.5 | B6: CAJON | C6: HUEVO | D6: 52000 | E6: =A6*D6 -> 26000 | F6: =E6*1.21 -> 31460 | I6: 40000 | J6: =I6*A6 -> 20000 | K6: =F6-J6 -> 11460
A7: 3 | B7: CAJON | C7: CIRUELA | D7: 45000 | E7: =A7*D7 -> 135000 | F7: =E7*1.105 -> 149175 | I7: 39000 | J7: =I7*A7 -> 117000 | K7: =F7-J7 -> 32175
A8: 2 | B8: CAJA | C8: BANANA | D8: 46000 | E8: =A8*D8 -> 92000 | F8: =E8*1.105 -> 101660 | I8: 36000 | J8: =I8*A8 -> 72000 | K8: =F8-J8 -> 29660
A9: 3 | B9: CAJON | C9: NARANJA | D9: 23000 | E9: =A9*D9 -> 69000 | F9: =E9*1.105 -> 76245 | I9: 18000 | J9: =I9*A9 -> 54000 | K9: =F9-J9 -> 22245
A10: 3 | B10: CAJA | C10: MANZANA VERDE | D10: 77000 | E10: =A10*D10 -> 231000 | F10: =E10*1.105 -> 255255 | I10: 38000 | J10: =I10*A10 -> 114000 | K10: =F10-J10 -> 141255
A11: 4 | B11: CAJON | C11: DURAZNO | D11: 42000 | E11: =A11*D11 -> 168000 | F11: =E11*1.105 -> 185640 | I11: 30000 | J11: =I11*A11 -> 120000 | K11: =F11-J11 -> 65640
A12: 2 | B12: CAJA | C12: MELON | D12: 30000 | E12: =A12*D12 -> 60000 | F12: =E12*1.105 -> 66300 | I12: 22000 | J12: =I12*A12 -> 44000 | K12: =F12-J12 -> 22300
A13: 20 | B13: KG | C13: SANDIA | D13: 1500 | E13: =A13*D13 -> 30000 | F13: =E13*1.105 -> 33150 | I13: 600 | J13: =I13*A13 -> 12000 | K13: =F13-J13 -> 21150
A14: 3 | B14: CAJON | C14: TOMATE REDONDO | D14: 32000 | E14: =A14*D14 -> 96000 | F14: =E14*1.105 -> 106080 | I14: 20000 | J14: =I14*A14 -> 60000 | K14: =F14-J14 -> 46080
A15: 3 | B15: CAJON | C15: TOMATE CHEERY | D15: 35000 | E15: =A15*D15 -> 105000 | F15: =E15*1.105 -> 116025 | I15: 18000 | J15: =I15*A15 -> 54000 | K15: =F15-J15 -> 62025
A16: 1 | B16: CAJON | C16: NARANJA | D16: 23000 | E16: =A16*D16 -> 23000 | F16: =E16*1.105 -> 25415 | G16: BOLSA | J16: =I16*A16 -> 0 | K16: =F16-J16 -> 25415
A17: 1 | B17: CAJA | C17: BANANA | D17: 46000 | E17: =A17*D17 -> 46000 | F17: =E17*1.105 -> 50830 | G17: BOLSA | J17: =I17*A17 -> 0 | K17: =F17-J17 -> 50830
A18: 1 | B18: CAJA | C18: MANZANA VERDE | D18: 77000 | E18: =A18*D18 -> 77000 | F18: =E18*1.105 -> 85085 | G18: BOLSA | J18: =I18*A18 -> 0 | K18: =F18-J18 -> 85085
A19: 1 | B19: CAJON | C19: CIRUELA | D19: 45000 | E19: =A19*D19 -> 45000 | F19: =E19*1.105 -> 49725 | G19: BOLSA | J19: =I19*A19 -> 0 | K19: =F19-J19 -> 49725
A20: 1 | B20: CAJON | C20: TOMATE CHERRY | D20: 35000 | E20: =A20*D20 -> 35000 | F20: =E20*1.105 -> 38675 | G20: BOLSA | J20: =I20*A20 -> 0 | K20: =F20-J20 -> 38675
A21: 1 | B21: CAJA | C21: MELON | D21: 30000 | E21: =A21*D21 -> 30000 | F21: =E21*1.105 -> 33150 | G21: BOLSA | J21: =I21*A21 -> 0 | K21: =F21-J21 -> 33150
A22: 0.5 | B22: CAJON | C22: HUEVO | D22: 52000 | E22: =A22*D22 -> 26000 | F22: =E22*1.21 -> 31460 | G22: BOLSA | J22: =I22*A22 -> 0 | K22: =F22-J22 -> 31460
A23: 1 | B23: CAJON | C23: TOMATE REDONDO | D23: 32000 | E23: =A23*D23 -> 32000 | F23: =E23*1.105 -> 35360 | G23: BOLSA PROPIA | J23: =I23*A23 -> 0 | K23: =F23-J23 -> 35360
E25: =SUM(E6:E23) -> 1326000 | F25: =SUM(F6:F23) -> 1470690 | K25: =SUM(K6:K23) -> 803690 | L25: =K25/F25 -> 0.54647138
A29: HOGAR | D29: rto: 1 | E29: 46029
A31: CANTIDAD | B31: UNIDAD | C31: PRODUCTO | D31: PRECIO | E31: TOTAL | I31: PRECIO | J31: TOTAL | K31: DIFERENCIA
A32: 4 | B32: ATADOS | C32: ACELGA | D32: 1200 | E32: =A32*D32 -> 4800 | I32: 1000 | J32: =I32*A32 -> 4000 | K32: =E32-J32 -> 800
A33: 1 | B33: UNIDAD | C33: APIO | D33: 2000 | E33: =A33*D33 -> 2000 | I33: 1000 | J33: =I33*A33 -> 1000 | K33: =E33-J33 -> 1000
A34: 4 | B34: UNIDAD | C34: AJO | D34: 1200 | E34: =A34*D34 -> 4800 | I34: =28000/50 -> 560 | J34: =I34*A34 -> 2240 | K34: =E34-J34 -> 2560
A35: 4 | B35: KG | C35: BATATA | D35: 1500 | E35: =A35*D35 -> 6000 | I35: =11000/10 -> 1100 | J35: =I35*A35 -> 4400 | K35: =E35-J35 -> 1600
A36: 4 | B36: KG | C36: BONIATO | D36: 4000 | E36: =A36*D36 -> 16000 | I36: =35000/11 -> 3181.8182 | J36: =I36*A36 -> 12727.273 | K36: =E36-J36 -> 3272.7273
A37: 2 | B37: KG | C37: BERENJENA | D37: 1800 | E37: =A37*D37 -> 3600 | I37: =11000/9 -> 1222.2222 | J37: =I37*A37 -> 2444.4444 | K37: =E37-J37 -> 1155.5556
A38: 4 | B38: UNIDAD | C38: BROCOLI | D38: 2200 | E38: =A38*D38 -> 8800 | I38: 2000 | J38: =I38*A38 -> 8000 | K38: =E38-J38 -> 800
A39: 2 | B39: KG | C39: CHAUCHA | D39: 5000 | E39: =A39*D39 -> 10000 | I39: 3000 | J39: =I39*A39 -> 6000 | K39: =E39-J39 -> 4000
A40: 3 | B40: KG | C40: TOMATE CHERRY | D40: 3000 | E40: =A40*D40 -> 9000 | I40: 0 | J40: =I40*A40 -> 0 | K40: =E40-J40 -> 9000
A41: 4 | B41: ATADO | C41: ESPINACA | D41: 1500 | E41: =A41*D41 -> 6000 | I41: =6000/4 -> 1500 | J41: =I41*A41 -> 6000 | K41: =E41-J41 -> 0
A42: 2 | B42: KG | C42: MORRÓN ROJO | D42: 3500 | E42: =A42*D42 -> 7000 | I42: =15000/8 -> 1875 | J42: =I42*A42 -> 3750 | K42: =E42-J42 -> 3250
A43: 1 | B43: KG | C43: LECHUGA | D43: 3500 | E43: =A43*D43 -> 3500 | I43: =14000/5 -> 2800 | J43: =I43*A43 -> 2800 | K43: =E43-J43 -> 700
A44: 2 | B44: UNIDAD | C44: PALTA | D44: 1400 | E44: =A44*D44 -> 2800 | I44: =60000/70 -> 857.14286 | J44: =I44*A44 -> 1714.2857 | K44: =E44-J44 -> 1085.7143
A45: 6 | B45: ATADOS | C45: REMOLACHA | D45: 1700 | E45: =A45*D45 -> 10200 | I45: 1000 | J45: =I45*A45 -> 6000 | K45: =E45-J45 -> 4200
A46: 1 | B46: UNIDAD | C46: REPOLLO | D46: 2000 | E46: =A46*D46 -> 2000 | I46: 1000 | J46: =I46*A46 -> 1000 | K46: =E46-J46 -> 1000
A47: 4 | B47: ATADO | C47: RÚCULA | D47: 600 | E47: =A47*D47 -> 2400 | I47: =5000/12 -> 416.66667 | J47: =I47*A47 -> 1666.6667 | K47: =E47-J47 -> 733.33333
A48: 4 | B48: KG | C48: TOMATE | D48: 2400 | E48: =A48*D48 -> 9600 | I48: =20000/15 -> 1333.3333 | J48: =I48*A48 -> 5333.3333 | K48: =E48-J48 -> 4266.6667
...

Sheet 08-01-2026 
A3: FV | E3: rto: 213 | F3: 46030 | I3: COMPRA
A5: CANTIDAD | B5: UNIDAD | C5: PRODUCTO | D5: PRECIO | E5: TOTAL | F5: TOTAL + IVA | I5: PRECIO | J5: TOTAL | K5: DIFERENCIA
A6: 1 | B6: CAJON | C6: HUEVO | D6: 52000 | E6: =A6*D6 -> 52000 | F6: =E6*1.21 -> 62920 | I6: 45000 | J6: =I6*A6 -> 45000 | K6: =F6-J6 -> 17920
A7: 3 | B7: CAJA | C7: DURAZNO | D7: 42000 | E7: =A7*D7 -> 126000 | F7: =E7*1.105 -> 139230 | I7: 33000 | J7: =I7*A7 -> 99000 | K7: =F7-J7 -> 40230
A8: 3 | B8: CAJA | C8: BANANA | D8: 46000 | E8: =A8*D8 -> 138000 | F8: =E8*1.105 -> 152490 | I8: 36000 | J8: =I8*A8 -> 108000 | K8: =F8-J8 -> 44490
A9: 36 | B9: KG | C9: SANDIA | D9: 1500 | E9: =A9*D9 -> 54000 | F9: =E9*1.105 -> 59670 | I9: 600 | J9: =I9*A9 -> 21600 | K9: =F9-J9 -> 38070
A10: 3 | B10: CAJON | C10: MELON | D10: 30000 | E10: =A10*D10 -> 90000 | F10: =E10*1.105 -> 99450 | I10: 22000 | J10: =I10*A10 -> 66000 | K10: =F10-J10 -> 33450
A11: 3 | B11: CAJON | C11: NARANJA | D11: 23000 | E11: =A11*D11 -> 69000 | F11: =E11*1.105 -> 76245 | I11: 18000 | J11: =I11*A11 -> 54000 | K11: =F11-J11 -> 22245
A12: 2 | B12: CAJA | C12: UVA SUPERIOR NACIONAL | D12: 37000 | E12: =A12*D12 -> 74000 | F12: =E12*1.105 -> 81770 | I12: 27000 | J12: =I12*A12 -> 54000 | K12: =F12-J12 -> 27770
A13: 0.5 | B13: CAJON | C13: HUEVO | D13: 52000 | E13: =A13*D13 -> 26000 | F13: =E13*1.21 -> 31460 | G13: BOLSA | I13: 0 | J13: =I13*A13 -> 0 | K13: =F13-J13 -> 31460
A14: 1 | B14: CAJA | C14: BANANA | D14: 46000 | E14: =A14*D14 -> 46000 | F14: =E14*1.105 -> 50830 | G14: BOLSA | I14: 0 | J14: =I14*A14 -> 0 | K14: =F14-J14 -> 50830
A15: 1 | B15: CAJA | C15: UVA SUPERIOR NACIONAL | D15: 37000 | E15: =A15*D15 -> 37000 | F15: =E15*1.105 -> 40885 | G15: BOLSA | I15: 0 | J15: =I15*A15 -> 0 | K15: =F15-J15 -> 40885
A16: 1 | B16: CAJA | C16: DURAZNO | D16: 42000 | E16: =A16*D16 -> 42000 | F16: =E16*1.105 -> 46410 | G16: BOLSA | I16: 0 | J16: =I16*A16 -> 0 | K16: =F16-J16 -> 46410
E18: =SUM(E6:E16) -> 754000 | F18: =SUM(F6:F16) -> 841360 | K18: =SUM(K6:K17) -> 393760 | L18: =K18/F18 -> 0.46800418
A22: LA PIADINA | D22: rto: 3 | E22: 46030
A24: CANTIDAD | B24: UNIDAD | C24: PRODUCTO | D24: PRECIO | E24: TOTAL | I24: PRECIO | J24: TOTAL | K24: DIFERENCIA
A25: 1 | B25: KG | C25: UVA VERDE | D25: 4500 | E25: =A25*D25 -> 4500 | I25: 0 | J25: =I25*A25 -> 0 | K25: =E25-J25 -> 4500
A26: 2 | B26: KG | C26: BANANA | D26: 3000 | E26: =A26*D26 -> 6000 | I26: 0 | J26: =I26*A26 -> 0 | K26: =E26-J26 -> 6000
A27: 1.03 | B27: KG | C27: MANZANA | D27: 5000 | E27: =A27*D27 -> 5150 | I27: 5000 | J27: =I27*A27 -> 5150 | K27: =E27-J27 -> 0
A28: 1 | B28: KG | C28: FRUTILLA | D28: 9000 | E28: =A28*D28 -> 9000 | I28: 9000 | J28: =I28*A28 -> 9000 | K28: =E28-J28 -> 0
A29: 0.7 | B29: KG | C29: DURAZNO | D29: 4000 | E29: =A29*D29 -> 2800 | I29: 0 | J29: =I29*A29 -> 0 | K29: =E29-J29 -> 2800
A30: 1 | B30: KG | C30: NARANJA | D30: 1500 | E30: =A30*D30 -> 1500 | I30: 0 | J30: =I30*A30 -> 0 | K30: =E30-J30 -> 1500
A31: 3 | B31: BANDEJA | C31: ARANDANOS | D31: 2500 | E31: =A31*D31 -> 7500 | I31: =20000/12 -> 1666.6667 | J31: =I31*A31 -> 5000 | K31: =E31-J31 -> 2500
A32: 0.2 | B32: KG | C32: KIWI | D32: 11000 | E32: =A32*D32 -> 2200 | I32: =70000/7 -> 10000 | J32: =I32*A32 -> 2000 | K32: =E32-J32 -> 200
A33: 2 | B33: KG | C33: AJO | D33: 1200 | E33: =A33*D33 -> 2400 | I33: 560 | J33: =I33*A33 -> 1120 | K33: =E33-J33 -> 1280
E35: =SUM(E26:E33) -> 36550 | K35: =SUM(K25:K33) -> 18780 | L35: =K35/E35 -> 0.51381669
A38: PAULA CASERO | D38: rto: 2 | E38: 46030
A40: CANTIDAD | B40: UNIDAD | C40: PRODUCTO | D40: PRECIO | E40: TOTAL | I40: PRECIO | J40: TOTAL | K40: DIFERENCIA
A41: 1 | B41: BOLSA | C41: ANCO | D41: 14000 | E41: =A41*D41 -> 14000 | I41: 10000 | J41: =I41*A41 -> 10000 | K41: =E41-J41 -> 4000
A42: 1 | B42: BOLSA | C42: CEBOLLA | D42: 14000 | E42: =A42*D42 -> 14000 | I42: 9000 | J42: =I42*A42 -> 9000 | K42: =E42-J42 -> 5000
A43: 0.5 | B43: ATADO | C43: PUERRO | D43: 5500 | E43: =A43*D43 -> 2750 | I43: =2610*2 -> 5220 | J43: =I43*A43 -> 2610 | K43: =E43-J43 -> 140
A44: 2 | B44: KG | C44: ZUCCINI | D44: 1200 | E44: =A44*D44 -> 2400 | I44: =10000/14 -> 714.28571 | J44: =I44*A44 -> 1428.5714 | K44: =E44-J44 -> 971.42857
A45: 2.12 | B45: KG | C45: BERENJENA | D45: 2000 | E45: =A45*D45 -> 4240 | I45: 2000 | J45: =I45*A45 -> 4240 | K45: =E45-J45 -> 0
E47: =SUM(E41:E45) -> 37390 | K47: =SUM(K41:K45) -> 10111.429 | L47: =K47/E47 -> 0.27043136
A51: TOTAL DIA | B51: =F18+E35+E47 -> 915300
A53: GANANCIA | B53: =K47+K35+K18 -> 422651.43
A55: % | B55: =B53/B51 -> 0.46176273
A57: BULTOS COMPRADOS | C57: 31
B62: EFECTIVO | C62: MERCADO PAGO | D62: BANCO GALCIA | E62: BANCO RIO | F62: CHEQUES
B63: ='07-01-2026 '!B138 -> 2619750 | C63: ='07-01-2026 '!C138 -> 4083.6 | D63: ='07-01-2026 '!D138 -> 440685.67 | E63: ='07-01-2026 '!E138 -> 0 | F63: ='07-01-2026 '!F138 -> 8500000
...

Sheet 09-01-2026 
A3: FV | E3: rto: 214 | F3: 46031 | I3: COMPRA
A5: CANTIDAD | B5: UNIDAD | C5: PRODUCTO | D5: PRECIO | E5: TOTAL | F5: TOTAL + IVA | I5: PRECIO | J5: TOTAL | K5: DIFERENCIA
A6: 4 | B6: CAJA | C6: BANANA | D6: 46000 | E6: =A6*D6 -> 184000 | F6: =E6*1.105 -> 203320 | I6: 35000 | J6: =I6*A6 -> 140000 | K6: =F6-J6 -> 63320
A7: 4 | B7: CAJA | C7: PELON | D7: 42000 | E7: =A7*D7 -> 168000 | F7: =E7*1.105 -> 185640 | I7: 32000 | J7: =I7*A7 -> 128000 | K7: =F7-J7 -> 57640
A8: 2 | B8: CAJA | C8: CIRUELA RED | D8: 45000 | E8: =A8*D8 -> 90000 | F8: =E8*1.105 -> 99450 | I8: 45000 | J8: =I8*A8 -> 90000 | K8: =F8-J8 -> 9450
A9: 1 | B9: CAJON | C9: ZUCCINI | D9: 12000 | E9: =A9*D9 -> 12000 | F9: =E9*1.105 -> 13260 | I9: 8000 | J9: =I9*A9 -> 8000 | K9: =F9-J9 -> 5260
A10: 2 | B10: CAJA | C10: BANANA | D10: 46000 | E10: =A10*D10 -> 92000 | F10: =E10*1.105 -> 101660 | G10: BOLSA | J10: =I10*A10 -> 0 | K10: =F10-J10 -> 101660
A11: 1 | B11: CAJA | C11: PELON | D11: 42000 | E11: =A11*D11 -> 42000 | F11: =E11*1.105 -> 46410 | G11: BOLSA | J11: =I11*A11 -> 0 | K11: =F11-J11 -> 46410
A12: 1 | B12: CAJA | C12: CIRUELA RED | D12: 45000 | E12: =A12*D12 -> 45000 | F12: =E12*1.105 -> 49725 | G12: BOLSA | J12: =I12*A12 -> 0 | K12: =F12-J12 -> 49725
E14: =SUM(E6:E12) -> 633000 | F14: =SUM(F6:F12) -> 699465 | K14: =SUM(K6:K12) -> 333465 | L14: =K14/F14 -> 0.47674294
A17: BRASOV | D17: rto: 2 | E17: 46031 | I17: COMPRA
A19: CANTIDAD | B19: UNIDAD | C19: PRODUCTO | D19: PRECIO | E19: TOTAL | I19: PRECIO | J19: TOTAL | K19: DIFERENCIA
A20: 1 | B20: CAJA | C20: LIMON | D20: 46000 | E20: =A20*D20 -> 46000 | I20: 40000 | J20: =I20*A20 -> 40000 | K20: =E20-J20 -> 6000
A21: 1 | B21: CAJON | C21: NARANJA | D21: 22000 | E21: =A21*D21 -> 22000 | I21: 18000 | J21: =I21*A21 -> 18000 | K21: =E21-J21 -> 4000
A22: 0.5 | B22: CAJON | C22: MORRON ROJO | D22: 20000 | E22: =A22*D22 -> 10000 | I22: 12000 | J22: =I22*A22 -> 6000 | K22: =E22-J22 -> 4000
A23: 0.5 | B23: CAJON | C23: TOMATE REDONDO | D23: 35000 | E23: =A23*D23 -> 17500 | I23: 30000 | J23: =I23*A23 -> 15000 | K23: =E23-J23 -> 2500
A24: 1 | B24: CAJA | C24: PALTA | D24: 55000 | E24: =A24*D24 -> 55000 | I24: 35000 | J24: =I24*A24 -> 35000 | K24: =E24-J24 -> 20000
A25: 2 | B25: ATADO | C25: PEREJIL | D25: 4000 | E25: =A25*D25 -> 8000 | I25: 2000 | J25: =I25*A25 -> 4000 | K25: =E25-J25 -> 4000
A26: 2 | B26: ATADO | C26: CEB VERDEO | D26: 4000 | E26: =A26*D26 -> 8000 | I26: 3000 | J26: =I26*A26 -> 6000 | K26: =E26-J26 -> 2000
E28: =SUM(E20:E26) -> 166500 | K28: =SUM(K20:K26) -> 42500 | L28: =K28/E28 -> 0.25525526
A31: COMO SIEMPRE LAGUNA | D31: rto: 19 | E31: 46031
A33: CANTIDAD | B33: UNIDAD | C33: PRODUCTO | D33: PRECIO | E33: TOTAL | I33: PRECIO | J33: TOTAL | K33: DIFERENCIA
A34: 4 | B34: KG | C34: TOM PERITA | D34: 2800 | E34: =A34*D34 -> 11200 | I34: 3000 | J34: =I34*A34 -> 12000 | K34: =E34-J34 -> -800
A35: 1 | B35: UNIDAD | C35: APIO | D35: 1500 | E35: =A35*D35 -> 1500 | I35: 1000 | J35: =I35*A35 -> 1000 | K35: =E35-J35 -> 500
A36: 1 | B36: ATADO | C36: CILANTRO | D36: 2500 | E36: =A36*D36 -> 2500 | I36: 1500 | J36: =I36*A36 -> 1500 | K36: =E36-J36 -> 1000
A37: 1 | B37: ATADO | C37: CIBOULETTE | D37: 3000 | E37: =A37*D37 -> 3000 | I37: 2000 | J37: =I37*A37 -> 2000 | K37: =E37-J37 -> 1000
A38: 4.2 | B38: KG | C38: CEBOLLA MORADA | D38: 2200 | E38: =A38*D38 -> 9240 | I38: 1600 | J38: =I38*A38 -> 6720 | K38: =E38-J38 -> 2520
A39: 3 | B39: KG | C39: LIMA | D39: 3500 | E39: =A39*D39 -> 10500 | I39: 2500 | J39: =I39*A39 -> 7500 | K39: =E39-J39 -> 3000
A40: 3 | B40: KG | C40: LIMON | D40: 3000 | E40: =A40*D40 -> 9000 | I40: =35000/14 -> 2500 | J40: =I40*A40 -> 7500 | K40: =E40-J40 -> 1500
A41: 2 | B41: BOLSA | C41: PAPA GARLIC | D41: 21000 | E41: =A41*D41 -> 42000 | I41: 18000 | J41: =I41*A41 -> 36000 | K41: =E41-J41 -> 6000
A42: 12 | B42: UNIDAD | C42: PALTA | D42: 1400 | E42: =A42*D42 -> 16800 | I42: =60000/70 -> 857.14286 | J42: =I42*A42 -> 10285.714 | K42: =E42-J42 -> 6514.2857
A43: 0.25 | B43: KG | C43: FRUTILLA | D43: 6000 | E43: =A43*D43 -> 1500 | I43: 3500 | J43: =I43*A43 -> 875 | K43: =E43-J43 -> 625
A44: 4 | B44: UNIDAD | C44: AJO | D44: 1200 | E44: =A44*D44 -> 4800 | I44: 560 | J44: =I44*A44 -> 2240 | K44: =E44-J44 -> 2560
A45: 0.25 | B45: KG | C45: JENGIBRE | D45: 5000 | E45: =A45*D45 -> 1250 | I45: 4000 | J45: =I45*A45 -> 1000 | K45: =E45-J45 -> 250
A46: 1 | B46: ATADO | C46: TOMILLO | D46: 3000 | E46: =A46*D46 -> 3000 | I46: 2000 | J46: =I46*A46 -> 2000 | K46: =E46-J46 -> 1000
A47: 1 | B47: ATADO | C47: MENTA | D47: 3000 | E47: =A47*D47 -> 3000 | I47: 2000 | J47: =I47*A47 -> 2000 | K47: =E47-J47 -> 1000
A48: 1 | B48: ATADO | C48: PUERRO | D48: 5000 | E48: =A48*D48 -> 5000 | I48: 4000 | J48: =I48*A48 -> 4000 | K48: =E48-J48 -> 1000
A49: 3 | B49: ATADO | C49: ALBAHACA | D49: 1200 | E49: =A49*D49 -> 3600 | I49: 1000 | J49: =I49*A49 -> 3000 | K49: =E49-J49 -> 600
A50: 0.5 | B50: CAJON | C50: RUCULA | D50: 12000 | E50: =A50*D50 -> 6000 | I50: 6000 | J50: =I50*A50 -> 3000 | K50: =E50-J50 -> 3000
A51: 1 | B51: KG | C51: BATATA | D51: 1400 | E51: =A51*D51 -> 1400 | I51: =11000/10 -> 1100 | J51: =I51*A51 -> 1100 | K51: =E51-J51 -> 300
...

Sheet 12-01-2026 
A3: FV | E3: rto: 215 | F3: 46034 | I3: COMPRA
A5: CANTIDAD | B5: UNIDAD | C5: PRODUCTO | D5: PRECIO | E5: TOTAL | F5: TOTAL + IVA | I5: PRECIO | J5: TOTAL | K5: DIFERENCIA
A6: 4 | B6: CAJA | C6: BANANA | D6: 38000 | E6: =A6*D6 -> 152000 | F6: =E6*1.105 -> 167960 | I6: 30000 | J6: =I6*A6 -> 120000 | K6: =F6-J6 -> 47960
A7: 3 | B7: CAJON | C7: NARANJA | D7: 22000 | E7: =A7*D7 -> 66000 | F7: =E7*1.105 -> 72930 | I7: 18000 | J7: =I7*A7 -> 54000 | K7: =F7-J7 -> 18930
A8: 32 | B8: KG | C8: SANDIA | D8: 1200 | E8: =A8*D8 -> 38400 | F8: =E8*1.105 -> 42432 | G8: (11 KG X 4 ARANDANO) | I8: 800 | J8: =I8*A8 -> 25600 | K8: =F8-J8 -> 16832
A9: 3 | B9: CAJON | C9: MELON | D9: 28000 | E9: =A9*D9 -> 84000 | F9: =E9*1.105 -> 92820 | I9: 20000 | J9: =I9*A9 -> 60000 | K9: =F9-J9 -> 32820
A10: 2 | B10: CAJA | C10: MANZANA GRANNY | D10: 70000 | E10: =A10*D10 -> 140000 | F10: =E10*1.105 -> 154700 | I10: 42000 | J10: =I10*A10 -> 84000 | K10: =F10-J10 -> 70700
A11: 2 | B11: CAJA | C11: DURAZNO | D11: 35000 | E11: =A11*D11 -> 70000 | F11: =E11*1.105 -> 77350 | I11: 30000 | J11: =I11*A11 -> 60000 | K11: =F11-J11 -> 17350
A12: 2 | B12: CAJON | C12: UVA BLANCA | D12: 32000 | E12: =A12*D12 -> 64000 | F12: =E12*1.105 -> 70720 | I12: 27000 | J12: =I12*A12 -> 54000 | K12: =F12-J12 -> 16720
A13: 2 | B13: CAJA | C13: PELON | D13: 38000 | E13: =A13*D13 -> 76000 | F13: =E13*1.105 -> 83980 | I13: 30000 | J13: =I13*A13 -> 60000 | K13: =F13-J13 -> 23980
A14: 1 | B14: CAJON | C14: HUEVO | D14: 50000 | E14: =A14*D14 -> 50000 | F14: =E14*1.21 -> 60500 | I14: 38000 | J14: =I14*A14 -> 38000 | K14: =F14-J14 -> 22500
A15: 1 | B15: CAJON | C15: MORRON ROJO | D15: 20000 | E15: =A15*D15 -> 20000 | F15: =E15*1.105 -> 22100 | I15: 12000 | J15: =I15*A15 -> 12000 | K15: =F15-J15 -> 10100
A16: 1 | B16: CAJON | C16: MORRON VERDE | D16: 20000 | E16: =A16*D16 -> 20000 | F16: =E16*1.105 -> 22100 | I16: 15000 | J16: =I16*A16 -> 15000 | K16: =F16-J16 -> 7100
A17: 1 | B17: CAJON | C17: MORRON AMARILLO | D17: 30000 | E17: =A17*D17 -> 30000 | F17: =E17*1.105 -> 33150 | I17: 16000 | J17: =I17*A17 -> 16000 | K17: =F17-J17 -> 17150
A18: 15 | B18: UNIDAD | C18: PALTA | D18: 1300 | E18: =A18*D18 -> 19500 | F18: =E18*1.105 -> 21547.5 | I18: =60000/70 -> 857.14286 | J18: =I18*A18 -> 12857.143 | K18: =F18-J18 -> 8690.3571
A19: 1 | B19: CAJON | C19: BANANA | D19: 38000 | E19: =A19*D19 -> 38000 | F19: =E19*1.105 -> 41990 | G19: BOLSA | J19: =I19*A19 -> 0 | K19: =F19-J19 -> 41990
A20: 2 | B20: CAJON | C20: NARANJA | D20: 22000 | E20: =A20*D20 -> 44000 | F20: =E20*1.105 -> 48620 | G20: BOLSA | J20: =I20*A20 -> 0 | K20: =F20-J20 -> 48620
A21: 1 | B21: CAJON | C21: DURAZNO | D21: 35000 | E21: =A21*D21 -> 35000 | F21: =E21*1.105 -> 38675 | G21: BOLSA | J21: =I21*A21 -> 0 | K21: =F21-J21 -> 38675
A22: 1 | B22: CAJON | C22: PELON | D22: 38000 | E22: =A22*D22 -> 38000 | F22: =E22*1.105 -> 41990 | G22: BOLSA | J22: =I22*A22 -> 0 | K22: =F22-J22 -> 41990
A23: 1 | B23: CAJON | C23: UVA BLANCA | D23: 32000 | E23: =A23*D23 -> 32000 | F23: =E23*1.105 -> 35360 | G23: BOLSA PROPIA | J23: =I23*A23 -> 0 | K23: =F23-J23 -> 35360
E25: =SUM(E6:E23) -> 1016900 | F25: =SUM(F6:F23) -> 1128924.5 | K25: =SUM(K6:K23) -> 517467.36 | L25: =K25/F25 -> 0.45837198
A28: COMO SIEMPRE LAGUNA | D28: rto: 20 | E28: 46034
A30: CANTIDAD | B30: UNIDAD | C30: PRODUCTO | D30: PRECIO | E30: TOTAL | I30: PRECIO | J30: TOTAL | K30: DIFERENCIA
A31: 3 | B31: BOLSA | C31: PAPA GARLIC | D31: 23000 | E31: =A31*D31 -> 69000 | I31: 20000 | J31: =I31*A31 -> 60000 | K31: =E31-J31 -> 9000
A32: 1 | B32: CAJON | C32: TOM CHERRY | D32: 34000 | E32: =A32*D32 -> 34000 | I32: 26000 | J32: =I32*A32 -> 26000 | K32: =E32-J32 -> 8000
A33: 3 | B33: UNIDAD | C33: AJO | D33: 1200 | E33: =A33*D33 -> 3600 | I33: =30000/50 -> 600 | J33: =I33*A33 -> 1800 | K33: =E33-J33 -> 1800
A34: 3 | B34: UNIDAD | C34: MANGO | D34: 2200 | E34: =A34*D34 -> 6600 | I34: =15000/9 -> 1666.6667 | J34: =I34*A34 -> 5000 | K34: =E34-J34 -> 1600
A35: 1 | B35: CAJON | C35: RUCULA | D35: 12000 | E35: =A35*D35 -> 12000 | I35: 8000 | J35: =I35*A35 -> 8000 | K35: =E35-J35 -> 4000
A36: 1 | B36: KG | C36: CHAMPI | D36: 19000 | E36: =A36*D36 -> 19000 | I36: 16000 | J36: =I36*A36 -> 16000 | K36: =E36-J36 -> 3000
A37: 1 | B37: KG | C37: PORTO | D37: 20000 | E37: =A37*D37 -> 20000 | I37: 17000 | J37: =I37*A37 -> 17000 | K37: =E37-J37 -> 3000
A38: 2 | B38: ATADO | C38: ALBAHACA | D38: 1200 | E38: =A38*D38 -> 2400 | I38: =4000/6 -> 666.66667 | J38: =I38*A38 -> 1333.3333 | K38: =E38-J38 -> 1066.6667
A39: 1 | B39: ATADO | C39: ENELDO | D39: 3000 | E39: =A39*D39 -> 3000 | I39: 2000 | J39: =I39*A39 -> 2000 | K39: =E39-J39 -> 1000
A40: 0.5 | B40: CAJON | C40: NARANJA | D40: 22000 | E40: =A40*D40 -> 11000 | I40: 18000 | J40: =I40*A40 -> 9000 | K40: =E40-J40 -> 2000
A41: 0.5 | B41: CAJON | C41: POMELO | D41: 46000 | E41: =A41*D41 -> 23000 | I41: 40000 | J41: =I41*A41 -> 20000 | K41: =E41-J41 -> 3000
A42: 0.5 | B42: CAJON | C42: LIMON | D42: 46000 | E42: =A42*D42 -> 23000 | I42: 40000 | J42: =I42*A42 -> 20000 | K42: =E42-J42 -> 3000
E44: =SUM(E31:E42) -> 226600 | K44: =SUM(K31:K42) -> 40466.667 | L44: =K44/E44 -> 0.17858194
A48: PAULA | D48: rto: 3 | E48: 46031
A50: CANTIDAD | B50: UNIDAD | C50: PRODUCTO | D50: PRECIO | E50: TOTAL | I50: PRECIO | J50: TOTAL | K50: DIFERENCIA
A51: 1 | B51: BOLSA | C51: CEBOLLA | D51: 13000 | E51: =A51*D51 -> 13000 | I51: 10000 | J51: =I51*A51 -> 10000 | K51: =E51-J51 -> 3000
A52: 1 | B52: BOLSA | C52: PAPA GARLIC | D52: 20000 | E52: =A52*D52 -> 20000 | I52: 18000 | J52: =I52*A52 -> 18000 | K52: =E52-J52 -> 2000
...

Sheet 13-01-2026 
A3: FV | E3: rto: 216 | F3: 46035 | I3: COMPRA
A5: CANTIDAD | B5: UNIDAD | C5: PRODUCTO | D5: PRECIO | E5: TOTAL | F5: TOTAL + IVA | I5: PRECIO | J5: TOTAL | K5: DIFERENCIA
A6: 2 | B6: CAJON | C6: TOMATE | D6: 32000 | E6: =A6*D6 -> 64000 | F6: =E6*1.105 -> 70720 | I6: =55000/2 -> 27500 | J6: =I6*A6 -> 55000 | K6: =F6-J6 -> 15720
A7: 2 | B7: CAJON | C7: TOM CHERRY | D7: 30000 | E7: =A7*D7 -> 60000 | F7: =E7*1.105 -> 66300 | I7: 15000 | J7: =I7*A7 -> 30000 | K7: =F7-J7 -> 36300
A8: 1 | B8: CAJON | C8: BERENJENA | D8: 13000 | E8: =A8*D8 -> 13000 | F8: =E8*1.105 -> 14365 | I8: 8000 | J8: =I8*A8 -> 8000 | K8: =F8-J8 -> 6365
A9: 3 | B9: CAJA | C9: CIRUELA | D9: 32000 | E9: =A9*D9 -> 96000 | F9: =E9*1.105 -> 106080 | I9: 25000 | J9: =I9*A9 -> 75000 | K9: =F9-J9 -> 31080
A10: 1 | B10: CAJON | C10: NARANJA | D10: 22000 | E10: =A10*D10 -> 22000 | F10: =E10*1.105 -> 24310 | I10: 18000 | J10: =I10*A10 -> 18000 | K10: =F10-J10 -> 6310
A11: 2 | B11: CAJON | C11: MELON | D11: 28000 | E11: =A11*D11 -> 56000 | F11: =E11*1.105 -> 61880 | I11: 25000 | J11: =I11*A11 -> 50000 | K11: =F11-J11 -> 11880
A12: 1 | B12: CAJA | C12: MANZANA GRANNY | D12: 70000 | E12: =A12*D12 -> 70000 | F12: =E12*1.105 -> 77350 | I12: 44000 | J12: =I12*A12 -> 44000 | K12: =F12-J12 -> 33350
A13: 2 | B13: CAJA | C13: BANANA | D13: 38000 | E13: =A13*D13 -> 76000 | F13: =E13*1.105 -> 83980 | I13: 30000 | J13: =I13*A13 -> 60000 | K13: =F13-J13 -> 23980
A14: 1 | B14: CAJA | C14: DURAZNO | D14: 35000 | E14: =A14*D14 -> 35000 | F14: =E14*1.105 -> 38675 | I14: 30000 | J14: =I14*A14 -> 30000 | K14: =F14-J14 -> 8675
A15: 1 | B15: CAJON | C15: UVA | D15: 32000 | E15: =A15*D15 -> 32000 | F15: =E15*1.105 -> 35360 | I15: 27000 | J15: =I15*A15 -> 27000 | K15: =F15-J15 -> 8360
A16: 41.9 | B16: KG | C16: SANDIA | D16: 1200 | E16: =A16*D16 -> 50280 | F16: =E16*1.105 -> 55559.4 | I16: 0 | J16: =I16*A16 -> 0 | K16: =F16-J16 -> 55559.4
A17: 1 | B17: CAJON | C17: TOMATE | D17: 32000 | E17: =A17*D17 -> 32000 | F17: =E17*1.105 -> 35360 | G17: BOLSA | I17: 0 | J17: =I17*A17 -> 0 | K17: =F17-J17 -> 35360
A18: 1 | B18: CAJON | C18: TOM CHERRY | D18: 30000 | E18: =A18*D18 -> 30000 | F18: =E18*1.105 -> 33150 | G18: BOLSA | I18: 0 | J18: =I18*A18 -> 0 | K18: =F18-J18 -> 33150
A19: 1 | B19: CAJON | C19: BERENJENA | D19: 13000 | E19: =A19*D19 -> 13000 | F19: =E19*1.105 -> 14365 | G19: BOLSA | I19: 0 | J19: =I19*A19 -> 0 | K19: =F19-J19 -> 14365
E21: =SUM(E6:E19) -> 649280 | F21: =SUM(F6:F19) -> 717454.4 | K21: =SUM(K6:K19) -> 320454.4 | L21: =K21/F21 -> 0.44665473
A24: RAKUS | D24: rto: 14 | E24: 46035
A26: CANTIDAD | B26: UNIDAD | C26: PRODUCTO | D26: PRECIO | E26: TOTAL | I26: PRECIO | J26: TOTAL | K26: DIFERENCIA
A27: 1 | B27: BANDEJA | C27: FLORES | D27: 5500 | E27: =A27*D27 -> 5500 | I27: 4000 | J27: =I27*A27 -> 4000 | K27: =E27-J27 -> 1500
A28: 3 | B28: KG | C28: LEC CRIOLLA | D28: 4000 | E28: =A28*D28 -> 12000 | I28: =15000/5 -> 3000 | J28: =I28*A28 -> 9000 | K28: =E28-J28 -> 3000
A29: 1 | B29: ATADOS | C29: ROMERO | D29: 3000 | E29: =A29*D29 -> 3000 | I29: 2000 | J29: =I29*A29 -> 2000 | K29: =E29-J29 -> 1000
A30: 1 | B30: ATADOS | C30: TOMILLO | D30: 3000 | E30: =A30*D30 -> 3000 | I30: 2000 | J30: =I30*A30 -> 2000 | K30: =E30-J30 -> 1000
A31: 1 | B31: CAJON | C31: HUEVO | D31: 55000 | E31: =A31*D31 -> 55000 | I31: 45000 | J31: =I31*A31 -> 45000 | K31: =E31-J31 -> 10000
A32: 1 | B32: KG | C32: CHAMPI | D32: 18500 | E32: =A32*D32 -> 18500 | I32: 16000 | J32: =I32*A32 -> 16000 | K32: =E32-J32 -> 2500
A33: 1 | B33: KG | C33: TOM CHERRY | D33: 3000 | E33: =A33*D33 -> 3000 | I33: =15000/8 -> 1875 | J33: =I33*A33 -> 1875 | K33: =E33-J33 -> 1125
A34: 1 | B34: CAJA | C34: PALTA CHILE | D34: 75000 | E34: =A34*D34 -> 75000 | I34: 65000 | J34: =I34*A34 -> 65000 | K34: =E34-J34 -> 10000
A35: 16 | B35: ATADOS | C35: ALBAHACA | D35: 1000 | E35: =A35*D35 -> 16000 | I35: =6000/12 -> 500 | J35: =I35*A35 -> 8000 | K35: =E35-J35 -> 8000
A36: 10 | B36: UNIDAD | C36: AJO | D36: 1200 | E36: =A36*D36 -> 12000 | I36: 560 | J36: =I36*A36 -> 5600 | K36: =E36-J36 -> 6400
A37: 1 | B37: ATADOS | C37: CEB VERDEO | D37: 5000 | E37: =A37*D37 -> 5000 | I37: 4000 | J37: =I37*A37 -> 4000 | K37: =E37-J37 -> 1000
A38: 1 | B38: KG | C38: CEB MORADA | D38: 1600 | E38: =A38*D38 -> 1600 | I38: 1600 | J38: =I38*A38 -> 1600 | K38: =E38-J38 -> 0
A39: 1 | B39: BOLSA | C39: CEBOLLON | D39: 13000 | E39: =A39*D39 -> 13000 | I39: 9000 | J39: =I39*A39 -> 9000 | K39: =E39-J39 -> 4000
A40: 1 | B40: CAJON | C40: FRUTILLA | D40: 22000 | E40: =A40*D40 -> 22000 | I40: 20000 | J40: =I40*A40 -> 20000 | K40: =E40-J40 -> 2000
A41: 2 | B41: KG | C41: MORRON ROJO | D41: 2300 | E41: =A41*D41 -> 4600 | I41: =12000/8 -> 1500 | J41: =I41*A41 -> 3000 | K41: =E41-J41 -> 1600
A42: 1 | B42: BOLSA | C42: PAPA CEPILLADA | D42: 14000 | E42: =A42*D42 -> 14000 | I42: 12000 | J42: =I42*A42 -> 12000 | K42: =E42-J42 -> 2000
A43: 1 | B43: ATADOS | C43: REMOLACHA | D43: 2000 | E43: =A43*D43 -> 2000 | I43: 1500 | J43: =I43*A43 -> 1500 | K43: =E43-J43 -> 500
A44: 1 | B44: BOLSA | C44: ZANAHORIA | D44: 13000 | E44: =A44*D44 -> 13000 | I44: 10000 | J44: =I44*A44 -> 10000 | K44: =E44-J44 -> 3000
A45: 0.5 | B45: KG | C45: JENGIBRE | D45: 6500 | E45: =A45*D45 -> 3250 | I45: 5000 | J45: =I45*A45 -> 2500 | K45: =E45-J45 -> 750
A46: 2 | B46: CAJON | C46: NARANJA | D46: 22000 | E46: =A46*D46 -> 44000 | I46: 18000 | J46: =I46*A46 -> 36000 | K46: =E46-J46 -> 8000
A47: 1 | B47: CAJA | C47: LIMON | D47: 44000 | E47: =A47*D47 -> 44000 | I47: 35000 | J47: =I47*A47 -> 35000 | K47: =E47-J47 -> 9000
...

Sheet 14-01-2026 
A3: FV | E3: rto: 217 | F3: 46036 | I3: COMPRA
A5: CANTIDAD | B5: UNIDAD | C5: PRODUCTO | D5: PRECIO | E5: TOTAL | F5: TOTAL + IVA | I5: PRECIO | J5: TOTAL | K5: DIFERENCIA
A6: 5 | B6: CAJON | C6: NARANJA | D6: 22000 | E6: =A6*D6 -> 110000 | F6: =E6*1.105 -> 121550 | I6: 18000 | J6: =I6*A6 -> 90000 | K6: =F6-J6 -> 31550
A7: 2 | B7: CAJA | C7: MANZANA GRANNY | D7: 70000 | E7: =A7*D7 -> 140000 | F7: =E7*1.105 -> 154700 | I7: 42000 | J7: =I7*A7 -> 84000 | K7: =F7-J7 -> 70700
A8: 1 | B8: CAJA | C8: BANANA | D8: 38000 | E8: =A8*D8 -> 38000 | F8: =E8*1.105 -> 41990 | I8: 30000 | J8: =I8*A8 -> 30000 | K8: =F8-J8 -> 11990
A9: 1 | B9: CAJON | C9: NARANJA | D9: 22000 | E9: =A9*D9 -> 22000 | F9: =E9*1.105 -> 24310 | G9: BOLSA | I9: 0 | J9: =I9*A9 -> 0 | K9: =F9-J9 -> 24310
A10: 1 | B10: CAJA | C10: MANZANA GRANNY | D10: 70000 | E10: =A10*D10 -> 70000 | F10: =E10*1.105 -> 77350 | G10: BOLSA | I10: 0 | J10: =I10*A10 -> 0 | K10: =F10-J10 -> 77350
E12: =SUM(E6:E10) -> 380000 | F12: =SUM(F6:F10) -> 419900 | K12: =SUM(K6:K10) -> 215900 | L12: =K12/F12 -> 0.51417004
A15: HOGAR | D15: rto: 2 | E15: 46036
A17: CANTIDAD | B17: UNIDAD | C17: PRODUCTO | D17: PRECIO | E17: TOTAL | I17: PRECIO | J17: TOTAL | K17: DIFERENCIA
A18: 1 | B18: UNIDAD | C18: APIO | D18: 1500 | E18: =A18*D18 -> 1500 | I18: 1600 | J18: =I18*A18 -> 1600 | K18: =E18-J18 -> -100
A19: 3 | B19: UNIDAD | C19: AJO | D19: 1200 | E19: =A19*D19 -> 3600 | I19: 560 | J19: =I19*A19 -> 1680 | K19: =E19-J19 -> 1920
A20: 4 | B20: KG | C20: BATATA | D20: 1500 | E20: =A20*D20 -> 6000 | I20: 1100 | J20: =I20*A20 -> 4400 | K20: =E20-J20 -> 1600
A21: 4 | B21: KG | C21: BONIATO | D21: 3800 | E21: =A21*D21 -> 15200 | I21: 2500 | J21: =I21*A21 -> 10000 | K21: =E21-J21 -> 5200
A22: 4 | B22: KG | C22: BERENJENA | D22: 1600 | E22: =A22*D22 -> 6400 | I22: =9000/8 -> 1125 | J22: =I22*A22 -> 4500 | K22: =E22-J22 -> 1900
A23: 3 | B23: KG | C23: TOMATE CHERRY | D23: 2800 | E23: =A23*D23 -> 8400 | I23: =15000/8 -> 1875 | J23: =I23*A23 -> 5625 | K23: =E23-J23 -> 2775
A24: 4 | B24: ATADO | C24: ESPINACA | D24: 1700 | E24: =A24*D24 -> 6800 | I24: =7200/4 -> 1800 | J24: =I24*A24 -> 7200 | K24: =E24-J24 -> -400
A25: 2 | B25: KG | C25: MORRÓN ROJO | D25: 3000 | E25: =A25*D25 -> 6000 | I25: =12000/8 -> 1500 | J25: =I25*A25 -> 3000 | K25: =E25-J25 -> 3000
A26: 1 | B26: KG | C26: LECHUGA | D26: 3500 | E26: =A26*D26 -> 3500 | I26: 3000 | J26: =I26*A26 -> 3000 | K26: =E26-J26 -> 500
A27: 2 | B27: UNIDAD | C27: PALTA | D27: 1300 | E27: =A27*D27 -> 2600 | I27: =65000/80 -> 812.5 | J27: =I27*A27 -> 1625 | K27: =E27-J27 -> 975
A28: 0.5 | B28: ATADOS | C28: PEREJIL | D28: 3500 | E28: =A28*D28 -> 1750 | I28: 2000 | J28: =I28*A28 -> 1000 | K28: =E28-J28 -> 750
A29: 6 | B29: ATADOS | C29: REMOLACHA | D29: 2000 | E29: =A29*D29 -> 12000 | I29: 1400 | J29: =I29*A29 -> 8400 | K29: =E29-J29 -> 3600
A30: 4 | B30: ATADO | C30: RÚCULA | D30: 500 | E30: =A30*D30 -> 2000 | I30: 350 | J30: =I30*A30 -> 1400 | K30: =E30-J30 -> 600
A31: 4 | B31: KG | C31: TOMATE | D31: 2000 | E31: =A31*D31 -> 8000 | I31: =28000/15 -> 1866.6667 | J31: =I31*A31 -> 7466.6667 | K31: =E31-J31 -> 533.33333
A32: 4 | B32: KG | C32: ZAPALLITO | D32: 900 | E32: =A32*D32 -> 3600 | I32: =18000/14 -> 1285.7143 | J32: =I32*A32 -> 5142.8571 | K32: =E32-J32 -> -1542.8571
A33: 2 | B33: KG | C33: ZUCCINI | D33: 1000 | E33: =A33*D33 -> 2000 | I33: 2000 | J33: =I33*A33 -> 4000 | K33: =E33-J33 -> -2000
A34: 1 | B34: BOLSA | C34: ANCO | D34: 12000 | E34: =A34*D34 -> 12000 | I34: 9000 | J34: =I34*A34 -> 9000 | K34: =E34-J34 -> 3000
A35: 0.5 | B35: BOLSA | C35: CEBOLLA | D35: 13000 | E35: =A35*D35 -> 6500 | I35: 9000 | J35: =I35*A35 -> 4500 | K35: =E35-J35 -> 2000
A36: 1 | B36: BOLSA | C36: PAPA | D36: 14000 | E36: =A36*D36 -> 14000 | I36: 13000 | J36: =I36*A36 -> 13000 | K36: =E36-J36 -> 1000
A37: 1 | B37: BOLSA | C37: ZANAHORIA | D37: 13000 | E37: =A37*D37 -> 13000 | I37: 12000 | J37: =I37*A37 -> 12000 | K37: =E37-J37 -> 1000
A38: 1 | B38: CAJON | C38: HUEVO | D38: 50000 | E38: =A38*D38 -> 50000 | I38: 38000 | J38: =I38*A38 -> 38000 | K38: =E38-J38 -> 12000
A39: 1 | B39: CAJA | C39: BANANA | D39: 40000 | E39: =A39*D39 -> 40000 | I39: 30000 | J39: =I39*A39 -> 30000 | K39: =E39-J39 -> 10000
A40: 2 | B40: KG | C40: CIRUELA | D40: 4000 | E40: =A40*D40 -> 8000 | J40: =I40*A40 -> 0 | K40: =E40-J40 -> 8000
A41: 3 | B41: KG | C41: DURAZNO | D41: 4000 | E41: =A41*D41 -> 12000 | J41: =I41*A41 -> 0 | K41: =E41-J41 -> 12000
A42: 0.5 | B42: KG | C42: KIWI | D42: 12000 | E42: =A42*D42 -> 6000 | J42: =I42*A42 -> 0 | K42: =E42-J42 -> 6000
A43: 3 | B43: KG | C43: LIMÓN | D43: 3000 | E43: =A43*D43 -> 9000 | I43: =35000/15 -> 2333.3333 | J43: =I43*A43 -> 7000 | K43: =E43-J43 -> 2000
A44: 4 | B44: KG | C44: MANZANA VERDE | D44: 5000 | E44: =A44*D44 -> 20000 | I44: =40000/18 -> 2222.2222 | J44: =I44*A44 -> 8888.8889 | K44: =E44-J44 -> 11111.111
A45: 7 | B45: KG | C45: NARANJA | D45: 1600 | E45: =A45*D45 -> 11200 | I45: =18000/15 -> 1200 | J45: =I45*A45 -> 8400 | K45: =E45-J45 -> 2800
A46: 2 | B46: UNIDAD | C46: MELON | D46: 4000 | E46: =A46*D46 -> 8000 | I46: 5000 | J46: =I46*A46 -> 10000 | K46: =E46-J46 -> -2000
A47: 12 | B47: KG | C47: SANDÍA | D47: 1200 | E47: =A47*D47 -> 14400 | I47: 600 | J47: =I47*A47 -> 7200 | K47: =E47-J47 -> 7200
...

Sheet 15-01-2026 
A3: FV | E3: rto: 218 | F3: 46037 | I3: COMPRA
A5: CANTIDAD | B5: UNIDAD | C5: PRODUCTO | D5: PRECIO | E5: TOTAL | F5: TOTAL + IVA | I5: PRECIO | J5: TOTAL | K5: DIFERENCIA
A6: 2 | B6: CAJON | C6: TOM CHERRY | D6: 30000 | E6: =A6*D6 -> 60000 | F6: =E6*1.105 -> 66300 | I6: 30000 | J6: =I6*A6 -> 60000 | K6: =F6-J6 -> 6300
A7: 6 | B7: ATADO | C7: ALBAHACA | D7: 1000 | E7: =A7*D7 -> 6000 | F7: =E7*1.105 -> 6630 | I7: 500 | J7: =I7*A7 -> 3000 | K7: =F7-J7 -> 3630
A8: 2 | B8: CAJON | C8: TOMATE REDONDO | D8: 32000 | E8: =A8*D8 -> 64000 | F8: =E8*1.105 -> 70720 | I8: 25000 | J8: =I8*A8 -> 50000 | K8: =F8-J8 -> 20720
A9: 4 | B9: CAJA | C9: BANANA | D9: 38000 | E9: =A9*D9 -> 152000 | F9: =E9*1.105 -> 167960 | I9: 28000 | J9: =I9*A9 -> 112000 | K9: =F9-J9 -> 55960
A10: 4 | B10: CAJA | C10: DURAZNO | D10: 35000 | E10: =A10*D10 -> 140000 | F10: =E10*1.105 -> 154700 | I10: 30000 | J10: =I10*A10 -> 120000 | K10: =F10-J10 -> 34700
A11: 2 | B11: CAJA | C11: MANZANA GRANNY | D11: 70000 | E11: =A11*D11 -> 140000 | F11: =E11*1.105 -> 154700 | I11: 40000 | J11: =I11*A11 -> 80000 | K11: =F11-J11 -> 74700
A12: 1 | B12: CAJA | C12: UVA | D12: 32000 | E12: =A12*D12 -> 32000 | F12: =E12*1.105 -> 35360 | I12: 30000 | J12: =I12*A12 -> 30000 | K12: =F12-J12 -> 5360
A13: 1 | B13: CAJA | C13: CIRUELA | D13: 32000 | E13: =A13*D13 -> 32000 | F13: =E13*1.105 -> 35360 | I13: 35000 | J13: =I13*A13 -> 35000 | K13: =F13-J13 -> 360
A14: 1 | B14: CAJON | C14: TOMATE REDONDO | D14: 32000 | E14: =A14*D14 -> 32000 | F14: =E14*1.105 -> 35360 | G14: BOLSA | I14: 0 | J14: =I14*A14 -> 0 | K14: =F14-J14 -> 35360
A15: 1 | B15: CAJON | C15: CHERRY | D15: 30000 | E15: =A15*D15 -> 30000 | F15: =E15*1.105 -> 33150 | G15: BOLSA | I15: 0 | J15: =I15*A15 -> 0 | K15: =F15-J15 -> 33150
A16: 1 | B16: CAJA | C16: MANZANA GRANNY | D16: 70000 | E16: =A16*D16 -> 70000 | F16: =E16*1.105 -> 77350 | G16: BOLSA | I16: 0 | J16: =I16*A16 -> 0 | K16: =F16-J16 -> 77350
A17: 1 | B17: CAJA | C17: CIRUELA | D17: 32000 | E17: =A17*D17 -> 32000 | F17: =E17*1.105 -> 35360 | G17: BOLSA PROPIA | I17: 0 | J17: =I17*A17 -> 0 | K17: =F17-J17 -> 35360
E19: =SUM(E6:E17) -> 790000 | F19: =SUM(F6:F17) -> 872950 | K19: =SUM(K6:K17) -> 382950 | L19: =K19/F19 -> 0.43868492
A22: LA MARQUESA | D22: rto: 2 | E22: 46037
A24: CANTIDAD | B24: UNIDAD | C24: PRODUCTO | D24: PRECIO | E24: TOTAL | I24: PRECIO | J24: TOTAL | K24: DIFERENCIA
A25: 3 | B25: UNIDAD | C25: AJO | D25: 1000 | E25: =A25*D25 -> 3000 | I25: =560 -> 560 | J25: =I25*A25 -> 1680 | K25: =E25-J25 -> 1320
A26: 2 | B26: KG | C26: BANANA | D26: 3000 | E26: =A26*D26 -> 6000 | I26: 0 | J26: =I26*A26 -> 0 | K26: =E26-J26 -> 6000
A27: 4 | B27: CUBETA | C27: ARANDANO | D27: 2500 | E27: =A27*D27 -> 10000 | I27: =18000/12 -> 1500 | J27: =I27*A27 -> 6000 | K27: =E27-J27 -> 4000
A28: 0.5 | B28: KG | C28: CHAMPI | D28: 19000 | E28: =A28*D28 -> 9500 | I28: 16000 | J28: =I28*A28 -> 8000 | K28: =E28-J28 -> 1500
A29: 2 | B29: CAJON | C29: HUEVO | D29: 50000 | E29: =A29*D29 -> 100000 | I29: 38000 | J29: =I29*A29 -> 76000 | K29: =E29-J29 -> 24000
A30: 1 | B30: KG | C30: KIWI | D30: 13000 | E30: =A30*D30 -> 13000 | I30: 10000 | J30: =I30*A30 -> 10000 | K30: =E30-J30 -> 3000
A31: 2 | B31: KG | C31: LIMA | D31: 4000 | E31: =A31*D31 -> 8000 | I31: 3000 | J31: =I31*A31 -> 6000 | K31: =E31-J31 -> 2000
A32: 3 | B32: KG | C32: LIMON | D32: 3200 | E32: =A32*D32 -> 9600 | I32: =35000/15 -> 2333.3333 | J32: =I32*A32 -> 7000 | K32: =E32-J32 -> 2600
A33: 2 | B33: UNIDAD | C33: MANGO | D33: 2500 | E33: =A33*D33 -> 5000 | I33: =15000/9 -> 1666.6667 | J33: =I33*A33 -> 3333.3333 | K33: =E33-J33 -> 1666.6667
A34: 1 | B34: KG | C34: MANZANA GRANNY | D34: 3200 | E34: =A34*D34 -> 3200 | I34: =44000/18 -> 2444.4444 | J34: =I34*A34 -> 2444.4444 | K34: =E34-J34 -> 755.55556
A35: 15 | B35: UNIDAD | C35: PALTA | D35: 1200 | E35: =A35*D35 -> 18000 | I35: =65000/80 -> 812.5 | J35: =I35*A35 -> 12187.5 | K35: =E35-J35 -> 5812.5
A36: 1 | B36: KG | C36: TOM CHERRY | D36: 4000 | E36: =A36*D36 -> 4000 | I36: =30000/8 -> 3750 | J36: =I36*A36 -> 3750 | K36: =E36-J36 -> 250
A37: 1 | B37: CAJON | C37: TOMATE REDONDO | D37: 30000 | E37: =A37*D37 -> 30000 | I37: 22000 | J37: =I37*A37 -> 22000 | K37: =E37-J37 -> 8000
A38: 1 | B38: BOLSA | C38: ZANAHORIA | D38: 16000 | E38: =A38*D38 -> 16000 | I38: 13000 | J38: =I38*A38 -> 13000 | K38: =E38-J38 -> 3000
A39: 2 | B39: KG | C39: ZAP LARGO | D39: 2000 | E39: =A39*D39 -> 4000 | I39: =20000/14 -> 1428.5714 | J39: =I39*A39 -> 2857.1429 | K39: =E39-J39 -> 1142.8571
E41: =SUM(E25:E39) -> 239300 | K41: =SUM(K25:K39) -> 65047.579 | L41: =K41/E41 -> 0.2718244
A45: LA PIADINA | D45: rto: 6 | E45: 46035
A47: CANTIDAD | B47: UNIDAD | C47: PRODUCTO | D47: PRECIO | E47: TOTAL | I47: PRECIO | J47: TOTAL | K47: DIFERENCIA
A48: 4 | B48: ATADO | C48: ALBAHACA | D48: 1200 | E48: =A48*D48 -> 4800 | I48: 500 | J48: =I48*A48 -> 2000 | K48: =E48-J48 -> 2800
A49: 2 | B49: UNIDAD | C49: AJO | D49: 1200 | E49: =A49*D49 -> 2400 | I49: 560 | J49: =I49*A49 -> 1120 | K49: =E49-J49 -> 1280
A50: 1 | B50: KG | C50: LEC FRANCESA | D50: 3000 | E50: =A50*D50 -> 3000 | I50: 3000 | J50: =I50*A50 -> 3000 | K50: =E50-J50 -> 0
A51: 0.5 | B51: CAJON | C51: RUCULA | D51: 12000 | E51: =A51*D51 -> 6000 | I51: 6000 | J51: =I51*A51 -> 3000 | K51: =E51-J51 -> 3000
A52: 1.5 | B52: KG | C52: BANANA | D52: 3000 | E52: =A52*D52 -> 4500 | I52: 0 | J52: =I52*A52 -> 0 | K52: =E52-J52 -> 4500
...

Sheet 16-01-2026 
A3: FV | E3: rto: 219 | F3: 46038 | I3: COMPRA
A5: CANTIDAD | B5: UNIDAD | C5: PRODUCTO | D5: PRECIO | E5: TOTAL | F5: TOTAL + IVA | I5: PRECIO | J5: TOTAL | K5: DIFERENCIA
A6: 4 | B6: CAJA | C6: BANANA | D6: 38000 | E6: =A6*D6 -> 152000 | F6: =E6*1.105 -> 167960 | I6: 30000 | J6: =I6*A6 -> 120000 | K6: =F6-J6 -> 47960
A7: 3 | B7: CAJA | C7: MANZANA GRNNY | D7: 70000 | E7: =A7*D7 -> 210000 | F7: =E7*1.105 -> 232050 | I7: 40000 | J7: =I7*A7 -> 120000 | K7: =F7-J7 -> 112050
A8: 2 | B8: CAJA | C8: NARANJA | D8: 22000 | E8: =A8*D8 -> 44000 | F8: =E8*1.105 -> 48620 | I8: 19000 | J8: =I8*A8 -> 38000 | K8: =F8-J8 -> 10620
A9: 1 | B9: CAJON | C9: UVA | D9: 32000 | E9: =A9*D9 -> 32000 | F9: =E9*1.105 -> 35360 | I9: 27000 | J9: =I9*A9 -> 27000 | K9: =F9-J9 -> 8360
A10: 23.8 | B10: KG | C10: SANDIA | D10: 1200 | E10: =A10*D10 -> 28560 | F10: =E10*1.105 -> 31558.8 | I10: 700 | J10: =I10*A10 -> 16660 | K10: =F10-J10 -> 14898.8
A11: 1 | B11: BOLSA | C11: CEBOLLA | D11: 14000 | E11: =A11*D11 -> 14000 | F11: =E11*1.105 -> 15470 | I11: 10000 | J11: =I11*A11 -> 10000 | K11: =F11-J11 -> 5470
A12: 1 | B12: CAJA | C12: BANANA | D12: 38000 | E12: =A12*D12 -> 38000 | F12: =E12*1.105 -> 41990 | G12: BOLSA | J12: =I12*A12 -> 0 | K12: =F12-J12 -> 41990
A13: 1 | B13: CAJA | C13: MANZANA | D13: 70000 | E13: =A13*D13 -> 70000 | F13: =E13*1.105 -> 77350 | G13: BOLSA | J13: =I13*A13 -> 0 | K13: =F13-J13 -> 77350
A14: 1 | B14: CAJA | C14: NARNAJA | D14: 22000 | E14: =A14*D14 -> 22000 | F14: =E14*1.105 -> 24310 | G14: BOLSA | J14: =I14*A14 -> 0 | K14: =F14-J14 -> 24310
E16: =SUM(E6:E14) -> 610560 | F16: =SUM(F6:F14) -> 674668.8 | K16: =SUM(K6:K14) -> 343008.8 | L16: =K16/F16 -> 0.50841065
A19: BRASOV | D19: rto: 5 | E19: 46038 | I19: COMPRA
A21: CANTIDAD | B21: UNIDAD | C21: PRODUCTO | D21: PRECIO | E21: TOTAL | I21: PRECIO | J21: TOTAL | K21: DIFERENCIA
A22: 2 | B22: CAJA | C22: LIMÓN | D22: 42000 | E22: =A22*D22 -> 84000 | I22: 32000 | J22: =I22*A22 -> 64000 | K22: =E22-J22 -> 20000
A23: 2 | B23: CAJÓN | C23: NARANJA | D23: 19000 | E23: =A23*D23 -> 38000 | I23: 15000 | J23: =I23*A23 -> 30000 | K23: =E23-J23 -> 8000
A24: 4 | B24: ATADO | C24: CEBOLLA DE VERDEO | D24: 5000 | E24: =A24*D24 -> 20000 | I24: 4000 | J24: =I24*A24 -> 16000 | K24: =E24-J24 -> 4000
A25: 1 | B25: CAJA | C25: PALTA | D25: 65000 | E25: =A25*D25 -> 65000 | I25: 57000 | J25: =I25*A25 -> 57000 | K25: =E25-J25 -> 8000
A26: 4 | B26: UNIDAD | C26: MANGO | D26: 2500 | E26: =A26*D26 -> 10000 | I26: =15000/9 -> 1666.6667 | J26: =I26*A26 -> 6666.6667 | K26: =E26-J26 -> 3333.3333
A27: 1 | B27: BANDEJA | C27: TOMATE CHERRY | D27: 22500 | E27: =A27*D27 -> 22500 | I27: =3750*5 -> 18750 | J27: =I27*A27 -> 18750 | K27: =E27-J27 -> 3750
E29: =SUM(E22:E27) -> 239500 | K29: =SUM(K22:K27) -> 47083.333 | L29: =K29/E29 -> 0.19659012
A32: COMO SIEMPRE LAGUNA | D32: rto: 21 | E32: 46038
A34: CANTIDAD | B34: UNIDAD | C34: PRODUCTO | D34: PRECIO | E34: TOTAL | I34: PRECIO | J34: TOTAL | K34: DIFERENCIA
A35: 2 | B35: BOLSA | C35: PAPA BLANCA | D35: 23000 | E35: =A35*D35 -> 46000 | I35: 19500 | J35: =I35*A35 -> 39000 | K35: =E35-J35 -> 7000
A36: 1 | B36: BOLSA | C36: CABUTIA | D36: 18000 | E36: =A36*D36 -> 18000 | I36: 15000 | J36: =I36*A36 -> 15000 | K36: =E36-J36 -> 3000
A37: 1 | B37: BOLSA | C37: ZANAHORIA | D37: 15000 | E37: =A37*D37 -> 15000 | I37: 13000 | J37: =I37*A37 -> 13000 | K37: =E37-J37 -> 2000
A38: 1 | B38: CAJÓN | C38: ESPINACA | D38: 22000 | E38: =A38*D38 -> 22000 | I38: 17000 | J38: =I38*A38 -> 17000 | K38: =E38-J38 -> 5000
A39: 1 | B39: CAJÓN | C39: HUEVOS | D39: 48000 | E39: =A39*D39 -> 48000 | I39: 38000 | J39: =I39*A39 -> 38000 | K39: =E39-J39 -> 10000
A40: 1 | B40: KG | C40: MANZANA VERDE | D40: 3500 | E40: =A40*D40 -> 3500 | I40: =40000/17 -> 2352.9412 | J40: =I40*A40 -> 2352.9412 | K40: =E40-J40 -> 1147.0588
A41: 5 | B41: UNIDAD | C41: AJO | D41: 1200 | E41: =A41*D41 -> 6000 | I41: 560 | J41: =I41*A41 -> 2800 | K41: =E41-J41 -> 3200
A42: 1 | B42: PAQ | C42: APIO | D42: 2000 | E42: =A42*D42 -> 2000 | I42: 1600 | J42: =I42*A42 -> 1600 | K42: =E42-J42 -> 400
A43: 6 | B43: KG | C43: CEBOLLA MORADA | D43: 1600 | E43: =A43*D43 -> 9600 | I43: =1000 -> 1000 | J43: =I43*A43 -> 6000 | K43: =E43-J43 -> 3600
A44: 2 | B44: CAJÓN | C44: COLIFLOR | D44: 15000 | E44: =A44*D44 -> 30000 | I44: 10000 | J44: =I44*A44 -> 20000 | K44: =E44-J44 -> 10000
A45: 6 | B45: KG | C45: TOMATE PERITA | D45: 3200 | E45: =A45*D45 -> 19200 | I45: =40000/15 -> 2666.6667 | J45: =I45*A45 -> 16000 | K45: =E45-J45 -> 3200
A46: 6 | B46: KG | C46: BONIATO | D46: 3200 | E46: =A46*D46 -> 19200 | I46: 2500 | J46: =I46*A46 -> 15000 | K46: =E46-J46 -> 4200
A47: 3 | B47: KG | C47: MORRÓN ROJO | D47: 3000 | E47: =A47*D47 -> 9000 | I47: =12000/8 -> 1500 | J47: =I47*A47 -> 4500 | K47: =E47-J47 -> 4500
A48: 1 | B48: KG | C48: MORRÓN AMARILLO | D48: 3500 | E48: =A48*D48 -> 3500 | I48: =16000/8 -> 2000 | J48: =I48*A48 -> 2000 | K48: =E48-J48 -> 1500
A49: 1 | B49: KG | C49: MORRÓN VERDE | D49: 2800 | E49: =A49*D49 -> 2800 | I49: 3000 | J49: =I49*A49 -> 3000 | K49: =E49-J49 -> -200
A50: 1 | B50: KG | C50: ZUCCINI | D50: 2000 | E50: =A50*D50 -> 2000 | I50: =20000/15 -> 1333.3333 | J50: =I50*A50 -> 1333.3333 | K50: =E50-J50 -> 666.66667
A51: 1 | B51: KG | C51: BERENJENA | D51: 1800 | E51: =A51*D51 -> 1800 | I51: =10000/8 -> 1250 | J51: =I51*A51 -> 1250 | K51: =E51-J51 -> 550
...

Sheet 19-01-2026 
A3: FV | E3: rto: 220 | F3: 46041 | I3: COMPRA
A5: CANTIDAD | B5: UNIDAD | C5: PRODUCTO | D5: PRECIO | E5: TOTAL | F5: TOTAL + IVA | I5: PRECIO | J5: TOTAL | K5: DIFERENCIA
A6: 2 | B6: CAJA | C6: MANZANA GRANNY | D6: 63000 | E6: =A6*D6 -> 126000 | F6: =E6*1.105 -> 139230 | I6: 40000 | J6: =I6*A6 -> 80000 | K6: =F6-J6 -> 59230
A7: 2 | B7: CAJON | C7: TOMATE REDONDO | D7: 53000 | E7: =A7*D7 -> 106000 | F7: =E7*1.105 -> 117130 | I7: 45000 | J7: =I7*A7 -> 90000 | K7: =F7-J7 -> 27130
A8: 2 | B8: CAJON | C8: TOMATE CHERRY | D8: 43000 | E8: =A8*D8 -> 86000 | F8: =E8*1.105 -> 95030 | I8: 35000 | J8: =I8*A8 -> 70000 | K8: =F8-J8 -> 25030
A9: 1 | B9: CAJON | C9: BERENJENA | D9: 13000 | E9: =A9*D9 -> 13000 | F9: =E9*1.105 -> 14365 | I9: 9000 | J9: =I9*A9 -> 9000 | K9: =F9-J9 -> 5365
A10: 6 | B10: ATADO | C10: ALBAHACA | D10: 1000 | E10: =A10*D10 -> 6000 | F10: =E10*1.105 -> 6630 | I10: 500 | J10: =I10*A10 -> 3000 | K10: =F10-J10 -> 3630
A11: 2 | B11: CAJA | C11: BANANA | D11: 38000 | E11: =A11*D11 -> 76000 | F11: =E11*1.105 -> 83980 | I11: 28000 | J11: =I11*A11 -> 56000 | K11: =F11-J11 -> 27980
A12: 2 | B12: CAJON | C12: UVA RED GLOBE OFER | D12: 25000 | E12: =A12*D12 -> 50000 | F12: =E12*1.105 -> 55250 | I12: =50000/3 -> 16666.667 | J12: =I12*A12 -> 33333.333 | K12: =F12-J12 -> 21916.667
A13: 4 | B13: CAJA | C13: CIRUELA | D13: 32000 | E13: =A13*D13 -> 128000 | F13: =E13*1.105 -> 141440 | I13: 27000 | J13: =I13*A13 -> 108000 | K13: =F13-J13 -> 33440
A14: 0.5 | B14: CAJON | C14: HUEVO | D14: 50000 | E14: =A14*D14 -> 25000 | F14: =E14*1.105 -> 27625 | I14: 38000 | J14: =I14*A14 -> 19000 | K14: =F14-J14 -> 8625
A15: 1 | B15: CAJA | C15: BANANA | D15: 38000 | E15: =A15*D15 -> 38000 | F15: =E15*1.105 -> 41990 | G15: BOLSA | J15: =I15*A15 -> 0 | K15: =F15-J15 -> 41990
A16: 1 | B16: CAJON | C16: TOMATE | D16: 53000 | E16: =A16*D16 -> 53000 | F16: =E16*1.105 -> 58565 | G16: BOLSA | J16: =I16*A16 -> 0 | K16: =F16-J16 -> 58565
A17: 1 | B17: CJAON | C17: TOM CHERRY | D17: 43000 | E17: =A17*D17 -> 43000 | F17: =E17*1.105 -> 47515 | G17: BOLSA | I17: 0 | J17: =I17*A17 -> 0 | K17: =F17-J17 -> 47515
A18: 1 | B18: CAJA | C18: MANZANA GRANNY | D18: 63000 | E18: =A18*D18 -> 63000 | F18: =E18*1.105 -> 69615 | G18: BOLSA | J18: =I18*A18 -> 0 | K18: =F18-J18 -> 69615
A19: 0.5 | B19: CAJON | C19: HUEVO | D19: 50000 | E19: =A19*D19 -> 25000 | F19: =E19*1.21 -> 30250 | G19: BOLSA | J19: =I19*A19 -> 0 | K19: =F19-J19 -> 30250
E21: =SUM(E6:E19) -> 838000 | F21: =SUM(F6:F19) -> 928615 | K21: =SUM(K6:K19) -> 460281.67
A24: COMO SIEMPRE LAGUNA | D24: rto: 22 | E24: 46041
A26: CANTIDAD | B26: UNIDAD | C26: PRODUCTO | D26: PRECIO | E26: TOTAL | I26: PRECIO | J26: TOTAL | K26: DIFERENCIA
A27: 0.5 | B27: CAJON | C27: NARANJA | D27: 20000 | E27: =A27*D27 -> 10000 | I27: 15000 | J27: =I27*A27 -> 7500 | K27: =E27-J27 -> 2500
A28: 1 | B28: CAJA | C28: LIMON | D28: 42000 | E28: =A28*D28 -> 42000 | I28: 32000 | J28: =I28*A28 -> 32000 | K28: =E28-J28 -> 10000
A29: 1 | B29: ATADO | C29: MENTA | D29: 3000 | E29: =A29*D29 -> 3000 | I29: 2000 | J29: =I29*A29 -> 2000 | K29: =E29-J29 -> 1000
A30: 2 | B30: BOLSA | C30: PAPA GARLIC | D30: 23000 | E30: =A30*D30 -> 46000 | I30: 19000 | J30: =I30*A30 -> 38000 | K30: =E30-J30 -> 8000
A31: 2 | B31: CAJON | C31: ESPINACA | D31: 22000 | E31: =A31*D31 -> 44000 | I31: 17000 | J31: =I31*A31 -> 34000 | K31: =E31-J31 -> 10000
A32: 0.5 | B32: KG | C32: CHAMPI | D32: 19000 | E32: =A32*D32 -> 9500 | I32: 16000 | J32: =I32*A32 -> 8000 | K32: =E32-J32 -> 1500
A33: 0.5 | B33: KG | C33: PORTO | D33: 20000 | E33: =A33*D33 -> 10000 | I33: 17000 | J33: =I33*A33 -> 8500 | K33: =E33-J33 -> 1500
A34: 3 | B34: UNIDAD | C34: AJO | D34: 1200 | E34: =A34*D34 -> 3600 | I34: 560 | J34: =I34*A34 -> 1680 | K34: =E34-J34 -> 1920
A35: 3 | B35: KG | C35: TOM PERITA | D35: 4000 | E35: =A35*D35 -> 12000 | I35: 4000 | J35: =I35*A35 -> 12000 | K35: =E35-J35 -> 0
A36: 3 | B36: KG | C36: MORRON ROJO | D36: 3000 | E36: =A36*D36 -> 9000 | I36: =10000/8 -> 1250 | J36: =I36*A36 -> 3750 | K36: =E36-J36 -> 5250
A37: 1 | B37: ATADO | C37: CILANTRO | D37: 2000 | E37: =A37*D37 -> 2000 | I37: 1000 | J37: =I37*A37 -> 1000 | K37: =E37-J37 -> 1000
A38: 1 | B38: ATADO | C38: CIBOULLETE | D38: 3000 | E38: =A38*D38 -> 3000 | I38: 2000 | J38: =I38*A38 -> 2000 | K38: =E38-J38 -> 1000
A39: 1 | B39: CAJON | C39: RUCULA | D39: 9000 | E39: =A39*D39 -> 9000 | I39: 5000 | J39: =I39*A39 -> 5000 | K39: =E39-J39 -> 4000
A40: 1 | B40: KG | C40: REMOLACHA | D40: 2000 | E40: =A40*D40 -> 2000 | I40: 1400 | J40: =I40*A40 -> 1400 | K40: =E40-J40 -> 600
E42: =SUM(E27:E40) -> 205100 | K42: =SUM(K27:K40) -> 48270 | L42: =K42/E42 -> 0.23534861
A45: LA PIADINA | D45: rto: 8 | E45: 46041
A47: CANTIDAD | B47: UNIDAD | C47: PRODUCTO | D47: PRECIO | E47: TOTAL | I47: PRECIO | J47: TOTAL | K47: DIFERENCIA
A48: 1 | B48: CAJON | C48: RUCULA | D48: 10000 | E48: =A48*D48 -> 10000 | I48: 5000 | J48: =I48*A48 -> 5000 | K48: =E48-J48 -> 5000
A49: 4 | B49: KG | C49: TOMATE | D49: 4000 | E49: =A49*D49 -> 16000 | I49: 0 | J49: =I49*A49 -> 0 | K49: =E49-J49 -> 16000
A50: 1.5 | B50: KG | C50: LECHUGA | D50: 4000 | E50: =A50*D50 -> 6000 | I50: 3500 | J50: =I50*A50 -> 5250 | K50: =E50-J50 -> 750
A51: 1 | B51: KG | C51: ZANAHORIA | D51: 2000 | E51: =A51*D51 -> 2000 | I51: 1200 | J51: =I51*A51 -> 1200 | K51: =E51-J51 -> 800
...

Sheet 20-01-2026 
A4: RAKUS | D4: rto: 16 | E4: 46042 | F4: **
A6: CANTIDAD | B6: UNIDAD | C6: PRODUCTO | D6: PRECIO | E6: TOTAL | I6: PRECIO | J6: TOTAL | K6: DIFERENCIA
A7: 1 | B7: KG | C7: TOMATE CHERRY | D7: 3800 | E7: =A7*D7 -> 3800 | I7: 0 | J7: =I7*A7 -> 0 | K7: =E7-J7 -> 3800
A8: 1 | B8: UNIDAD | C8: REP BLANCO | D8: 2000 | E8: =A8*D8 -> 2000 | I8: 1500 | J8: =I8*A8 -> 1500 | K8: =E8-J8 -> 500
A9: 1 | B9: UNIDAD | C9: REP ROJO | D9: 2000 | E9: =A9*D9 -> 2000 | I9: 1200 | J9: =I9*A9 -> 1200 | K9: =E9-J9 -> 800
A10: 4.1 | B10: KG | C10: TOMATE REDONDO | D10: 4000 | E10: =A10*D10 -> 16400 | I10: =40000/15 -> 2666.6667 | J10: =I10*A10 -> 10933.333 | K10: =E10-J10 -> 5466.6667
A11: 8 | B11: CUBETA | C11: ARANDANO | D11: 2500 | E11: =A11*D11 -> 20000 | I11: =22000/12 -> 1833.3333 | J11: =I11*A11 -> 14666.667 | K11: =E11-J11 -> 5333.3333
