Workbook

Sheet 02-02-2026 
A3: FV | E3: rto: 223 | F3: 46055 | G3: ** | I3: COMPRA
A5: CANTIDAD | B5: UNIDAD | C5: PRODUCTO | D5: PRECIO | E5: TOTAL | F5: TOTAL + IVA | I5: PRECIO | J5: TOTAL | K5: DIFERENCIA
A6: 10 | B6: ATADOS | C6: TOMILLO | D6: 3500 | E6: =A6*D6 -> 35000 | F6: =E6*1.105 -> 38675 | I6: 2000 | J6: =I6*A6 -> 20000 | K6: =F6-J6 -> 18675
A7: 10 | B7: ATADOS | C7: ROMERO | D7: 3500 | E7: =A7*D7 -> 35000 | F7: =E7*1.105 -> 38675 | I7: 2000 | J7: =I7*A7 -> 20000 | K7: =F7-J7 -> 18675
A8: 10 | B8: ATADOS | C8: SALVIA | D8: 3500 | E8: =A8*D8 -> 35000 | F8: =E8*1.105 -> 38675 | I8: 2000 | J8: =I8*A8 -> 20000 | K8: =F8-J8 -> 18675
A9: 10 | B9: ATADOS | C9: ALBAHACA | D9: 1000 | E9: =A9*D9 -> 10000 | F9: =E9*1.105 -> 11050 | I9: =6000/12 -> 500 | J9: =I9*A9 -> 5000 | K9: =F9-J9 -> 6050
A10: 1 | B10: ATADOS | C10: CEB VERDEO | D10: 5500 | E10: =A10*D10 -> 5500 | F10: =E10*1.105 -> 6077.5 | I10: 4000 | J10: =I10*A10 -> 4000 | K10: =F10-J10 -> 2077.5
A11: 3 | B11: CAJON | C11: TOMATE REDONDO | D11: 18000 | E11: =A11*D11 -> 54000 | F11: =E11*1.105 -> 59670 | I11: 13000 | J11: =I11*A11 -> 39000 | K11: =F11-J11 -> 20670
A12: 3 | B12: CAJON | C12: TOMATE CHERRY | D12: 30000 | E12: =A12*D12 -> 90000 | F12: =E12*1.105 -> 99450 | I12: 20000 | J12: =I12*A12 -> 60000 | K12: =F12-J12 -> 39450
A13: 0.5 | B13: CAJON | C13: HUEVO | D13: 56000 | E13: =A13*D13 -> 28000 | F13: =E13*1.21 -> 33880 | I13: 46000 | J13: =I13*A13 -> 23000 | K13: =F13-J13 -> 10880
A14: 1 | B14: CAJON | C14: ZUCCINI | D14: 16000 | E14: =A14*D14 -> 16000 | F14: =E14*1.105 -> 17680 | I14: 8000 | J14: =I14*A14 -> 8000 | K14: =F14-J14 -> 9680
A15: 1 | B15: CAJON | C15: BERENJENA | D15: 15000 | E15: =A15*D15 -> 15000 | F15: =E15*1.105 -> 16575 | I15: 7000 | J15: =I15*A15 -> 7000 | K15: =F15-J15 -> 9575
A16: 1 | B16: CAJON | C16: MORRON ROJO | D16: 40000 | E16: =A16*D16 -> 40000 | F16: =E16*1.105 -> 44200 | I16: 30000 | J16: =I16*A16 -> 30000 | K16: =F16-J16 -> 14200
A17: 1 | B17: CAJON | C17: MORRON VERDE | D17: 25000 | E17: =A17*D17 -> 25000 | F17: =E17*1.105 -> 27625 | I17: 13000 | J17: =I17*A17 -> 13000 | K17: =F17-J17 -> 14625
A18: 1 | B18: CAJON | C18: MORRON AMARILLO | D18: 35000 | E18: =A18*D18 -> 35000 | F18: =E18*1.105 -> 38675 | I18: 25000 | J18: =I18*A18 -> 25000 | K18: =F18-J18 -> 13675
A19: 2 | B19: PAQUETES | C19: BROTE DE SOJA | D19: 3000 | E19: =A19*D19 -> 6000 | F19: =E19*1.105 -> 6630 | I19: 2000 | J19: =I19*A19 -> 4000 | K19: =F19-J19 -> 2630
A20: 2 | B20: CAJA | C20: MANZANA GRANNY | D20: 63000 | E20: =A20*D20 -> 126000 | F20: =E20*1.105 -> 139230 | I20: 40000 | J20: =I20*A20 -> 80000 | K20: =F20-J20 -> 59230
A21: 2 | B21: CAJA | C21: BANANA | D21: 35000 | E21: =A21*D21 -> 70000 | F21: =E21*1.105 -> 77350 | I21: 24000 | J21: =I21*A21 -> 48000 | K21: =F21-J21 -> 29350
A22: 3 | B22: CAJON | C22: NARANJA FRIO | D22: 22000 | E22: =A22*D22 -> 66000 | F22: =E22*1.105 -> 72930 | I22: 17000 | J22: =I22*A22 -> 51000 | K22: =F22-J22 -> 21930
A23: 28 | B23: KG | C23: SANDIA | D23: 1200 | E23: =A23*D23 -> 33600 | F23: =E23*1.105 -> 37128 | I23: 700 | J23: =I23*A23 -> 19600 | K23: =F23-J23 -> 17528
A24: 2 | B24: CAJON | C24: MELON BLANCO | D24: 22000 | E24: =A24*D24 -> 44000 | F24: =E24*1.105 -> 48620 | I24: 15000 | J24: =I24*A24 -> 30000 | K24: =F24-J24 -> 18620
A25: 2 | B25: CAJON | C25: UVA RED GLOBE | D25: 40000 | E25: =A25*D25 -> 80000 | F25: =E25*1.105 -> 88400 | I25: 25000 | J25: =I25*A25 -> 50000 | K25: =F25-J25 -> 38400
A26: 2 | B26: CAJA | C26: BANANA | D26: 35000 | E26: =A26*D26 -> 70000 | F26: =E26*1.105 -> 77350 | G26: BOLSA | J26: =I26*A26 -> 0 | K26: =F26-J26 -> 77350
A27: 2 | B27: CAJON | C27: NARANJA | D27: 22000 | E27: =A27*D27 -> 44000 | F27: =E27*1.105 -> 48620 | G27: BOLSA | J27: =I27*A27 -> 0 | K27: =F27-J27 -> 48620
A28: 0.5 | B28: CAJÓN | C28: HUEVO | D28: 56000 | E28: =A28*D28 -> 28000 | F28: =E28*1.21 -> 33880 | G28: BOLSA | J28: =I28*A28 -> 0 | K28: =F28-J28 -> 33880
A29: 1 | B29: CAJON | C29: BERENJENA | D29: 15000 | E29: =A29*D29 -> 15000 | F29: =E29*1.105 -> 16575 | G29: BOLSA PROPIA | J29: =I29*A29 -> 0 | K29: =F29-J29 -> 16575
A30: 1 | B30: CAJON | C30: ZUCCINI | D30: 16000 | E30: =A30*D30 -> 16000 | F30: =E30*1.105 -> 17680 | G30: BOLSA PROPIA | J30: =I30*A30 -> 0 | K30: =F30-J30 -> 17680
A31: 1 | B31: CAJÓN | C31: TOMATE REDONDO | D31: 18000 | E31: =A31*D31 -> 18000 | F31: =E31*1.105 -> 19890 | G31: BOLSA PROPIA | J31: =I31*A31 -> 0 | K31: =F31-J31 -> 19890
A32: 1 | B32: CAJON | C32: TOMATE CHERRY | D32: 30000 | E32: =A32*D32 -> 30000 | F32: =E32*1.105 -> 33150 | G32: BOLSA PROPIA | J32: =I32*A32 -> 0 | K32: =F32-J32 -> 33150
E34: =SUM(E6:E32) -> 1070100 | F34: =SUM(F6:F32) -> 1188340.5 | K34: =SUM(K6:K32) -> 631740.5 | L34: =K34/F34 -> 0.53161573
A37: LUSQTOFF | B37: SEDE: IRALA | E37: rto: 1 | F37: 46055 | G37: ** | I37: COMPRA
A39: CANTIDAD | B39: UNIDAD | C39: PRODUCTO | D39: PRECIO | E39: TOTAL | F39: TOTAL + IVA | I39: PRECIO | J39: TOTAL | K39: DIFERENCIA
A40: 5 | B40: KG | C40: BERENJENA | D40: 1700 | E40: =A40*D40 -> 8500 | F40: =E40*1.105 -> 9392.5 | I40: 1000 | J40: =I40*A40 -> 5000 | K40: =F40-J40 -> 4392.5
A41: 1 | B41: BOLSA | C41: ANCO | D41: 13000 | E41: =A41*D41 -> 13000 | F41: =E41*1.105 -> 14365 | I41: 8000 | J41: =I41*A41 -> 8000 | K41: =F41-J41 -> 6365
A42: 1 | B42: BOLSA | C42: PAPA | D42: 14000 | E42: =A42*D42 -> 14000 | F42: =E42*1.105 -> 15470 | I42: 11000 | J42: =I42*A42 -> 11000 | K42: =F42-J42 -> 4470
A43: 0.5 | B43: BOLSA | C43: ZANAHORIA | D43: 12000 | E43: =A43*D43 -> 6000 | F43: =E43*1.105 -> 6630 | I43: 8000 | J43: =I43*A43 -> 4000 | K43: =F43-J43 -> 2630
A44: 3 | B44: KG | C44: LECHUGA | D44: 3500 | E44: =A44*D44 -> 10500 | F44: =E44*1.105 -> 11602.5 | I44: =12000/4 -> 3000 | J44: =I44*A44 -> 9000 | K44: =F44-J44 -> 2602.5
A45: 3 | B45: KG | C45: TOMATE REDONDO | D45: 1500 | E45: =A45*D45 -> 4500 | F45: =E45*1.105 -> 4972.5 | I45: =1000 -> 1000 | J45: =I45*A45 -> 3000 | K45: =F45-J45 -> 1972.5
A46: 5 | B46: KG | C46: ZUCCINI | D46: 1500 | E46: =A46*D46 -> 7500 | F46: =E46*1.105 -> 8287.5 | I46: =8000/14 -> 571.42857 | J46: =I46*A46 -> 2857.1429 | K46: =F46-J46 -> 5430.3571
A47: 4 | B47: KG | C47: ZAPALLITOS | D47: 1300 | E47: =A47*D47 -> 5200 | F47: =E47*1.105 -> 5746 | I47: =10000/15 -> 666.66667 | J47: =I47*A47 -> 2666.6667 | K47: =F47-J47 -> 3079.3333
...

Sheet 03-02-2026 
A3: FABRIC SUSHI - MORENO | E3: rto: 3 | F3: 46056 | I3: COMPRA
A5: CANTIDAD | B5: UNIDAD | C5: PRODUCTO | D5: PRECIO | E5: TOTAL | F5: TOTAL + IVA | I5: PRECIO | J5: TOTAL | K5: DIFERENCIA
A6: 1 | B6: UNIDAD | C6: APIO | D6: 1500 | E6: =A6*D6 -> 1500 | F6: =E6*1.105 -> 1657.5 | I6: 1000 | J6: =I6*A6 -> 1000 | K6: =F6-J6 -> 657.5
A7: 3 | B7: ATADOS | C7: CEB VERDEO | D7: 5500 | E7: =A7*D7 -> 16500 | F7: =E7*1.105 -> 18232.5 | I7: 4000 | J7: =I7*A7 -> 12000 | K7: =F7-J7 -> 6232.5
A8: 3 | B8: ATADOS | C8: CILANTRO | D8: 3000 | E8: =A8*D8 -> 9000 | F8: =E8*1.105 -> 9945 | I8: 2000 | J8: =I8*A8 -> 6000 | K8: =F8-J8 -> 3945
A9: 3 | B9: ATADOS | C9: CIBOULLETE | D9: 3000 | E9: =A9*D9 -> 9000 | F9: =E9*1.105 -> 9945 | I9: 2000 | J9: =I9*A9 -> 6000 | K9: =F9-J9 -> 3945
A10: 3 | B10: KG | C10: MORRON ROJO | D10: 4000 | E10: =A10*D10 -> 12000 | F10: =E10*1.105 -> 13260 | I10: =25000/8 -> 3125 | J10: =I10*A10 -> 9375 | K10: =F10-J10 -> 3885
A11: 2 | B11: KG | C11: MORRON VERDE | D11: 2700 | E11: =A11*D11 -> 5400 | F11: =E11*1.105 -> 5967 | I11: =13000/8 -> 1625 | J11: =I11*A11 -> 3250 | K11: =F11-J11 -> 2717
A12: 2 | B12: KG | C12: MORRON AMARILLO | D12: 4000 | E12: =A12*D12 -> 8000 | F12: =E12*1.105 -> 8840 | I12: =25000/8 -> 3125 | J12: =I12*A12 -> 6250 | K12: =F12-J12 -> 2590
A13: 2 | B13: KG | C13: ZAP LARGO | D13: 1500 | E13: =A13*D13 -> 3000 | F13: =E13*1.105 -> 3315 | I13: =8000/15 -> 533.33333 | J13: =I13*A13 -> 1066.6667 | K13: =F13-J13 -> 2248.3333
A14: 3 | B14: KG | C14: CEBOLLA MORADA | D14: 1600 | E14: =A14*D14 -> 4800 | F14: =E14*1.105 -> 5304 | I14: 1000 | J14: =I14*A14 -> 3000 | K14: =F14-J14 -> 2304
A15: 2 | B15: KG | C15: CEBOLLA | D15: 800 | E15: =A15*D15 -> 1600 | F15: =E15*1.105 -> 1768 | I15: =10000/17 -> 588.23529 | J15: =I15*A15 -> 1176.4706 | K15: =F15-J15 -> 591.52941
A16: 5 | B16: UNIDAD | C16: AJO | D16: 900 | E16: =A16*D16 -> 4500 | F16: =E16*1.105 -> 4972.5 | I16: 560 | J16: =I16*A16 -> 2800 | K16: =F16-J16 -> 2172.5
A17: 3 | B17: KG | C17: PEPINO | D17: 1300 | E17: =A17*D17 -> 3900 | F17: =E17*1.105 -> 4309.5 | I17: =12000/15 -> 800 | J17: =I17*A17 -> 2400 | K17: =F17-J17 -> 1909.5
A18: 2 | B18: KG | C18: TOMATE | D18: 1500 | E18: =A18*D18 -> 3000 | F18: =E18*1.105 -> 3315 | I18: =12000/15 -> 800 | J18: =I18*A18 -> 1600 | K18: =F18-J18 -> 1715
A19: 0.5 | B19: BOLSA | C19: PAPA LAVADA | D19: 20000 | E19: =A19*D19 -> 10000 | F19: =E19*1.105 -> 11050 | I19: 18500 | J19: =I19*A19 -> 9250 | K19: =F19-J19 -> 1800
A20: 5 | B20: KG | C20: BATATA | D20: 1400 | E20: =A20*D20 -> 7000 | F20: =E20*1.105 -> 7735 | I20: 1000 | J20: =I20*A20 -> 5000 | K20: =F20-J20 -> 2735
A21: 1 | B21: BANDEJAS | C21: GIRGOLAS | D21: 6000 | E21: =A21*D21 -> 6000 | F21: =E21*1.105 -> 6630 | I21: 4500 | J21: =I21*A21 -> 4500 | K21: =F21-J21 -> 2130
A22: 0.5 | B22: KG | C22: PORTOBELLO | D22: 22000 | E22: =A22*D22 -> 11000 | F22: =E22*1.105 -> 12155 | I22: 20000 | J22: =I22*A22 -> 10000 | K22: =F22-J22 -> 2155
A23: 1 | B23: KG | C23: AJI PERUANO | D23: 26000 | E23: =A23*D23 -> 26000 | F23: =E23*1.105 -> 28730 | I23: 22000 | J23: =I23*A23 -> 22000 | K23: =F23-J23 -> 6730
A24: 0.5 | B24: KG | C24: AJI ROCOTO | D24: 12000 | E24: =A24*D24 -> 6000 | F24: =E24*1.105 -> 6630 | I24: 8000 | J24: =I24*A24 -> 4000 | K24: =F24-J24 -> 2630
A25: 0.5 | B25: KG | C25: AJI LIMO | D25: 12000 | E25: =A25*D25 -> 6000 | F25: =E25*1.105 -> 6630 | I25: 7000 | J25: =I25*A25 -> 3500 | K25: =F25-J25 -> 3130
A26: 0.25 | B26: KG | C26: HONGOS DE PINO | D26: 50000 | E26: =A26*D26 -> 12500 | F26: =E26*1.105 -> 13812.5 | I26: 40000 | J26: =I26*A26 -> 10000 | K26: =F26-J26 -> 3812.5
A27: 1 | B27: BOLSA | C27: BROTES DE SOJA | D27: 3000 | E27: =A27*D27 -> 3000 | F27: =E27*1.105 -> 3315 | I27: 2000 | J27: =I27*A27 -> 2000 | K27: =F27-J27 -> 1315
A28: 0.6 | B28: KG | C28: AJI PANKA ROJO | D28: 23000 | E28: =A28*D28 -> 13800 | F28: =E28*1.105 -> 15249 | I28: 18000 | J28: =I28*A28 -> 10800 | K28: =F28-J28 -> 4449
A29: 4 | B29: ATADOS | C29: PUERRO | D29: 6000 | E29: =A29*D29 -> 24000 | F29: =E29*1.105 -> 26520 | I29: 4000 | J29: =I29*A29 -> 16000 | K29: =F29-J29 -> 10520
E31: =SUM(E6:E29) -> 207500 | F31: =SUM(F6:F29) -> 229287.5 | K31: =SUM(K6:K29) -> 76319.363 | L31: =K31/F31 -> 0.33285444
A33: Comisión Juan | B33: 0.04 | E33: =E31*0.04 -> 8300
A36: S&T CATERING | D36: rto: 2 | E36: 46056
A38: CANTIDAD | B38: UNIDAD | C38: PRODUCTO | D38: PRECIO | E38: TOTAL | I38: PRECIO | J38: TOTAL | K38: DIFERENCIA
A39: 2 | B39: CAJON | C39: ZAPALLITO LARGO | D39: 13000 | E39: =A39*D39 -> 26000 | I39: 8000 | J39: =I39*A39 -> 16000 | K39: =E39-J39 -> 10000
A40: 1 | B40: CAJON | C40: ZAPALLITO REDONDO | D40: 13000 | E40: =A40*D40 -> 13000 | H40: S/COSTO | I40: 0 | J40: =I40*A40 -> 0 | K40: =E40-J40 -> 13000
A41: 2 | B41: CAJON | C41: BERENJENA | D41: 13000 | E41: =A41*D41 -> 26000 | I41: 7000 | J41: =I41*A41 -> 14000 | K41: =E41-J41 -> 12000
A42: 2 | B42: CAJON | C42: LECHUGA FRANCESA | D42: 13000 | E42: =A42*D42 -> 26000 | I42: 10000 | J42: =I42*A42 -> 20000 | K42: =E42-J42 -> 6000
A43: 2 | B43: CAJON | C43: LECHUGA MORADA | D43: 10000 | E43: =A43*D43 -> 20000 | I43: 6000 | J43: =I43*A43 -> 12000 | K43: =E43-J43 -> 8000
A44: 2 | B44: CAJON | C44: RUCULA | D44: 7500 | E44: =A44*D44 -> 15000 | I44: 6000 | J44: =I44*A44 -> 12000 | K44: =E44-J44 -> 3000
A45: 1 | B45: CAJON | C45: CHERRY | D45: 23000 | E45: =A45*D45 -> 23000 | I45: 15000 | J45: =I45*A45 -> 15000 | K45: =E45-J45 -> 8000
E47: =SUM(E39:E45) -> 149000 | K47: =SUM(K39:K45) -> 60000 | L47: =K47/E47 -> 0.40268456
A51: RAKUS | D51: rto: 19 | E51: 46056
A53: CANTIDAD | B53: UNIDAD | C53: PRODUCTO | D53: PRECIO | E53: TOTAL | I53: PRECIO | J53: TOTAL | K53: DIFERENCIA
...

Sheet 04-02-2026 
A3: FV | E3: rto: 224 | F3: 46057 | I3: COMPRA
A5: CANTIDAD | B5: UNIDAD | C5: PRODUCTO | D5: PRECIO | E5: TOTAL | F5: TOTAL + IVA | I5: PRECIO | J5: TOTAL | K5: DIFERENCIA
A6: 3 | B6: CAJA | C6: BANANA | D6: 35000 | E6: =A6*D6 -> 105000 | F6: =E6*1.105 -> 116025 | I6: 25000 | J6: =I6*A6 -> 75000 | K6: =F6-J6 -> 41025
A7: 5 | B7: CAJA | C7: DURAZNO | D7: 34000 | E7: =A7*D7 -> 170000 | F7: =E7*1.105 -> 187850 | I7: 22000 | J7: =I7*A7 -> 110000 | K7: =F7-J7 -> 77850
A8: 3 | B8: CAJA | C8: CIRUELA | D8: 35000 | E8: =A8*D8 -> 105000 | F8: =E8*1.105 -> 116025 | I8: 27000 | J8: =I8*A8 -> 81000 | K8: =F8-J8 -> 35025
A9: 3 | B9: CAJA | C9: PELON | D9: 35000 | E9: =A9*D9 -> 105000 | F9: =E9*1.105 -> 116025 | I9: 20000 | J9: =I9*A9 -> 60000 | K9: =F9-J9 -> 56025
A10: 2 | B10: CAJON | C10: TOMATE REDONDO | D10: 18000 | E10: =A10*D10 -> 36000 | F10: =E10*1.105 -> 39780 | I10: 12000 | J10: =I10*A10 -> 24000 | K10: =F10-J10 -> 15780
A11: 1 | B11: CAJON | C11: HUEVO | D11: 56000 | E11: =A11*D11 -> 56000 | F11: =E11*1.21 -> 67760 | I11: 46000 | J11: =I11*A11 -> 46000 | K11: =F11-J11 -> 21760
A12: 2 | B12: CAJA | C12: MANZANA GRANNY | D12: 63000 | E12: =A12*D12 -> 126000 | F12: =E12*1.105 -> 139230 | I12: 22000 | J12: =I12*A12 -> 44000 | K12: =F12-J12 -> 95230
A13: 15 | B13: UNIDAD | C13: PALTA HASS | D13: 1300 | E13: =A13*D13 -> 19500 | F13: =E13*1.105 -> 21547.5 | I13: =53000/80 -> 662.5 | J13: =I13*A13 -> 9937.5 | K13: =F13-J13 -> 11610
A14: 2 | B14: CAJON | C14: NARANJA | D14: 22000 | E14: =A14*D14 -> 44000 | F14: =E14*1.105 -> 48620 | I14: 18000 | J14: =I14*A14 -> 36000 | K14: =F14-J14 -> 12620
A15: 19 | B15: KG | C15: SANDIA | D15: 1200 | E15: =A15*D15 -> 22800 | F15: =E15*1.105 -> 25194 | I15: 700 | J15: =I15*A15 -> 13300 | K15: =F15-J15 -> 11894
A16: 1 | B16: CAJON | C16: MELON | D16: 22000 | E16: =A16*D16 -> 22000 | F16: =E16*1.105 -> 24310 | I16: 15000 | J16: =I16*A16 -> 15000 | K16: =F16-J16 -> 9310
A17: 2 | B17: CAJON | C17: UVA blanca s/semilla | D17: 40000 | E17: =A17*D17 -> 80000 | F17: =E17*1.105 -> 88400 | I17: 35000 | J17: =I17*A17 -> 70000 | K17: =F17-J17 -> 18400
A18: 1 | B18: CAJA | C18: MANZANA GRANNY | D18: 63000 | E18: =A18*D18 -> 63000 | F18: =E18*1.105 -> 69615 | G18: bolsa | I18: 0 | J18: =I18*A18 -> 0 | K18: =F18-J18 -> 69615
A19: 1 | B19: CAJON | C19: NARANJA | D19: 22000 | E19: =A19*D19 -> 22000 | F19: =E19*1.105 -> 24310 | G19: bolsa | I19: 0 | J19: =I19*A19 -> 0 | K19: =F19-J19 -> 24310
A20: 1 | B20: CAJON | C20: TOMATE REDONDO | D20: 18000 | E20: =A20*D20 -> 18000 | F20: =E20*1.105 -> 19890 | G20: bolsa | I20: 0 | J20: =I20*A20 -> 0 | K20: =F20-J20 -> 19890
A21: 0.5 | B21: CAJON | C21: HUEVO | D21: 56000 | E21: =A21*D21 -> 28000 | F21: =E21*1.21 -> 33880 | G21: bolsa | I21: 0 | J21: =I21*A21 -> 0 | K21: =F21-J21 -> 33880
A22: 1 | B22: CAJON | C22: PELON | D22: 35000 | E22: =A22*D22 -> 35000 | F22: =E22*1.105 -> 38675 | G22: bolsa propia | I22: 0 | J22: =I22*A22 -> 0 | K22: =F22-J22 -> 38675
A23: 1 | B23: CAJON | C23: DURAZNO | D23: 34000 | E23: =A23*D23 -> 34000 | F23: =E23*1.105 -> 37570 | G23: bolsa propia | I23: 0 | J23: =I23*A23 -> 0 | K23: =F23-J23 -> 37570
A24: 3 | B24: CAJA | C24: BANANA | D24: 35000 | E24: =A24*D24 -> 105000 | F24: =E24*1.105 -> 116025 | G24: bolsa propia | I24: 0 | J24: =I24*A24 -> 0 | K24: =F24-J24 -> 116025
E26: =SUM(E6:E24) -> 1196300 | F26: =SUM(F6:F24) -> 1330731.5 | K26: =SUM(K6:K24) -> 746494 | L26: =K26/F26 -> 0.56096515
A29: LA PIADINA | D29: rto: 15 | E29: 46057
A31: CANTIDAD | B31: UNIDAD | C31: PRODUCTO | D31: PRECIO | E31: TOTAL | I31: PRECIO | J31: TOTAL | K31: DIFERENCIA
A32: 1 | B32: KG | C32: BANANA | D32: 2800 | E32: =A32*D32 -> 2800 | H32: S/COSTO | I32: 0 | J32: =I32*A32 -> 0 | K32: =E32-J32 -> 2800
A33: 1 | B33: KG | C33: NARANJA | D33: 1400 | E33: =A33*D33 -> 1400 | H33: S/COSTO | I33: 0 | J33: =I33*A33 -> 0 | K33: =E33-J33 -> 1400
A34: 0.5 | B34: KG | C34: MANZANA | D34: 3500 | E34: =A34*D34 -> 1750 | I34: =50000/18 -> 2777.7778 | J34: =I34*A34 -> 1388.8889 | K34: =E34-J34 -> 361.11111
A35: 1.5 | B35: KG | C35: FRUTILLA | D35: 6000 | E35: =A35*D35 -> 9000 | I35: =20000/5 -> 4000 | J35: =I35*A35 -> 6000 | K35: =E35-J35 -> 3000
A36: 0.35 | B36: KG | C36: DURAZNO | D36: 4500 | E36: =A36*D36 -> 1575 | H36: S/COSTO | I36: 0 | J36: =I36*A36 -> 0 | K36: =E36-J36 -> 1575
A37: 0.3 | B37: KG | C37: KIWI | D37: 12000 | E37: =A37*D37 -> 3600 | I37: =65000/7 -> 9285.7143 | J37: =I37*A37 -> 2785.7143 | K37: =E37-J37 -> 814.28571
A38: 3 | B38: CUBETA | C38: ARANDANO | D38: 2500 | E38: =A38*D38 -> 7500 | I38: =22000/12 -> 1833.3333 | J38: =I38*A38 -> 5500 | K38: =E38-J38 -> 2000
A39: 0.5 | B39: KG | C39: UVA | D39: 4500 | E39: =A39*D39 -> 2250 | H39: S/COSTO | I39: 0 | J39: =I39*A39 -> 0 | K39: =E39-J39 -> 2250
A40: 3 | B40: KG | C40: TOMATE | D40: 1500 | E40: =A40*D40 -> 4500 | I40: =13000/15 -> 866.66667 | J40: =I40*A40 -> 2600 | K40: =E40-J40 -> 1900
A41: 3 | B41: ATADO | C41: ALBAHACA | D41: 1000 | E41: =A41*D41 -> 3000 | I41: 500 | J41: =I41*A41 -> 1500 | K41: =E41-J41 -> 1500
A42: 1 | B42: KG | C42: LECHUGA | D42: 3500 | E42: =A42*D42 -> 3500 | H42: S/COSTO | I42: 0 | J42: =I42*A42 -> 0 | K42: =E42-J42 -> 3500
A43: 4 | B43: UNIDAD | C43: PALTA | D43: 1300 | E43: =A43*D43 -> 5200 | I43: =53000/80 -> 662.5 | J43: =I43*A43 -> 2650 | K43: =E43-J43 -> 2550
E45: =SUM(E32:E43) -> 46075 | K45: =SUM(K32:K42) -> 21100.397 | L45: =K45/E45 -> 0.45795761
A49: HOGAR CARDALES | D49: rto: 5 | E49: 46057
A51: CANTIDAD | B51: UNIDAD | C51: PRODUCTO | D51: PRECIO | E51: TOTAL | I51: PRECIO | J51: TOTAL | K51: DIFERENCIA
A52: 4 | B52: ATADOS | C52: ACELGA | D52: 1500 | E52: =A52*D52 -> 6000 | H52: VERDU | I52: 1500 | J52: =I52*A52 -> 6000 | K52: =E52-J52 -> 0
...

Sheet 05-02-2026 
A4: LA PIADINA | D4: rto: 16 | E4: 46058
A6: CANTIDAD | B6: UNIDAD | C6: PRODUCTO | D6: PRECIO | E6: TOTAL | I6: PRECIO | J6: TOTAL | K6: DIFERENCIA
A7: 1.5 | B7: CAJON | C7: RUCULA | D7: 10000 | E7: =A7*D7 -> 15000 | I7: 8000 | J7: =I7*A7 -> 12000 | K7: =E7-J7 -> 3000
A8: 1 | B8: KG | C8: LECHUGA | D8: 3500 | E8: =A8*D8 -> 3500 | I8: 3500 | J8: =I8*A8 -> 3500 | K8: =E8-J8 -> 0
A9: 4 | B9: KG | C9: TOMATE | D9: 1500 | E9: =A9*D9 -> 6000 | I9: 1500 | J9: =I9*A9 -> 6000 | K9: =E9-J9 -> 0
A10: 1 | B10: ATADO | C10: ESPINACA | D10: 2000 | E10: =A10*D10 -> 2000 | I10: 2000 | J10: =I10*A10 -> 2000 | K10: =E10-J10 -> 0
A11: 4 | B11: UNIDAD | C11: PALTA | D11: 1300 | E11: =A11*D11 -> 5200 | I11: 1300 | J11: =I11*A11 -> 5200 | K11: =E11-J11 -> 0
E13: =SUM(E7:E11) -> 31700 | K13: =SUM(K7:K11) -> 3000 | L13: =K13/E13 -> 0.094637224
A16: LUSQTOFF | B16: SEDE: IRALA | E16: rto: 3 | F16: 46058 | I16: COMPRA
A18: CANTIDAD | B18: UNIDAD | C18: PRODUCTO | D18: PRECIO | E18: TOTAL | F18: TOTAL + IVA | I18: PRECIO | J18: TOTAL | K18: DIFERENCIA
A19: 1 | B19: BOLSA | C19: CEBOLLA | D19: 13000 | E19: =A19*D19 -> 13000 | F19: =E19*1.105 -> 14365 | I19: 0 | J19: =I19*A19 -> 0 | K19: =F19-J19 -> 14365
A20: 1 | B20: CAJON | C20: LECHUGA | D20: 16000 | E20: =A20*D20 -> 16000 | F20: =E20*1.105 -> 17680 | I20: 0 | J20: =I20*A20 -> 0 | K20: =F20-J20 -> 17680
A21: 2 | B21: KG | C21: ZUCCINI | D21: 1500 | E21: =A21*D21 -> 3000 | F21: =E21*1.105 -> 3315 | I21: 0 | J21: =I21*A21 -> 0 | K21: =F21-J21 -> 3315
A22: 2 | B22: KG | C22: MORRON ROJO | D22: 3500 | E22: =A22*D22 -> 7000 | F22: =E22*1.105 -> 7735 | I22: 0 | J22: =I22*A22 -> 0 | K22: =F22-J22 -> 7735
E24: =SUM(E19:E22) -> 39000 | F24: =SUM(F19:F22) -> 43095 | K24: =SUM(K19:K22) -> 43095 | L24: =K24/F24 -> 1
A26: TOTAL DIA | B26: =F24+E13 -> 74795
A28: GANANCIA | B28: =K24+K13 -> 46095
A30: Comision Juan | B30: 0
A32: % | B32: =B28/B26 -> 0.61628451
A34: BULTOS COMPRADOS | C34: 100
B39: EFECTIVO | C39: MERCADO PAGO | D39: BANCO GALCIA | E39: BANCO RIO | F39: CHEQUES
B40: 2528350 | C40: 308459.29 | D40: =2277828.28-500000-1000000+491000 -> 1268828.3 | F40: =8500000+1101582.8 -> 9601582.8
A42: INGRESOS
A43: COBR. CTA. CTE | B43: 319800 | C43: 0 | D43: 0 | E43: 0 | F43: 0
A44: RENDIMIENTO MP | B44: 0 | C44: 3625.2 | D44: 0 | E44: 0 | F44: 0
A45: CHE ACREDITADO | B45: 0 | C45: 0 | D45: 1101582.8 | E45: 0 | F45: 0
A46: COBR. VACIOS | B46: 0 | C46: 0 | D46: 0 | E46: 0 | F46: 0
A47: PRESTAMOS | B47: 0 | C47: 0 | D47: 0 | E47: 0 | F47: 0
A48: IMP. CRED. 0,6% | B48: 0 | C48: =C43*0.6%+C46*0.6% -> 0 | D48: =SUM(D43:D45)*0.6% -> 6609.4968 | E48: 0 | F48: 0
A50: TOTAL | B50: =SUM(B40:B48) -> 2848150 | C50: =C40+C43+C46+C47-C48+C44 -> 312084.49 | D50: =D40+D43+D46+D47-D48+D45 -> 2363801.6 | E50: =E40+E43+E46+E47-E48 -> 0 | F50: =F40+F43+F46+F47-F48-D45 -> 8500000
A52: GASTOS
A53: ING. MERCADO | B53: 10000 | C53: 0 | D53: 0 | E53: 0
A54: CARGA / VACIOS | B54: 0 | C54: 0 | D54: 0 | E54: 0
A55: CHEQ DEBITADO | B55: 0 | C55: 0 | D55: 500000 | E55: 0
A56: PEAJE | B56: 0 | C56: 0 | D56: 0 | E56: 0
A57: MERCADERIA | B57: 0 | C57: 395000 | D57: 0 | E57: 0
A58: COMBUSTIBLE | B58: 40000 | C58: 0 | D58: 0 | E58: 0
A59: SUELDOS | B59: 0 | C59: 0 | D59: 0 | E59: 0
A60: DEV. PRESTAMOS | B60: 0 | C60: 0 | D60: 0 | E60: 0
A61: AGUA | B61: 0 | C61: 0 | D61: 0 | E61: 0
...

Sheet 06-02-2026 
A2: COLEGIO SJCB - VIRREY DEL PINO 3299 | E2: rto: 1 | F2: 46059 | I2: COMPRA
A4: CANTIDAD | B4: UNIDAD | C4: PRODUCTO | D4: PRECIO | E4: TOTAL | F4: TOTAL + IVA | I4: PRECIO | J4: TOTAL | K4: DIFERENCIA
A5: 1 | B5: BOLSA | C5: PAPA | D5: 20000 | E5: =A5*D5 -> 20000 | F5: =E5*1.105 -> 22100 | I5: 17500 | J5: =I5*A5 -> 17500 | K5: =F5-J5 -> 4600
A6: 10 | B6: KG | C6: BATATA | D6: 1400 | E6: =A6*D6 -> 14000 | F6: =E6*1.105 -> 15470 | I6: =9000/11 -> 818.18182 | J6: =I6*A6 -> 8181.8182 | K6: =F6-J6 -> 7288.1818
A7: 12 | B7: KG | C7: ANCO | D7: 1000 | E7: =A7*D7 -> 12000 | F7: =E7*1.105 -> 13260 | I7: =8000/13 -> 615.38462 | J7: =I7*A7 -> 7384.6154 | K7: =F7-J7 -> 5875.3846
A8: 4 | B8: KG | C8: CEBOLLA MORADA | D8: 1600 | E8: =A8*D8 -> 6400 | F8: =E8*1.105 -> 7072 | I8: =1000 -> 1000 | J8: =I8*A8 -> 4000 | K8: =F8-J8 -> 3072
A9: 2 | B9: KG | C9: MORRON ROJO | D9: 3500 | E9: =A9*D9 -> 7000 | F9: =E9*1.105 -> 7735 | I9: =25000/8 -> 3125 | J9: =I9*A9 -> 6250 | K9: =F9-J9 -> 1485
A10: 1 | B10: KG | C10: MORRON VERDE | D10: 2300 | E10: =A10*D10 -> 2300 | F10: =E10*1.105 -> 2541.5 | I10: =12000/7 -> 1714.2857 | J10: =I10*A10 -> 1714.2857 | K10: =F10-J10 -> 827.21429
A11: 1 | B11: KG | C11: MORRON AMARILLO | D11: 3000 | E11: =A11*D11 -> 3000 | F11: =E11*1.105 -> 3315 | I11: =20000/8 -> 2500 | J11: =I11*A11 -> 2500 | K11: =F11-J11 -> 815
A12: 10 | B12: KG | C12: ZANAHORIA | D12: 1500 | E12: =A12*D12 -> 15000 | F12: =E12*1.105 -> 16575 | I12: =8000/8 -> 1000 | J12: =I12*A12 -> 10000 | K12: =F12-J12 -> 6575
A13: 1 | B13: KG | C13: BERENJENA | D13: 1600 | E13: =A13*D13 -> 1600 | F13: =E13*1.105 -> 1768 | I13: =1000 -> 1000 | J13: =I13*A13 -> 1000 | K13: =F13-J13 -> 768
A14: 2 | B14: MAPLE | C14: HUEVO | D14: 4500 | E14: =A14*D14 -> 9000 | F14: =E14*1.21 -> 10890 | I14: =52000/12 -> 4333.3333 | J14: =I14*A14 -> 8666.6667 | K14: =F14-J14 -> 2223.3333
A15: 3 | B15: KG | C15: BANANA | D15: 2500 | E15: =A15*D15 -> 7500 | F15: =E15*1.105 -> 8287.5 | I15: =25000/17 -> 1470.5882 | J15: =I15*A15 -> 4411.7647 | K15: =F15-J15 -> 3875.7353
A16: 5 | B16: KG | C16: MANZANA ROJA | D16: 4500 | E16: =A16*D16 -> 22500 | F16: =E16*1.105 -> 24862.5 | I16: =65000/18 -> 3611.1111 | J16: =I16*A16 -> 18055.556 | K16: =F16-J16 -> 6806.9444
A17: 5 | B17: KG | C17: MANZANA VERDE | D17: 3500 | E17: =A17*D17 -> 17500 | F17: =E17*1.105 -> 19337.5 | I17: =40000/18 -> 2222.2222 | J17: =I17*A17 -> 11111.111 | K17: =F17-J17 -> 8226.3889
A18: 8 | B18: KG | C18: NARANJA | D18: 1400 | E18: =A18*D18 -> 11200 | F18: =E18*1.105 -> 12376 | I18: =18000/16 -> 1125 | J18: =I18*A18 -> 9000 | K18: =F18-J18 -> 3376
A19: 0.2 | B19: KG | C19: PEREJIL | D19: 3500 | E19: =A19*D19 -> 700 | F19: =E19*1.105 -> 773.5 | I19: 1500 | J19: =I19*A19 -> 300 | K19: =F19-J19 -> 473.5
A20: 1 | B20: UNIDAD | C20: REPOLLO BLANCO | D20: 1500 | E20: =A20*D20 -> 1500 | F20: =E20*1.105 -> 1657.5 | I20: =13000/12 -> 1083.3333 | J20: =I20*A20 -> 1083.3333 | K20: =F20-J20 -> 574.16667
A21: 1 | B21: UNIDAD | C21: REPOLLO COLORADO | D21: 1500 | E21: =A21*D21 -> 1500 | F21: =E21*1.105 -> 1657.5 | I21: 1083.33 | J21: =I21*A21 -> 1083.33 | K21: =F21-J21 -> 574.17
A22: 5 | B22: KG | C22: TOMATE PERITA | D22: 1800 | E22: =A22*D22 -> 9000 | F22: =E22*1.105 -> 9945 | I22: =20000/15 -> 1333.3333 | J22: =I22*A22 -> 6666.6667 | K22: =F22-J22 -> 3278.3333
A23: 1 | B23: KG | C23: LECHUGA CRIOLLA | D23: 3000 | E23: =A23*D23 -> 3000 | F23: =E23*1.105 -> 3315 | I23: =10000/5 -> 2000 | J23: =I23*A23 -> 2000 | K23: =F23-J23 -> 1315
A24: 12 | B24: ATADOS | C24: RUCULA | D24: 350 | E24: =A24*D24 -> 4200 | F24: =E24*1.105 -> 4641 | I24: =6000/24 -> 250 | J24: =I24*A24 -> 3000 | K24: =F24-J24 -> 1641
E26: =SUM(E5:E24) -> 168900 | F26: =SUM(F5:F24) -> 187579.5 | K26: =SUM(K5:K24) -> 63670.353 | L26: =K26/F26 -> 0.3394313
A28: COLEGIO ST CATHERINES MOORLANDS - CARBAJAL 3250 | E28: rto: 1 | F28: 46059 | I28: COMPRA
A30: CANTIDAD | B30: UNIDAD | C30: PRODUCTO | D30: PRECIO | E30: TOTAL | F30: TOTAL + IVA | I30: PRECIO | J30: TOTAL | K30: DIFERENCIA
A31: 3 | B31: KG | C31: BANANA | D31: 2500 | E31: =A31*D31 -> 7500 | F31: =E31*1.105 -> 8287.5 | I31: =25000/17 -> 1470.5882 | J31: =I31*A31 -> 4411.7647 | K31: =F31-J31 -> 3875.7353
A32: 1 | B32: UNIDAD | C32: AJO | D32: 900 | E32: =A32*D32 -> 900 | F32: =E32*1.105 -> 994.5 | I32: =23000/50 -> 460 | J32: =I32*A32 -> 460 | K32: =F32-J32 -> 534.5
A33: 1 | B33: BOLSA | C33: BATATA | D33: 14000 | E33: =A33*D33 -> 14000 | F33: =E33*1.105 -> 15470 | I33: 9000 | J33: =I33*A33 -> 9000 | K33: =F33-J33 -> 6470
A34: 2 | B34: BOLSA | C34: ANCO | D34: 13000 | E34: =A34*D34 -> 26000 | F34: =E34*1.105 -> 28730 | I34: 8000 | J34: =I34*A34 -> 16000 | K34: =F34-J34 -> 12730
A35: 3 | B35: KG | C35: CEBOLLA | D35: 800 | E35: =A35*D35 -> 2400 | F35: =E35*1.105 -> 2652 | I35: =9500/18 -> 527.77778 | J35: =I35*A35 -> 1583.3333 | K35: =F35-J35 -> 1068.6667
A36: 6 | B36: KG | C36: CEBOLLA MORADA | D36: 1600 | E36: =A36*D36 -> 9600 | F36: =E36*1.105 -> 10608 | I36: 1000 | J36: =I36*A36 -> 6000 | K36: =F36-J36 -> 4608
A37: 1 | B37: ATADO | C37: CILANTRO | D37: 3000 | E37: =A37*D37 -> 3000 | F37: =E37*1.105 -> 3315 | I37: 2000 | J37: =I37*A37 -> 2000 | K37: =F37-J37 -> 1315
A38: 1 | B38: ATADO | C38: CIBOULETTE | D38: 3000 | E38: =A38*D38 -> 3000 | F38: =E38*1.105 -> 3315 | I38: 2000 | J38: =I38*A38 -> 2000 | K38: =F38-J38 -> 1315
A39: 2 | B39: ATADO | C39: CEBOLLA DE VERDEO | D39: 5500 | E39: =A39*D39 -> 11000 | F39: =E39*1.105 -> 12155 | I39: 3200 | J39: =I39*A39 -> 6400 | K39: =F39-J39 -> 5755
A40: 1 | B40: CAJON | C40: MANZANA ROJA | D40: 80000 | E40: =A40*D40 -> 80000 | F40: =E40*1.105 -> 88400 | I40: 65000 | J40: =I40*A40 -> 65000 | K40: =F40-J40 -> 23400
A41: 1 | B41: CAJON | C41: MANZANA VERDE | D41: 58000 | E41: =A41*D41 -> 58000 | F41: =E41*1.105 -> 64090 | I41: 40000 | J41: =I41*A41 -> 40000 | K41: =F41-J41 -> 24090
A42: 1 | B42: CAJON | C42: NARANJA JUGO | D42: 22000 | E42: =A42*D42 -> 22000 | F42: =E42*1.105 -> 24310 | I42: 18000 | J42: =I42*A42 -> 18000 | K42: =F42-J42 -> 6310
A43: 4 | B43: BOLSA | C43: PAPA LAVADA | D43: 20000 | E43: =A43*D43 -> 80000 | F43: =E43*1.105 -> 88400 | I43: 17500 | J43: =I43*A43 -> 70000 | K43: =F43-J43 -> 18400
A44: 0.5 | B44: ATADO | C44: PEREJIL | D44: 3500 | E44: =A44*D44 -> 1750 | F44: =E44*1.105 -> 1933.75 | I44: 1500 | J44: =I44*A44 -> 750 | K44: =F44-J44 -> 1183.75
A45: 5 | B45: KG | C45: MORRON ROJO | D45: 3500 | E45: =A45*D45 -> 17500 | F45: =E45*1.105 -> 19337.5 | I45: =25000/8 -> 3125 | J45: =I45*A45 -> 15625 | K45: =F45-J45 -> 3712.5
...

Sheet 09-02-2026 
A2: LUSQTOFF | B2: SEDE: MORENO | D2: rto: 2 | E2: 46062 | I2: COMPRA
A4: CANTIDAD | B4: UNIDAD | C4: PRODUCTO | D4: PRECIO | E4: TOTAL | F4: TOTAL + IVA | I4: COSTO | J4: TOTAL | K4: DIFERENCIA
A5: 2 | B5: UNIDAD | C5: ESPINACA | D5: 1800 | E5: =A5*D5 -> 3600 | F5: =E5*1.105 -> 3978 | I5: =7200/6 -> 1200 | J5: =I5*A5 -> 2400 | K5: =F5-J5 -> 1578
A6: 2 | B6: BOLSA | C6: PAPA CEPILLADA | D6: 14000 | E6: =A6*D6 -> 28000 | F6: =E6*1.105 -> 30940 | I6: 13000 | J6: =I6*A6 -> 26000 | K6: =F6-J6 -> 4940
A7: 2 | B7: BOLSA | C7: ANCO | D7: 13000 | E7: =A7*D7 -> 26000 | F7: =E7*1.105 -> 28730 | I7: 8000 | J7: =I7*A7 -> 16000 | K7: =F7-J7 -> 12730
A8: 1 | B8: CAJON | C8: ACELGA | D8: 15000 | E8: =A8*D8 -> 15000 | F8: =E8*1.105 -> 16575 | I8: 12000 | J8: =I8*A8 -> 12000 | K8: =F8-J8 -> 4575
A9: 1 | B9: ATADOS | C9: RABANITO | D9: 850 | E9: =A9*D9 -> 850 | F9: =E9*1.105 -> 939.25 | I9: 1600 | J9: =I9*A9 -> 1600 | K9: =F9-J9 -> -660.75
A10: 2 | B10: UNIDAD | C10: REMOLACHA | D10: 1800 | E10: =A10*D10 -> 3600 | F10: =E10*1.105 -> 3978 | I10: 1400 | J10: =I10*A10 -> 2800 | K10: =F10-J10 -> 1178
A11: 0.5 | B11: CAJON | C11: ZAPALLITO REDONDO | D11: 10000 | E11: =A11*D11 -> 5000 | F11: =E11*1.105 -> 5525 | I11: 6000 | J11: =I11*A11 -> 3000 | K11: =F11-J11 -> 2525
A12: 0.5 | B12: CAJON | C12: ZUCCINI | D12: 11000 | E12: =A12*D12 -> 5500 | F12: =E12*1.105 -> 6077.5 | I12: 7000 | J12: =I12*A12 -> 3500 | K12: =F12-J12 -> 2577.5
A13: 3 | B13: KG | C13: BERENJENA | D13: 1500 | E13: =A13*D13 -> 4500 | F13: =E13*1.105 -> 4972.5 | I13: 600 | J13: =I13*A13 -> 1800 | K13: =F13-J13 -> 3172.5
A14: 1 | B14: CAJON | C14: LECHUGA FRANCESA | D14: 14000 | E14: =A14*D14 -> 14000 | F14: =E14*1.105 -> 15470 | I14: 8000 | J14: =I14*A14 -> 8000 | K14: =F14-J14 -> 7470
A15: 0.5 | B15: CAJON | C15: TOMATE REDONDO | D15: 20000 | E15: =A15*D15 -> 10000 | F15: =E15*1.105 -> 11050 | I15: 12000 | J15: =I15*A15 -> 6000 | K15: =F15-J15 -> 5050
A16: 0.5 | B16: BOLSA | C16: ZANAHORIA CUBITO | D16: 12000 | E16: =A16*D16 -> 6000 | F16: =E16*1.105 -> 6630 | I16: 8000 | J16: =I16*A16 -> 4000 | K16: =F16-J16 -> 2630
A17: 1 | B17: BOLSA | C17: CEBOLLA | D17: 13000 | E17: =A17*D17 -> 13000 | F17: =E17*1.105 -> 14365 | I17: 9000 | J17: =I17*A17 -> 9000 | K17: =F17-J17 -> 5365
A18: 3 | B18: KG | C18: MORRÓN ROJO | D18: 3800 | E18: =A18*D18 -> 11400 | F18: =E18*1.105 -> 12597 | I18: =25000/8 -> 3125 | J18: =I18*A18 -> 9375 | K18: =F18-J18 -> 3222
A19: 2.7 | B19: KG | C19: MORRÓN VERDE | D19: 2800 | E19: =A19*D19 -> 7560 | F19: =E19*1.105 -> 8353.8 | I19: =12000/7 -> 1714.2857 | J19: =I19*A19 -> 4628.5714 | K19: =F19-J19 -> 3725.2286
A20: 2 | B20: KG | C20: LIMON | D20: 2700 | E20: =A20*D20 -> 5400 | F20: =E20*1.105 -> 5967 | I20: =28000/18 -> 1555.5556 | J20: =I20*A20 -> 3111.1111 | K20: =F20-J20 -> 2855.8889
A21: 2 | B21: UNIDAD | C21: REPOLLO BLANCO | D21: 1800 | E21: =A21*D21 -> 3600 | F21: =E21*1.105 -> 3978 | I21: 1600 | J21: =I21*A21 -> 3200 | K21: =F21-J21 -> 778
A22: 1 | B22: CAJON | C22: MANZANA ROJA | D22: 58000 | E22: =A22*D22 -> 58000 | F22: =E22*1.105 -> 64090 | I22: 50000 | J22: =I22*A22 -> 50000 | K22: =F22-J22 -> 14090
A23: 1 | B23: CAJON | C23: NARANJA DE JUGO | D23: 22000 | E23: =A23*D23 -> 22000 | F23: =E23*1.105 -> 24310 | I23: 18000 | J23: =I23*A23 -> 18000 | K23: =F23-J23 -> 6310
A24: 0.5 | B24: CAJON | C24: BANANA ECUADOR | D24: 35000 | E24: =A24*D24 -> 17500 | F24: =E24*1.105 -> 19337.5 | I24: 27000 | J24: =I24*A24 -> 13500 | K24: =F24-J24 -> 5837.5
A25: 2 | B25: KG | C25: FRUTILLA | D25: 12000 | E25: =A25*D25 -> 24000 | F25: =E25*1.105 -> 26520 | I25: 10000 | J25: =I25*A25 -> 20000 | K25: =F25-J25 -> 6520
A26: 2 | B26: KG | C26: KIWI | D26: 10500 | E26: =A26*D26 -> 21000 | F26: =E26*1.105 -> 23205 | I26: =60000/8 -> 7500 | J26: =I26*A26 -> 15000 | K26: =F26-J26 -> 8205
A27: 2 | B27: KG | C27: UVA | D27: 4500 | E27: =A27*D27 -> 9000 | F27: =E27*1.105 -> 9945 | I27: 3500 | J27: =I27*A27 -> 7000 | K27: =F27-J27 -> 2945
A28: 7 | B28: UNIDAD | C28: CHOCLO | D28: 800 | E28: =A28*D28 -> 5600 | F28: =E28*1.105 -> 6188 | I28: =4900/7 -> 700 | J28: =I28*A28 -> 4900 | K28: =F28-J28 -> 1288
E30: =SUM(E5:E28) -> 320110 | F30: =SUM(F5:F28) -> 353721.55 | K30: =SUM(K5:K28) -> 108906.87 | L30: =K30/F30 -> 0.3078887
A32: Comisión Juan | B32: 0.04 | E32: =E30*0.04 -> 12804.4
A34: LUSQTOFF | B34: SEDE: IRALA | E34: rto: 4 | F34: 46062 | I34: COMPRA
A36: CANTIDAD | B36: UNIDAD | C36: PRODUCTO | D36: PRECIO | E36: TOTAL | F36: TOTAL + IVA | I36: PRECIO | J36: TOTAL | K36: DIFERENCIA
A37: 1 | B37: BOLSA | C37: CEBOLLA | D37: 13000 | E37: =A37*D37 -> 13000 | F37: =E37*1.105 -> 14365 | I37: 9000 | J37: =I37*A37 -> 9000 | K37: =F37-J37 -> 5365
A38: 4 | B38: KG | C38: MORRON ROJO | D38: 3800 | E38: =A38*D38 -> 15200 | F38: =E38*1.105 -> 16796 | I38: =25000/8 -> 3125 | J38: =I38*A38 -> 12500 | K38: =F38-J38 -> 4296
A39: 4 | B39: KG | C39: MORRON VERDE | D39: 2800 | E39: =A39*D39 -> 11200 | F39: =E39*1.105 -> 12376 | I39: =12000/7 -> 1714.2857 | J39: =I39*A39 -> 6857.1429 | K39: =F39-J39 -> 5518.8571
A40: 3 | B40: ATADO | C40: ESPINACA | D40: 1800 | E40: =A40*D40 -> 5400 | F40: =E40*1.105 -> 5967 | I40: =7200/6 -> 1200 | J40: =I40*A40 -> 3600 | K40: =F40-J40 -> 2367
A41: 1 | B41: CAJON | C41: ZUCCINI | D41: 11000 | E41: =A41*D41 -> 11000 | F41: =E41*1.105 -> 12155 | I41: 7000 | J41: =I41*A41 -> 7000 | K41: =F41-J41 -> 5155
A42: 0.5 | B42: CAJON | C42: BERENJENA | D42: 13000 | E42: =A42*D42 -> 6500 | F42: =E42*1.105 -> 7182.5 | I42: 6000 | J42: =I42*A42 -> 3000 | K42: =F42-J42 -> 4182.5
A43: 1 | B43: BOLSA | C43: ZANAHORIA | D43: 12000 | E43: =A43*D43 -> 12000 | F43: =E43*1.105 -> 13260 | I43: 8000 | J43: =I43*A43 -> 8000 | K43: =F43-J43 -> 5260
A44: 2 | B44: BOLSA | C44: ANCO | D44: 13000 | E44: =A44*D44 -> 26000 | F44: =E44*1.105 -> 28730 | I44: 8000 | J44: =I44*A44 -> 16000 | K44: =F44-J44 -> 12730
A45: 5 | B45: KG | C45: BATATA | D45: 1500 | E45: =A45*D45 -> 7500 | F45: =E45*1.105 -> 8287.5 | I45: 1100 | J45: =I45*A45 -> 5500 | K45: =F45-J45 -> 2787.5
A46: 5 | B46: KG | C46: TOMATE REDONDO | D46: 1500 | E46: =A46*D46 -> 7500 | F46: =E46*1.105 -> 8287.5 | I46: =12000/18 -> 666.66667 | J46: =I46*A46 -> 3333.3333 | K46: =F46-J46 -> 4954.1667
...

Sheet 10-02-2026 
A2: COLEGIO SJCB - VIRREY DEL PINO 3299 | E2: rto: 2 | F2: 46063 | I2: COMPRA
A4: CANTIDAD | B4: UNIDAD | C4: PRODUCTO | D4: PRECIO | E4: TOTAL | F4: TOTAL + IVA | I4: COSTO | J4: TOTAL | K4: DIFERENCIA
A5: 2 | B5: KG | C5: MORRON ROJO | D5: 4000 | E5: =A5*D5 -> 8000 | F5: =E5*1.105 -> 8840 | I5: =25000/7 -> 3571.4286 | J5: =I5*A5 -> 7142.8571 | K5: =F5-J5 -> 1697.1429
A6: 1 | B6: KG | C6: MORRON VERDE | D6: 3100 | E6: =A6*D6 -> 3100 | F6: =E6*1.105 -> 3425.5 | I6: =13000/7 -> 1857.1429 | J6: =I6*A6 -> 1857.1429 | K6: =F6-J6 -> 1568.3571
A7: 1 | B7: KG | C7: MORRON AMARILLO | D7: 4000 | E7: =A7*D7 -> 4000 | F7: =E7*1.105 -> 4420 | I7: =25000/7 -> 3571.4286 | J7: =I7*A7 -> 3571.4286 | K7: =F7-J7 -> 848.57143
A8: 5 | B8: KG | C8: CEBOLLA MORADA | D8: 1600 | E8: =A8*D8 -> 8000 | F8: =E8*1.105 -> 8840 | I8: 1000 | J8: =I8*A8 -> 5000 | K8: =F8-J8 -> 3840
A9: 1 | B9: BOLSA | C9: ZANAHORIA CUBITO | D9: 12000 | E9: =A9*D9 -> 12000 | F9: =E9*1.105 -> 13260 | I9: 9000 | J9: =I9*A9 -> 9000 | K9: =F9-J9 -> 4260
A10: 1 | B10: BOLSA | C10: PAPA LAVADA | D10: 21000 | E10: =A10*D10 -> 21000 | F10: =E10*1.105 -> 23205 | I10: 19000 | J10: =I10*A10 -> 19000 | K10: =F10-J10 -> 4205
A11: 1 | B11: UNIDAD | C11: CIBOULETTE | D11: 3000 | E11: =A11*D11 -> 3000 | F11: =E11*1.105 -> 3315 | I11: 2000 | J11: =I11*A11 -> 2000 | K11: =F11-J11 -> 1315
A12: 0.25 | B12: UNIDAD | C12: APIO | D12: 2500 | E12: =A12*D12 -> 625 | F12: =E12*1.105 -> 690.625 | I12: 2000 | J12: =I12*A12 -> 500 | K12: =F12-J12 -> 190.625
A13: 0.5 | B13: KG | C13: CEBOLLA | D13: 800 | E13: =A13*D13 -> 400 | F13: =E13*1.105 -> 442 | I13: 500 | J13: =I13*A13 -> 250 | K13: =F13-J13 -> 192
A14: 6 | B14: KG | C14: TOMATE PERITA | D14: 1600 | E14: =A14*D14 -> 9600 | F14: =E14*1.105 -> 10608 | I14: 1000 | J14: =I14*A14 -> 6000 | K14: =F14-J14 -> 4608
A15: 18 | B15: ATADOS | C15: RUCULA | D15: 500 | E15: =A15*D15 -> 9000 | F15: =E15*1.105 -> 9945 | I15: 416 | J15: =I15*A15 -> 7488 | K15: =F15-J15 -> 2457
A16: 1.25 | B16: KG | C16: LECHUGA CRIOLLA | D16: 3500 | E16: =A16*D16 -> 4375 | F16: =E16*1.105 -> 4834.375 | I16: 2500 | J16: =I16*A16 -> 3125 | K16: =F16-J16 -> 1709.375
A17: 4 | B17: KG | C17: NARANJA DE JUGO | D17: 1400 | E17: =A17*D17 -> 5600 | F17: =E17*1.105 -> 6188 | I17: 1000 | J17: =I17*A17 -> 4000 | K17: =F17-J17 -> 2188
A18: 4 | B18: KG | C18: MANZANA ROJA ELEGIDA | D18: 4500 | E18: =A18*D18 -> 18000 | F18: =E18*1.105 -> 19890 | I18: =60000/18 -> 3333.3333 | J18: =I18*A18 -> 13333.333 | K18: =F18-J18 -> 6556.6667
A19: 3 | B19: KG | C19: BANANA ECUADOR | D19: 2500 | E19: =A19*D19 -> 7500 | F19: =E19*1.105 -> 8287.5 | I19: =27000/18 -> 1500 | J19: =I19*A19 -> 4500 | K19: =F19-J19 -> 3787.5
A20: 2 | B20: MAPLE | C20: HUEVO N1 | D20: 4500 | E20: =A20*D20 -> 9000 | F20: =E20*1.21 -> 10890 | I20: =50000/12 -> 4166.6667 | J20: =I20*A20 -> 8333.3333 | K20: =F20-J20 -> 2556.6667
A21: 0.5 | B21: ATADOS | C21: CEBOLLA DE VERDEO | D21: 5000 | E21: =A21*D21 -> 2500 | F21: =E21*1.105 -> 2762.5 | I21: 4000 | J21: =I21*A21 -> 2000 | K21: =F21-J21 -> 762.5
A22: 4 | B22: KG | C22: MANDARINA | D22: 1600 | E22: =A22*D22 -> 6400 | F22: =E22*1.105 -> 7072 | I22: =40000/18 -> 2222.2222 | J22: =I22*A22 -> 8888.8889 | K22: =F22-J22 -> -1816.8889
A23: 0.5 | B23: KG | C23: BERENJENA | D23: 1600 | E23: =A23*D23 -> 800 | F23: =E23*1.105 -> 884 | I23: 600 | J23: =I23*A23 -> 300 | K23: =F23-J23 -> 584
E25: =SUM(E5:E23) -> 132900 | F25: =SUM(F5:F23) -> 147799.5 | K25: =SUM(K5:K23) -> 41509.516 | L25: =K25/F25 -> 0.28085018
A28: COLEGIO ST CATHERINES MOORLANDS - CARBAJAL 3250 | E28: rto: 2 | F28: 46063 | I28: COMPRA
A30: CANTIDAD | B30: UNIDAD | C30: PRODUCTO | D30: PRECIO | E30: TOTAL | F30: TOTAL + IVA | I30: PRECIO | J30: TOTAL | K30: DIFERENCIA
A31: 3 | B31: KG | C31: BANANA ECUADOR | D31: 2500 | E31: =A31*D31 -> 7500 | F31: =E31*1.105 -> 8287.5 | I31: 1500 | J31: =I31*A31 -> 4500 | K31: =F31-J31 -> 3787.5
A32: 2 | B32: KG | C32: MANDARINA | D32: 1600 | E32: =A32*D32 -> 3200 | F32: =E32*1.105 -> 3536 | I32: =40000/18 -> 2222.2222 | J32: =I32*A32 -> 4444.4444 | K32: =F32-J32 -> -908.44444
A33: 2 | B33: UNIDAD | C33: AJO | D33: 900 | E33: =A33*D33 -> 1800 | F33: =E33*1.105 -> 1989 | I33: 460 | J33: =I33*A33 -> 920 | K33: =F33-J33 -> 1069
A34: 1 | B34: BOLSA | C34: BATATA | D34: 14000 | E34: =A34*D34 -> 14000 | F34: =E34*1.105 -> 15470 | I34: 10000 | J34: =I34*A34 -> 10000 | K34: =F34-J34 -> 5470
A35: 6 | B35: KG | C35: CEBOLLA | D35: 800 | E35: =A35*D35 -> 4800 | F35: =E35*1.105 -> 5304 | I35: 500 | J35: =I35*A35 -> 3000 | K35: =F35-J35 -> 2304
A36: 6 | B36: KG | C36: CEBOLLA MORADA | D36: 1600 | E36: =A36*D36 -> 9600 | F36: =E36*1.105 -> 10608 | I36: 1000 | J36: =I36*A36 -> 6000 | K36: =F36-J36 -> 4608
A37: 1 | B37: UNIDAD | C37: CILANTRO | D37: 3000 | E37: =A37*D37 -> 3000 | F37: =E37*1.105 -> 3315 | I37: 1000 | J37: =I37*A37 -> 1000 | K37: =F37-J37 -> 2315
A38: 0.5 | B38: ATADO | C38: CEBOLLA DE VERDEO | D38: 5000 | E38: =A38*D38 -> 2500 | F38: =E38*1.105 -> 2762.5 | I38: 4000 | J38: =I38*A38 -> 2000 | K38: =F38-J38 -> 762.5
A39: 1.5 | B39: CAJON | C39: MANZANA ROJA ELEGIDA | D39: 80000 | E39: =A39*D39 -> 120000 | F39: =E39*1.105 -> 132600 | I39: 60000 | J39: =I39*A39 -> 90000 | K39: =F39-J39 -> 42600
A40: 1.5 | B40: CAJON | C40: MANZANA GRANNY | D40: 58000 | E40: =A40*D40 -> 87000 | F40: =E40*1.105 -> 96135 | I40: 45000 | J40: =I40*A40 -> 67500 | K40: =F40-J40 -> 28635
A41: 1 | B41: CAJON | C41: NARANJA JUGO | D41: 22000 | E41: =A41*D41 -> 22000 | F41: =E41*1.105 -> 24310 | I41: 18000 | J41: =I41*A41 -> 18000 | K41: =F41-J41 -> 6310
A42: 4 | B42: BOLSA | C42: PAPA LAVADA | D42: 21000 | E42: =A42*D42 -> 84000 | F42: =E42*1.105 -> 92820 | I42: 19000 | J42: =I42*A42 -> 76000 | K42: =F42-J42 -> 16820
A43: 1 | B43: ATADO | C43: PEREJIL | D43: 3500 | E43: =A43*D43 -> 3500 | F43: =E43*1.105 -> 3867.5 | I43: 2000 | J43: =I43*A43 -> 2000 | K43: =F43-J43 -> 1867.5
A44: 4 | B44: KG | C44: MORRON ROJO | D44: 4000 | E44: =A44*D44 -> 16000 | F44: =E44*1.105 -> 17680 | I44: =25000/7 -> 3571.4286 | J44: =I44*A44 -> 14285.714 | K44: =F44-J44 -> 3394.2857
A45: 3 | B45: KG | C45: MORRON VERDE | D45: 3100 | E45: =A45*D45 -> 9300 | F45: =E45*1.105 -> 10276.5 | I45: =13000/7 -> 1857.1429 | J45: =I45*A45 -> 5571.4286 | K45: =F45-J45 -> 4705.0714
A46: 6 | B46: KG | C46: REPOLLO BLANCO | D46: 1500 | E46: =A46*D46 -> 9000 | F46: =E46*1.105 -> 9945 | I46: 882 | J46: =I46*A46 -> 5292 | K46: =F46-J46 -> 4653
...

Sheet 11-02-2026 
A2: FV | E2: rto: 228 | F2: 46064 | I2: COMPRA
A4: CANTIDAD | B4: UNIDAD | C4: PRODUCTO | D4: PRECIO | E4: TOTAL | F4: TOTAL + IVA | I4: PRECIO | J4: TOTAL | K4: DIFERENCIA
A5: 0.5 | B5: CAJON | C5: HUEVO | D5: 56000 | E5: =A5*D5 -> 28000 | F5: =E5*1.21 -> 33880 | I5: 50000 | J5: =I5*A5 -> 25000 | K5: =F5-J5 -> 8880
A6: 2 | B6: CAJON | C6: DURAZNO | D6: 40000 | E6: =A6*D6 -> 80000 | F6: =E6*1.105 -> 88400 | I6: 27000 | J6: =I6*A6 -> 54000 | K6: =F6-J6 -> 34400
A7: 2 | B7: CAJON | C7: CIRUELA | D7: 42000 | E7: =A7*D7 -> 84000 | F7: =E7*1.105 -> 92820 | I7: 26000 | J7: =I7*A7 -> 52000 | K7: =F7-J7 -> 40820
A8: 2 | B8: CAJON | C8: BANANA ECUADOR | D8: 35000 | E8: =A8*D8 -> 70000 | F8: =E8*1.105 -> 77350 | I8: 28000 | J8: =I8*A8 -> 56000 | K8: =F8-J8 -> 21350
A9: 2 | B9: CAJON | C9: NARANJA JUGO | D9: 22000 | E9: =A9*D9 -> 44000 | F9: =E9*1.105 -> 48620 | I9: 19000 | J9: =I9*A9 -> 38000 | K9: =F9-J9 -> 10620
A10: 2 | B10: CAJON | C10: MANZANA GRANNY | D10: 63000 | E10: =A10*D10 -> 126000 | F10: =E10*1.105 -> 139230 | I10: 21000 | J10: =I10*A10 -> 42000 | K10: =F10-J10 -> 97230
A11: 2 | B11: CAJON | C11: PELON | D11: 35000 | E11: =A11*D11 -> 70000 | F11: =E11*1.105 -> 77350 | I11: 25000 | J11: =I11*A11 -> 50000 | K11: =F11-J11 -> 27350
A12: 2 | B12: CAJON | C12: TOMATE REDONDO | D12: 23000 | E12: =A12*D12 -> 46000 | F12: =E12*1.105 -> 50830 | I12: 13000 | J12: =I12*A12 -> 26000 | K12: =F12-J12 -> 24830
A13: 2 | B13: CAJON | C13: TOMATE CHERRY | D13: 30000 | E13: =A13*D13 -> 60000 | F13: =E13*1.105 -> 66300 | I13: 15000 | J13: =I13*A13 -> 30000 | K13: =F13-J13 -> 36300
A14: 1 | B14: CAJON | C14: TOMATE CHERRY | D14: 30000 | E14: =A14*D14 -> 30000 | F14: =E14*1.105 -> 33150 | G14: BOLSA | I14: 0 | J14: =I14*A14 -> 0 | K14: =F14-J14 -> 33150
A15: 1 | B15: CAJON | C15: TOMATE REDONDO | D15: 23000 | E15: =A15*D15 -> 23000 | F15: =E15*1.105 -> 25415 | G15: BOLSA | I15: 0 | J15: =I15*A15 -> 0 | K15: =F15-J15 -> 25415
A16: 1 | B16: CAJON | C16: MANZANA GRANNY | D16: 63000 | E16: =A16*D16 -> 63000 | F16: =E16*1.105 -> 69615 | G16: BOLSA PROPIA | I16: 0 | J16: =I16*A16 -> 0 | K16: =F16-J16 -> 69615
A17: 1 | B17: CAJON | C17: BANANA ECUADOR | D17: 35000 | E17: =A17*D17 -> 35000 | F17: =E17*1.105 -> 38675 | G17: BOLSA | I17: 0 | J17: =I17*A17 -> 0 | K17: =F17-J17 -> 38675
A18: 1 | B18: CAJON | C18: CIRUELA | D18: 42000 | E18: =A18*D18 -> 42000 | F18: =E18*1.105 -> 46410 | G18: BOLSA | I18: 0 | J18: =I18*A18 -> 0 | K18: =F18-J18 -> 46410
A19: 1 | B19: CAJA | C19: DURAZNO | D19: 40000 | E19: =A19*D19 -> 40000 | F19: =E19*1.105 -> 44200 | G19: BOLSA | I19: 0 | J19: =I19*A19 -> 0 | K19: =F19-J19 -> 44200
A20: 0.5 | B20: CAJA | C20: HUEVO | D20: 56000 | E20: =A20*D20 -> 28000 | F20: =E20*1.21 -> 33880 | G20: BOLSA | J20: =I20*A20 -> 0 | K20: =F20-J20 -> 33880
E22: =SUM(E5:E20) -> 869000 | F22: =SUM(F5:F20) -> 966125 | K22: =SUM(K5:K20) -> 593125 | L22: =K22/F22 -> 0.61392159
A27: HOGAR CARDALES | D27: rto: 6 | E27: 46064
A29: CANTIDAD | B29: UNIDAD | C29: PRODUCTO | D29: PRECIO | E29: TOTAL | I29: PRECIO | J29: TOTAL | K29: DIFERENCIA
A30: 2 | B30: UNIDAD | C30: AJO | D30: 1200 | E30: =A30*D30 -> 2400 | I30: 460 | J30: =I30*A30 -> 920 | K30: =E30-J30 -> 1480
A31: 4 | B31: KG | C31: BONIATO | D31: 3200 | E31: =A31*D31 -> 12800 | I31: 2000 | J31: =I31*A31 -> 8000 | K31: =E31-J31 -> 4800
A32: 3 | B32: KG | C32: BERENJENA | D32: 1800 | E32: =A32*D32 -> 5400 | I32: 1500 | J32: =I32*A32 -> 4500 | K32: =E32-J32 -> 900
A33: 2 | B33: UNIDAD | C33: BROCOLI | D33: 2000 | E33: =A33*D33 -> 4000 | H33: S/C | I33: 0 | J33: =I33*A33 -> 0 | K33: =E33-J33 -> 4000
A34: 1 | B34: KG | C34: CHAUCHA | D34: 4500 | E34: =A34*D34 -> 4500 | I34: =15000/7 -> 2142.8571 | J34: =I34*A34 -> 2142.8571 | K34: =E34-J34 -> 2357.1429
A35: 2 | B35: KG | C35: TOMATE CHERRY | D35: 2800 | E35: =A35*D35 -> 5600 | I35: 1500 | J35: =I35*A35 -> 3000 | K35: =E35-J35 -> 2600
A36: 6 | B36: KG | C36: ESPINACA | D36: 1400 | E36: =A36*D36 -> 8400 | I36: =8000/12 -> 666.66667 | J36: =I36*A36 -> 4000 | K36: =E36-J36 -> 4400
A37: 3 | B37: ATADO | C37: MORRON ROJO | D37: 4500 | E37: =A37*D37 -> 13500 | I37: =25000/7 -> 3571.4286 | J37: =I37*A37 -> 10714.286 | K37: =E37-J37 -> 2785.7143
A38: 3 | B38: KG | C38: LECHUGA FRANCESA | D38: 3000 | E38: =A38*D38 -> 9000 | H38: S/C | I38: 0 | J38: =I38*A38 -> 0 | K38: =E38-J38 -> 9000
A39: 6 | B39: ATADO | C39: REMOLACHA | D39: 2200 | E39: =A39*D39 -> 13200 | I39: 1500 | J39: =I39*A39 -> 9000 | K39: =E39-J39 -> 4200
A40: 1.65 | B40: KG | C40: REPOLLO | D40: 1800 | E40: =A40*D40 -> 2970 | I40: 882 | J40: =I40*A40 -> 1455.3 | K40: =E40-J40 -> 1514.7
A41: 3 | B41: ATADO | C41: RUCULA | D41: 500 | E41: =A41*D41 -> 1500 | I41: 500 | J41: =I41*A41 -> 1500 | K41: =E41-J41 -> 0
A42: 6 | B42: KG | C42: TOMATE REDONDO | D42: 1700 | E42: =A42*D42 -> 10200 | I42: =13000/18 -> 722.22222 | J42: =I42*A42 -> 4333.3333 | K42: =E42-J42 -> 5866.6667
A43: 3 | B43: KG | C43: ZAPALLITO REDONDO | D43: 1500 | E43: =A43*D43 -> 4500 | I43: 1000 | J43: =I43*A43 -> 3000 | K43: =E43-J43 -> 1500
A44: 2 | B44: KG | C44: ZUCCINI | D44: 1500 | E44: =A44*D44 -> 3000 | I44: =8000/16 -> 500 | J44: =I44*A44 -> 1000 | K44: =E44-J44 -> 2000
A45: 1 | B45: BOLSA | C45: CABUTIA | D45: 12000 | E45: =A45*D45 -> 12000 | I45: 9000 | J45: =I45*A45 -> 9000 | K45: =E45-J45 -> 3000
A46: 0.5 | B46: BOLSA | C46: CEBOLLA | D46: 12500 | E46: =A46*D46 -> 6250 | I46: 9000 | J46: =I46*A46 -> 4500 | K46: =E46-J46 -> 1750
A47: 1 | B47: BOLSA | C47: PAPA | D47: 16000 | E47: =A47*D47 -> 16000 | I47: 13000 | J47: =I47*A47 -> 13000 | K47: =E47-J47 -> 3000
A48: 1 | B48: BOLSA | C48: ZANAHORIA | D48: 12000 | E48: =A48*D48 -> 12000 | I48: 9000 | J48: =I48*A48 -> 9000 | K48: =E48-J48 -> 3000
...

Sheet 12-02-2026 
A2: FV | E2: rto: 229 | F2: 46065 | I2: COMPRA
A4: CANTIDAD | B4: UNIDAD | C4: PRODUCTO | D4: PRECIO | E4: TOTAL | F4: TOTAL + IVA | I4: PRECIO | J4: TOTAL | K4: DIFERENCIA
A5: 4 | B5: CAJON | C5: CIRUELA | D5: 42000 | E5: =A5*D5 -> 168000 | F5: =E5*1.105 -> 185640 | I5: 26000 | J5: =I5*A5 -> 104000 | K5: =F5-J5 -> 81640
A6: 5 | B6: CAJON | C6: BANANA | D6: 35000 | E6: =A6*D6 -> 175000 | F6: =E6*1.105 -> 193375 | I6: 27000 | J6: =I6*A6 -> 135000 | K6: =F6-J6 -> 58375
A7: 5 | B7: CAJON | C7: DURAZNO | D7: 40000 | E7: =A7*D7 -> 200000 | F7: =E7*1.105 -> 221000 | I7: 27000 | J7: =I7*A7 -> 135000 | K7: =F7-J7 -> 86000
A8: 4 | B8: CAJON | C8: PELON | D8: 35000 | E8: =A8*D8 -> 140000 | F8: =E8*1.105 -> 154700 | I8: 20000 | J8: =I8*A8 -> 80000 | K8: =F8-J8 -> 74700
A9: 3 | B9: CAJON | C9: MANZANA GRANNY | D9: 63000 | E9: =A9*D9 -> 189000 | F9: =E9*1.105 -> 208845 | I9: 50000 | J9: =I9*A9 -> 150000 | K9: =F9-J9 -> 58845
A10: 1 | B10: CAJON | C10: HUEVO | D10: 56000 | E10: =A10*D10 -> 56000 | F10: =E10*1.21 -> 67760 | I10: 50000 | J10: =I10*A10 -> 50000 | K10: =F10-J10 -> 17760
A11: 0.5 | B11: CAJON | C11: HUEVO | D11: 56000 | E11: =A11*D11 -> 28000 | F11: =E11*1.21 -> 33880 | G11: BOLSA | I11: 0 | J11: =I11*A11 -> 0 | K11: =F11-J11 -> 33880
A12: 1 | B12: CAJON | C12: MANZANA GRANNY | D12: 63000 | E12: =A12*D12 -> 63000 | F12: =E12*1.105 -> 69615 | G12: BOLSA | I12: 0 | J12: =I12*A12 -> 0 | K12: =F12-J12 -> 69615
A13: 1 | B13: CAJON | C13: CIRUELA | D13: 42000 | E13: =A13*D13 -> 42000 | F13: =E13*1.105 -> 46410 | G13: BOLSA | I13: 0 | J13: =I13*A13 -> 0 | K13: =F13-J13 -> 46410
A14: 1 | B14: CAJON | C14: PELON | D14: 35000 | E14: =A14*D14 -> 35000 | F14: =E14*1.105 -> 38675 | G14: BOLSA | I14: 0 | J14: =I14*A14 -> 0 | K14: =F14-J14 -> 38675
A15: 1 | B15: CAJON | C15: BANANA | D15: 35000 | E15: =A15*D15 -> 35000 | F15: =E15*1.105 -> 38675 | G15: BOLSA | I15: 0 | J15: =I15*A15 -> 0 | K15: =F15-J15 -> 38675
E17: =SUM(E5:E15) -> 1131000 | F17: =SUM(F5:F15) -> 1258575 | K17: =SUM(K5:K15) -> 604575 | L17: =K17/F17 -> 0.4803647
A22: BRASOV | D22: rto: 13 | E22: 46065
A24: CANTIDAD | B24: UNIDAD | C24: PRODUCTO | D24: PRECIO | E24: TOTAL | I24: PRECIO | J24: TOTAL | K24: DIFERENCIA
A25: 2 | B25: BOLSA | C25: ANCO | D25: 13000 | E25: =A25*D25 -> 26000 | I25: 9000 | J25: =I25*A25 -> 18000 | K25: =E25-J25 -> 8000
A26: 4 | B26: BOLSA | C26: PAPA | D26: 21000 | E26: =A26*D26 -> 84000 | I26: 18000 | J26: =I26*A26 -> 72000 | K26: =E26-J26 -> 12000
A27: 1 | B27: BANDEJA | C27: TOM CHERRY | D27: 12500 | E27: =A27*D27 -> 12500 | I27: =1500*5 -> 7500 | J27: =I27*A27 -> 7500 | K27: =E27-J27 -> 5000
A28: 1 | B28: CAJA | C28: PALTA T.84 | D28: =64000+8000 -> 72000 | E28: =A28*D28 -> 72000 | I28: 64000 | J28: =I28*A28 -> 64000 | K28: =E28-J28 -> 8000
A29: 1 | B29: CAJA | C29: PALTA T.70 | D29: 75000 | E29: =A29*D29 -> 75000 | I29: 63000 | J29: =I29*A29 -> 63000 | K29: =E29-J29 -> 12000
A30: 4 | B30: CAJA | C30: LIMON | D30: 30000 | E30: =A30*D30 -> 120000 | I30: 25000 | J30: =I30*A30 -> 100000 | K30: =E30-J30 -> 20000
A31: 4 | B31: CAJON | C31: NARANJA FRIO | D31: 20000 | E31: =A31*D31 -> 80000 | I31: 17000 | J31: =I31*A31 -> 68000 | K31: =E31-J31 -> 12000
A32: 2 | B32: BOLSA | C32: BONIATO | D32: 27000 | E32: =A32*D32 -> 54000 | I32: 22000 | J32: =I32*A32 -> 44000 | K32: =E32-J32 -> 10000
A33: 1 | B33: CAJON | C33: TOMATE REDONDO | D33: 20000 | E33: =A33*D33 -> 20000 | I33: 16000 | J33: =I33*A33 -> 16000 | K33: =E33-J33 -> 4000
A34: 1 | B34: CAJON | C34: MORRON ROJO | D34: 32000 | E34: =A34*D34 -> 32000 | I34: 25000 | J34: =I34*A34 -> 25000 | K34: =E34-J34 -> 7000
A35: 6 | B35: ATADO | C35: CEB VERDEO | D35: 5000 | E35: =A35*D35 -> 30000 | I35: 4000 | J35: =I35*A35 -> 24000 | K35: =E35-J35 -> 6000
A36: 2 | B36: ATADO | C36: PEREJIL | D36: 3500 | E36: =A36*D36 -> 7000 | I36: 2000 | J36: =I36*A36 -> 4000 | K36: =E36-J36 -> 3000
A37: 2 | B37: BOLSA | C37: CEBOLLA | D37: 13000 | E37: =A37*D37 -> 26000 | I37: 9000 | J37: =I37*A37 -> 18000 | K37: =E37-J37 -> 8000
A38: 1 | B38: BOLSA | C38: BATATA | D38: 13000 | E38: =A38*D38 -> 13000 | I38: 10000 | J38: =I38*A38 -> 10000 | K38: =E38-J38 -> 3000
A39: 3 | B39: ATADO | C39: MENTA | D39: 3000 | E39: =A39*D39 -> 9000 | I39: 2000 | J39: =I39*A39 -> 6000 | K39: =E39-J39 -> 3000
A40: 2 | B40: ATADO | C40: CIBOULLETE | D40: 3500 | E40: =A40*D40 -> 7000 | I40: 2500 | J40: =I40*A40 -> 5000 | K40: =E40-J40 -> 2000
... A42: 4 | B42: UNIDAD | C42: MANGO | D42: 2200 | E42: =A42*D42 -> 8800 | I42: 2000 | J42: =I42*A42 -> 8000 | K42: =E42-J42 -> 800
E44: =SUM(E25:E43) -> 681800 | K44: =SUM(K25:K42) -> 129300 | L44: =K44/E44 -> 0.18964506
A47: LA PIADINA | D47: rto: 19 | E47: 46064
A49: CANTIDAD | B49: UNIDAD | C49: PRODUCTO | D49: PRECIO | E49: TOTAL | I49: PRECIO | J49: TOTAL | K49: DIFERENCIA
A50: 2 | B50: ATADO | C50: ESPINACA | D50: 1500 | E50: =A50*D50 -> 3000 | I50: 1200 | J50: =I50*A50 -> 2400 | K50: =E50-J50 -> 600
A51: 4 | B51: UNIDAD | C51: PALTA | D51: 1300 | E51: =A51*D51 -> 5200 | I51: 914 | J51: =I51*A51 -> 3656 | K51: =E51-J51 -> 1544
A52: 3 | B52: KG | C52: TOAMTE REDONDO | D52: 1500 | E52: =A52*D52 -> 4500 | I52: 722 | J52: =I52*A52 -> 2166 | K52: =E52-J52 -> 2334
A53: 1 | B53: CAJON | C53: RUCULA | D53: 10000 | E53: =A53*D53 -> 10000 | I53: 5000 | J53: =I53*A53 -> 5000 | K53: =E53-J53 -> 5000
...

Sheet 13-02-2026 
A2: COLEGIO SJCB - VIRREY DEL PINO 3299 | E2: rto: 3 | F2: 46066 | I2: COMPRA
A4: CANTIDAD | B4: UNIDAD | C4: PRODUCTO | D4: PRECIO | E4: TOTAL | F4: TOTAL + IVA | I4: COSTO | J4: TOTAL | K4: DIFERENCIA
A5: 0.5 | B5: CAJON | C5: HUEVO N1 | D5: 52000 | E5: =A5*D5 -> 26000 | F5: =E5*1.21 -> 31460 | I5: 50000 | J5: =I5*A5 -> 25000 | K5: =F5-J5 -> 6460
A6: 1 | B6: UNIDAD | C6: AJO | D6: 900 | E6: =A6*D6 -> 900 | F6: =E6*1.105 -> 994.5 | I6: =23000/50 -> 460 | J6: =I6*A6 -> 460 | K6: =F6-J6 -> 534.5
A7: 1 | B7: UNIDAD | C7: APIO | D7: 2500 | E7: =A7*D7 -> 2500 | F7: =E7*1.105 -> 2762.5 | I7: 1200 | J7: =I7*A7 -> 1200 | K7: =F7-J7 -> 1562.5
A8: 1 | B8: BOLSA | C8: BATATA | D8: 16000 | E8: =A8*D8 -> 16000 | F8: =E8*1.105 -> 17680 | I8: 13000 | J8: =I8*A8 -> 13000 | K8: =F8-J8 -> 4680
A9: 2 | B9: UNIDAD | C9: BROCOLI | D9: 2500 | E9: =A9*D9 -> 5000 | F9: =E9*1.105 -> 5525 | I9: 1500 | J9: =I9*A9 -> 3000 | K9: =F9-J9 -> 2525
A10: 1 | B10: BOLSA | C10: ANCO | D10: 13000 | E10: =A10*D10 -> 13000 | F10: =E10*1.105 -> 14365 | I10: 8000 | J10: =I10*A10 -> 8000 | K10: =F10-J10 -> 6365
A11: 1.5 | B11: KG | C11: ANCO | D11: 1200 | E11: =A11*D11 -> 1800 | F11: =E11*1.105 -> 1989 | I11: =8000/15 -> 533.33333 | J11: =I11*A11 -> 800 | K11: =F11-J11 -> 1189
A12: 3 | B12: KG | C12: CEBOLLA MORADA | D12: 1600 | E12: =A12*D12 -> 4800 | F12: =E12*1.105 -> 5304 | I12: 1000 | J12: =I12*A12 -> 3000 | K12: =F12-J12 -> 2304
A13: 1 | B13: KG | C13: CEBOLLA COMUN | D13: 800 | E13: =A13*D13 -> 800 | F13: =E13*1.105 -> 884 | I13: =9000/16 -> 562.5 | J13: =I13*A13 -> 562.5 | K13: =F13-J13 -> 321.5
A14: 0.5 | B14: CAJON | C14: MANZANA ROJA ELEGIDA | D14: 80000 | E14: =A14*D14 -> 40000 | F14: =E14*1.105 -> 44200 | I14: 65000 | J14: =I14*A14 -> 32500 | K14: =F14-J14 -> 11700
A15: 0.5 | B15: CAJON | C15: MANZANA VERDE ELEGIDA | D15: 65000 | E15: =A15*D15 -> 32500 | F15: =E15*1.105 -> 35912.5 | I15: 55000 | J15: =I15*A15 -> 27500 | K15: =F15-J15 -> 8412.5
A16: 1 | B16: CAJON | C16: NARANJA JUGO ELEGIDA | D16: 22000 | E16: =A16*D16 -> 22000 | F16: =E16*1.105 -> 24310 | I16: 17000 | J16: =I16*A16 -> 17000 | K16: =F16-J16 -> 7310
A17: 3 | B17: BOLSA | C17: PAPA BLANCA | D17: 21000 | E17: =A17*D17 -> 63000 | F17: =E17*1.105 -> 69615 | I17: 18000 | J17: =I17*A17 -> 54000 | K17: =F17-J17 -> 15615
A18: 3 | B18: KG | C18: MORRÓN ROJO | D18: 4000 | E18: =A18*D18 -> 12000 | F18: =E18*1.105 -> 13260 | I18: =27000/8 -> 3375 | J18: =I18*A18 -> 10125 | K18: =F18-J18 -> 3135
A19: 2.5 | B19: KG | C19: MORRÓN VERDE | D19: 3100 | E19: =A19*D19 -> 7750 | F19: =E19*1.105 -> 8563.75 | I19: =12000/8 -> 1500 | J19: =I19*A19 -> 3750 | K19: =F19-J19 -> 4813.75
A20: 2 | B20: KG | C20: MORRÓN AMARILLO | D20: 4000 | E20: =A20*D20 -> 8000 | F20: =E20*1.105 -> 8840 | I20: =25000/8 -> 3125 | J20: =I20*A20 -> 6250 | K20: =F20-J20 -> 2590
A21: 0.5 | B21: ATADO | C21: PUERRO | D21: 6000 | E21: =A21*D21 -> 3000 | F21: =E21*1.105 -> 3315 | I21: 5000 | J21: =I21*A21 -> 2500 | K21: =F21-J21 -> 815
A22: 3 | B22: KG | C22: POMELO | D22: 4500 | E22: =A22*D22 -> 13500 | F22: =E22*1.105 -> 14917.5 | I22: =50000/14 -> 3571.4286 | J22: =I22*A22 -> 10714.286 | K22: =F22-J22 -> 4203.2143
A23: 1 | B23: UNIDAD | C23: REMOLACHA | D23: 1600 | E23: =A23*D23 -> 1600 | F23: =E23*1.105 -> 1768 | I23: =10000/9 -> 1111.1111 | J23: =I23*A23 -> 1111.1111 | K23: =F23-J23 -> 656.88889
A24: 0.7 | B24: KG | C24: REPOLLO BLANCO | D24: 1500 | E24: =A24*D24 -> 1050 | F24: =E24*1.105 -> 1160.25 | I24: 882 | J24: =I24*A24 -> 617.4 | K24: =F24-J24 -> 542.85
A25: 9 | B25: KG | C25: TOMATE PERITA | D25: 1600 | E25: =A25*D25 -> 14400 | F25: =E25*1.105 -> 15912 | I25: 1000 | J25: =I25*A25 -> 9000 | K25: =F25-J25 -> 6912
A26: 1 | B26: BOLSA | C26: ZANAHORIA CUBITO ELEGIDA | D26: 12000 | E26: =A26*D26 -> 12000 | F26: =E26*1.105 -> 13260 | I26: 8000 | J26: =I26*A26 -> 8000 | K26: =F26-J26 -> 5260
A27: 5 | B27: KG | C27: ZANAHORIA CUBITO ELEGIDA | D27: 1500 | E27: =A27*D27 -> 7500 | F27: =E27*1.105 -> 8287.5 | I27: =8000/9 -> 888.88889 | J27: =I27*A27 -> 4444.4444 | K27: =F27-J27 -> 3843.0556
A28: 3 | B28: KG | C28: ZAPALLITO REDONDO | D28: 1200 | E28: =A28*D28 -> 3600 | F28: =E28*1.105 -> 3978 | I28: =10000/15 -> 666.66667 | J28: =I28*A28 -> 2000 | K28: =F28-J28 -> 1978
A29: 6 | B29: UNIDAD | C29: PALTA | D29: 1300 | E29: =A29*D29 -> 7800 | F29: =E29*1.105 -> 8619 | I29: 914 | J29: =I29*A29 -> 5484 | K29: =F29-J29 -> 3135
A30: 1 | B30: UNIDAD | C30: KALE | D30: 2000 | E30: =A30*D30 -> 2000 | F30: =E30*1.105 -> 2210 | I30: 1000 | J30: =I30*A30 -> 1000 | K30: =F30-J30 -> 1210
A31: 1 | B31: KG | C31: BERENJENA | D31: 1600 | E31: =A31*D31 -> 1600 | F31: =E31*1.105 -> 1768 | I31: 1000 | J31: =I31*A31 -> 1000 | K31: =F31-J31 -> 768
A32: 0.3 | B32: KG | C32: TOMATE CHERRY | D32: 3500 | E32: =A32*D32 -> 1050 | F32: =E32*1.105 -> 1160.25 | I32: 3000 | J32: =I32*A32 -> 900 | K32: =F32-J32 -> 260.25
E34: =SUM(E5:E32) -> 325150 | F34: =SUM(F5:F32) -> 362020.75 | K34: =SUM(K5:K32) -> 109102.01 | L34: =IFERROR(K34/E34, 0) -> 0.33554362
A36: COLEGIO ST. MATTHEWS - MOLDES 1469, BELGRANO | E36: rto: 1 | F36: 46066 | I36: COMPRA
A38: CANTIDAD | B38: UNIDAD | C38: PRODUCTO | D38: PRECIO | E38: TOTAL | F38: TOTAL + IVA | I38: COSTO | J38: TOTAL | K38: DIFERENCIA
A39: 3 | B39: BOLSA | C39: PAPA BLANCA | D39: 21000 | E39: =A39*D39 -> 63000 | F39: =E39*1.105 -> 69615 | I39: 18000 | J39: =I39*A39 -> 54000 | K39: =F39-J39 -> 15615
A40: 1 | B40: BOLSA | C40: ANCO | D40: 13000 | E40: =A40*D40 -> 13000 | F40: =E40*1.105 -> 14365 | I40: 8000 | J40: =I40*A40 -> 8000 | K40: =F40-J40 -> 6365
A41: 1 | B41: BOLSA | C41: ZANAHORIA CUBITO ELEGIDA | D41: 12000 | E41: =A41*D41 -> 12000 | F41: =E41*1.105 -> 13260 | I41: 8000 | J41: =I41*A41 -> 8000 | K41: =F41-J41 -> 5260
A42: 8 | B42: KG | C42: TOMATE PERITA | D42: 1600 | E42: =A42*D42 -> 12800 | F42: =E42*1.105 -> 14144 | I42: 1000 | J42: =I42*A42 -> 8000 | K42: =F42-J42 -> 6144
A43: 3 | B43: KG | C43: BATATA | D43: 1800 | E43: =A43*D43 -> 5400 | F43: =E43*1.105 -> 5967 | I43: =13000/10 -> 1300 | J43: =I43*A43 -> 3900 | K43: =F43-J43 -> 2067
A44: 2 | B44: KG | C44: ZAPALLITO REDONDO | D44: 1200 | E44: =A44*D44 -> 2400 | F44: =E44*1.105 -> 2652 | I44: =10000/15 -> 666.66667 | J44: =I44*A44 -> 1333.3333 | K44: =F44-J44 -> 1318.6667
A45: 3 | B45: KG | C45: CEBOLLA MORADA | D45: 1600 | E45: =A45*D45 -> 4800 | F45: =E45*1.105 -> 5304 | I45: 1000 | J45: =I45*A45 -> 3000 | K45: =F45-J45 -> 2304
...

Sheet 17-02-2026 
A2: COLCAR | E2: rto: 5 | F2: 46070 | I2: COMPRA
A4: CANTIDAD | B4: UNIDAD | C4: PRODUCTO | D4: PRECIO | E4: TOTAL | F4: TOTAL + IVA | I4: COSTO | J4: TOTAL | K4: DIFERENCIA
A5: 1 | B5: CAJON | C5: CHOCLO | D5: 18000 | E5: =A5*D5 -> 18000 | F5: =E5*1.105 -> 19890 | I5: 15000 | J5: =I5*A5 -> 15000 | K5: =F5-J5 -> 4890 | L5: =IFERROR(K5/E5, 0) -> 0.27166667
A6: 1 | B6: CAJON | C6: LECHUGA MANTECA | D6: 13000 | E6: =A6*D6 -> 13000 | F6: =E6*1.105 -> 14365 | I6: 9000 | J6: =I6*A6 -> 9000 | K6: =F6-J6 -> 5365 | L6: =IFERROR(K6/E6, 0) -> 0.41269231
A7: 2 | B7: CAJON | C7: TOMATE REDONDO | D7: 32000 | E7: =A7*D7 -> 64000 | F7: =E7*1.105 -> 70720 | I7: 28000 | J7: =I7*A7 -> 56000 | K7: =F7-J7 -> 14720 | L7: =IFERROR(K7/E7, 0) -> 0.23
A8: 3 | B8: CAJON | C8: ACELGA | D8: 16000 | E8: =A8*D8 -> 48000 | F8: =E8*1.105 -> 53040 | I8: 12000 | J8: =I8*A8 -> 36000 | K8: =F8-J8 -> 17040 | L8: =IFERROR(K8/E8, 0) -> 0.355
A9: 8 | B9: BOLSA | C9: PAPA | D9: 16000 | E9: =A9*D9 -> 128000 | F9: =E9*1.105 -> 141440 | I9: 13000 | J9: =I9*A9 -> 104000 | K9: =F9-J9 -> 37440 | L9: =IFERROR(K9/E9, 0) -> 0.2925
A10: 1 | B10: BOLSA | C10: ANCO | D10: 12000 | E10: =A10*D10 -> 12000 | F10: =E10*1.105 -> 13260 | I10: 8000 | J10: =I10*A10 -> 8000 | K10: =F10-J10 -> 5260 | L10: =IFERROR(K10/E10, 0) -> 0.43833333
A11: 1 | B11: BOLSA | C11: CEBOLLA | D11: 12000 | E11: =A11*D11 -> 12000 | F11: =E11*1.105 -> 13260 | I11: 8000 | J11: =I11*A11 -> 8000 | K11: =F11-J11 -> 5260 | L11: =IFERROR(K11/E11, 0) -> 0.43833333
E13: =SUM(E5:E11) -> 295000 | F13: =SUM(F5:F11) -> 325975 | K13: =SUM(K5:K11) -> 89975 | L13: =IFERROR(K13/E13, 0) -> 0.305
A15: Comisión Juan | B15: 0.04 | E15: =E13*0.04 -> 11800
A18: BRASOV | D18: rto: 14 | E18: 46070
A20: CANTIDAD | B20: UNIDAD | C20: PRODUCTO | D20: PRECIO | E20: TOTAL | I20: PRECIO | J20: TOTAL | K20: DIFERENCIA
A21: 1 | B21: BOLSA | C21: ANCO | D21: 13000 | E21: =A21*D21 -> 13000 | I21: 8000 | J21: =I21*A21 -> 8000 | K21: =E21-J21 -> 5000 | L21: =K21/E21 -> 0.38461538
A22: 1 | B22: BOLSA | C22: BONIATO | D22: 26000 | E22: =A22*D22 -> 26000 | I22: =105000/5 -> 21000 | J22: =I22*A22 -> 21000 | K22: =E22-J22 -> 5000 | L22: =K22/E22 -> 0.19230769
