Workbook

Sheet COMPRAS
B1: FECHA | C1: PRODUCTO | D1: COSTO | E1: CANTIDAD | F1: KILOS / UNIDADES | G1: PROVEEDOR | H1: METODO DE PAGO | I1: VACIO | J1: UNIDAD
A2: d536df47 | B2: 46065 | C2: ACELGA | D2: 12000 | E2: 2 | F2: 10 | G2: JCB | I2: 4000 | J2: CAJON

Sheet PRECIOS
A1: PRODUCTO | B1: UNIDAD | C1: COSTO ACTUAL | D1: MARGEN (%) | E1: PRECIO VENTA | F1: KG / UNIDAD POR CAJON | G1: TOTAL VACIOS | H1: STOCK ACTUAL X UNIDADES | I1: COSTO UNITARIO | J1: VENTA UNITARIO
A2: ACELGA | B2: CAJON | C2: =IFERROR(AVERAGEIFS(COMPRAS!$D:$D, COMPRAS!$C:$C, $A2, COMPRAS!$J:$J, $B2), 0) -> 12000 | D2: 1.3 | E2: =ROUNDUP(C2 * D2, -3) -> 16000 | F2: =IFERROR(AVERAGEIFS(COMPRAS!$F:$F, COMPRAS!$C:$C, $A2, COMPRAS!$J:$J, $B2), 1) -> 10 | G2: =IFERROR(SUMIFS(COMPRAS!I:I, COMPRAS!C:C, A2) * SUMIFS(COMPRAS!E:E, COMPRAS!C:C, A2) / COUNTIF(COMPRAS!C:C, A2), 0) -> 8000 | H2: =IFERROR( ((SUMIFS(COMPRAS!$E:$E, COMPRAS!$C:$C, $A2, COMPRAS!$J:$J, "CAJON") + SUMIFS(COMPRAS!$E:$E, COMPRAS!$C:$C, $A2, COMPRAS!$J:$J, "BOLSA")) * $F2) - ((SUMIFS(prueba!$A:$A, prueba!$C:$C, $A2, prueba!$B:$B, "CAJON") + SUMIFS(prueba!$A:$A, prueba!$C:$C, $A2, prueba!$B:$B, "BOLSA")) * $F2) - MAX(0, (SUMIFS(prueba!$A:$A, prueba!$C:$C, $A2, prueba!$B:$B, "UNIDAD") + SUMIFS(prueba!$A:$A, prueba!$C:$C, $A2, prueba!$B:$B, "KG")) - (SUMIFS(COMPRAS!$E:$E, COMPRAS!$C:$C, $A2, COMPRAS!$J:$J, "UNIDAD") + SUMIFS(COMPRAS!$E:$E, COMPRAS!$C:$C, $A2, COMPRAS!$J:$J, "KG"))), 0) -> 20 | I2: =IFERROR(C2 / F2, 0) -> 1200 | J2: =IFERROR(ROUNDUP((E2 / F2) * 1.2, -2),0) -> 2000 | K2: =A2&B2 -> ACELGACAJON
A3: ACELGA | B3: UNIDAD | C3: =IFERROR(AVERAGEIFS(COMPRAS!$D:$D, COMPRAS!$C:$C, $A3, COMPRAS!$J:$J, $B3), 0) -> 0 | D3: 1.1 | E3: =ROUNDUP(C3 * D3, -2) -> 0 | F3: =IFERROR(AVERAGEIFS(COMPRAS!$F:$F, COMPRAS!$C:$C, $A3, COMPRAS!$J:$J, $B3), 1) -> 1 | G3: =IFERROR(SUMIFS(COMPRAS!I:I, COMPRAS!C:C, A3) * SUMIFS(COMPRAS!E:E, COMPRAS!C:C, A3) / COUNTIF(COMPRAS!C:C, A3), 0) -> 8000 | H3: =MAX(0, (SUMIFS(COMPRAS!$E:$E, COMPRAS!$C:$C, $A3, COMPRAS!$J:$J, "UNIDAD") + SUMIFS(COMPRAS!$E:$E, COMPRAS!$C:$C, $A3, COMPRAS!$J:$J, "KG")) - (SUMIFS(prueba!$A:$A, prueba!$C:$C, $A3, prueba!$B:$B, "UNIDAD") + SUMIFS(prueba!$A:$A, prueba!$C:$C, $A3, prueba!$B:$B, "KG")) ) -> 0 | I3: =IFERROR(C3 / F3, 0) -> 0 | J3: =IFERROR(ROUNDUP((E3 / F3) , -2),0) -> 0 | K3: =A3&B3 -> ACELGAUNIDAD
A4: ALBAHACA | B4: CAJON | C4: =IFERROR(AVERAGEIFS(COMPRAS!$D:$D, COMPRAS!$C:$C, $A4, COMPRAS!$J:$J, $B4), 0) -> 0 | D4: 1.3 | E4: =ROUNDUP(C4 *D4, -3) -> 0 | F4: =IFERROR(AVERAGEIFS(COMPRAS!$F:$F, COMPRAS!$C:$C, $A4, COMPRAS!$J:$J, $B4), 1) -> 1 | G4: =IFERROR(SUMIFS(COMPRAS!I:I, COMPRAS!C:C, A4) * SUMIFS(COMPRAS!E:E, COMPRAS!C:C, A4) / COUNTIF(COMPRAS!C:C, A4), 0) -> 0 | H4: =IFERROR( ((SUMIFS(COMPRAS!$E:$E, COMPRAS!$C:$C, $A4, COMPRAS!$J:$J, "CAJON") + SUMIFS(COMPRAS!$E:$E, COMPRAS!$C:$C, $A4, COMPRAS!$J:$J, "BOLSA")) * $F4) - ((SUMIFS(prueba!$A:$A, prueba!$C:$C, $A4, prueba!$B:$B, "CAJON") + SUMIFS(prueba!$A:$A, prueba!$C:$C, $A4, prueba!$B:$B, "BOLSA")) * $F4) - MAX(0, (SUMIFS(prueba!$A:$A, prueba!$C:$C, $A4, prueba!$B:$B, "UNIDAD") + SUMIFS(prueba!$A:$A, prueba!$C:$C, $A4, prueba!$B:$B, "KG")) - (SUMIFS(COMPRAS!$E:$E, COMPRAS!$C:$C, $A4, COMPRAS!$J:$J, "UNIDAD") + SUMIFS(COMPRAS!$E:$E, COMPRAS!$C:$C, $A4, COMPRAS!$J:$J, "KG"))), 0) -> 0 | I4: =IFERROR(C4 / F4, 0) -> 0 | J4: =IFERROR(ROUNDUP((E4 / F4) * 1.1, -2),0) -> 0 | K4: =A4&B4 -> ALBAHACACAJON
A5: ALBAHACA | B5: UNIDAD | C5: =IFERROR(AVERAGEIFS(COMPRAS!$D:$D, COMPRAS!$C:$C, $A5, COMPRAS!$J:$J, $B5), 0) -> 0 | D5: 1.3 | E5: =ROUNDUP(C5 *D5, -2) -> 0 | F5: =IFERROR(AVERAGEIFS(COMPRAS!$F:$F, COMPRAS!$C:$C, $A5, COMPRAS!$J:$J, $B5), 1) -> 1 | G5: =IFERROR(SUMIFS(COMPRAS!I:I, COMPRAS!C:C, A5) * SUMIFS(COMPRAS!E:E, COMPRAS!C:C, A5) / COUNTIF(COMPRAS!C:C, A5), 0) -> 0 | H5: =MAX(0, (SUMIFS(COMPRAS!$E:$E, COMPRAS!$C:$C, $A5, COMPRAS!$J:$J, "UNIDAD") + SUMIFS(COMPRAS!$E:$E, COMPRAS!$C:$C, $A5, COMPRAS!$J:$J, "KG")) - (SUMIFS(prueba!$A:$A, prueba!$C:$C, $A5, prueba!$B:$B, "UNIDAD") + SUMIFS(prueba!$A:$A, prueba!$C:$C, $A5, prueba!$B:$B, "KG")) ) -> 0 | I5: =IFERROR(C5 / F5, 0) -> 0 | J5: =IFERROR(ROUNDUP((E5 / F5) * 1.1, -2),0) -> 0 | K5: =A5&B5 -> ALBAHACAUNIDAD
A6: APIO | B6: CAJON | C6: =IFERROR(AVERAGEIFS(COMPRAS!$D:$D, COMPRAS!$C:$C, $A6, COMPRAS!$J:$J, $B6), 0) -> 0 | D6: 1.3 | E6: =ROUNDUP(C6 *D6, -3) -> 0 | F6: =IFERROR(AVERAGEIFS(COMPRAS!$F:$F, COMPRAS!$C:$C, $A6, COMPRAS!$J:$J, $B6), 1) -> 1 | G6: =IFERROR(SUMIFS(COMPRAS!I:I, COMPRAS!C:C, A6) * SUMIFS(COMPRAS!E:E, COMPRAS!C:C, A6) / COUNTIF(COMPRAS!C:C, A6), 0) -> 0 | H6: =IFERROR( ((SUMIFS(COMPRAS!$E:$E, COMPRAS!$C:$C, $A6, COMPRAS!$J:$J, "CAJON") + SUMIFS(COMPRAS!$E:$E, COMPRAS!$C:$C, $A6, COMPRAS!$J:$J, "BOLSA")) * $F6) - ((SUMIFS(prueba!$A:$A, prueba!$C:$C, $A6, prueba!$B:$B, "CAJON") + SUMIFS(prueba!$A:$A, prueba!$C:$C, $A6, prueba!$B:$B, "BOLSA")) * $F6) - MAX(0, (SUMIFS(prueba!$A:$A, prueba!$C:$C, $A6, prueba!$B:$B, "UNIDAD") + SUMIFS(prueba!$A:$A, prueba!$C:$C, $A6, prueba!$B:$B, "KG")) - (SUMIFS(COMPRAS!$E:$E, COMPRAS!$C:$C, $A6, COMPRAS!$J:$J, "UNIDAD") + SUMIFS(COMPRAS!$E:$E, COMPRAS!$C:$C, $A6, COMPRAS!$J:$J, "KG"))), 0) -> -2 | I6: =IFERROR(C6 / F6, 0) -> 0 | J6: =IFERROR(ROUNDUP((E6 / F6) * 1.1, -2),0) -> 0 | K6: =A6&B6 -> APIOCAJON
A7: APIO | B7: UNIDAD | C7: =IFERROR(AVERAGEIFS(COMPRAS!$D:$D, COMPRAS!$C:$C, $A7, COMPRAS!$J:$J, $B7), 0) -> 0 | D7: 1.3 | E7: =ROUNDUP(C7 *D7, -2) -> 0 | F7: =IFERROR(AVERAGEIFS(COMPRAS!$F:$F, COMPRAS!$C:$C, $A7, COMPRAS!$J:$J, $B7), 1) -> 1 | G7: =IFERROR(SUMIFS(COMPRAS!I:I, COMPRAS!C:C, A7) * SUMIFS(COMPRAS!E:E, COMPRAS!C:C, A7) / COUNTIF(COMPRAS!C:C, A7), 0) -> 0 | H7: =MAX(0, (SUMIFS(COMPRAS!$E:$E, COMPRAS!$C:$C, $A7, COMPRAS!$J:$J, "UNIDAD") + SUMIFS(COMPRAS!$E:$E, COMPRAS!$C:$C, $A7, COMPRAS!$J:$J, "KG")) - (SUMIFS(prueba!$A:$A, prueba!$C:$C, $A7, prueba!$B:$B, "UNIDAD") + SUMIFS(prueba!$A:$A, prueba!$C:$C, $A7, prueba!$B:$B, "KG")) ) -> 0 | I7: =IFERROR(C7 / F7, 0) -> 0 | J7: =IFERROR(ROUNDUP((E7 / F7) * 1.1, -2),0) -> 0 | K7: =A7&B7 -> APIOUNIDAD
A8: BROCOLI | B8: CAJON | C8: =IFERROR(AVERAGEIFS(COMPRAS!$D:$D, COMPRAS!$C:$C, $A8, COMPRAS!$J:$J, $B8), 0) -> 0 | D8: 1.3 | E8: =ROUNDUP(C8 *D8, -3) -> 0 | F8: =IFERROR(AVERAGEIFS(COMPRAS!$F:$F, COMPRAS!$C:$C, $A8, COMPRAS!$J:$J, $B8), 1) -> 1 | G8: =IFERROR(SUMIFS(COMPRAS!I:I, COMPRAS!C:C, A8) * SUMIFS(COMPRAS!E:E, COMPRAS!C:C, A8) / COUNTIF(COMPRAS!C:C, A8), 0) -> 0 | H8: =IFERROR( ((SUMIFS(COMPRAS!$E:$E, COMPRAS!$C:$C, $A8, COMPRAS!$J:$J, "CAJON") + SUMIFS(COMPRAS!$E:$E, COMPRAS!$C:$C, $A8, COMPRAS!$J:$J, "BOLSA")) * $F8) - ((SUMIFS(prueba!$A:$A, prueba!$C:$C, $A8, prueba!$B:$B, "CAJON") + SUMIFS(prueba!$A:$A, prueba!$C:$C, $A8, prueba!$B:$B, "BOLSA")) * $F8) - MAX(0, (SUMIFS(prueba!$A:$A, prueba!$C:$C, $A8, prueba!$B:$B, "UNIDAD") + SUMIFS(prueba!$A:$A, prueba!$C:$C, $A8, prueba!$B:$B, "KG")) - (SUMIFS(COMPRAS!$E:$E, COMPRAS!$C:$C, $A8, COMPRAS!$J:$J, "UNIDAD") + SUMIFS(COMPRAS!$E:$E, COMPRAS!$C:$C, $A8, COMPRAS!$J:$J, "KG"))), 0) -> 0 | I8: =IFERROR(C8 / F8, 0) -> 0 | J8: =IFERROR(ROUNDUP((E8 / F8) * 1.1, -2),0) -> 0 | K8: =A8&B8 -> BROCOLICAJON
A9: BROCOLI | B9: UNIDAD | C9: =IFERROR(AVERAGEIFS(COMPRAS!$D:$D, COMPRAS!$C:$C, $A9, COMPRAS!$J:$J, $B9), 0) -> 0 | D9: 1.3 | E9: =ROUNDUP(C9 *D9, -2) -> 0 | F9: =IFERROR(AVERAGEIFS(COMPRAS!$F:$F, COMPRAS!$C:$C, $A9, COMPRAS!$J:$J, $B9), 1) -> 1 | G9: =IFERROR(SUMIFS(COMPRAS!I:I, COMPRAS!C:C, A9) * SUMIFS(COMPRAS!E:E, COMPRAS!C:C, A9) / COUNTIF(COMPRAS!C:C, A9), 0) -> 0 | H9: =MAX(0, (SUMIFS(COMPRAS!$E:$E, COMPRAS!$C:$C, $A9, COMPRAS!$J:$J, "UNIDAD") + SUMIFS(COMPRAS!$E:$E, COMPRAS!$C:$C, $A9, COMPRAS!$J:$J, "KG")) - (SUMIFS(prueba!$A:$A, prueba!$C:$C, $A9, prueba!$B:$B, "UNIDAD") + SUMIFS(prueba!$A:$A, prueba!$C:$C, $A9, prueba!$B:$B, "KG")) ) -> 0 | I9: =IFERROR(C9 / F9, 0) -> 0 | J9: =IFERROR(ROUNDUP((E9 / F9) * 1.1, -2),0) -> 0 | K9: =A9&B9 -> BROCOLIUNIDAD
A10: REPOLLITOS DE BRUSELAS | B10: CAJON | C10: =IFERROR(AVERAGEIFS(COMPRAS!$D:$D, COMPRAS!$C:$C, $A10, COMPRAS!$J:$J, $B10), 0) -> 0 | D10: 1.3 | E10: =ROUNDUP(C10 *D10, -3) -> 0 | F10: =IFERROR(AVERAGEIFS(COMPRAS!$F:$F, COMPRAS!$C:$C, $A10, COMPRAS!$J:$J, $B10), 1) -> 1 | G10: =IFERROR(SUMIFS(COMPRAS!I:I, COMPRAS!C:C, A10) * SUMIFS(COMPRAS!E:E, COMPRAS!C:C, A10) / COUNTIF(COMPRAS!C:C, A10), 0) -> 0 | H10: =IFERROR( ((SUMIFS(COMPRAS!$E:$E, COMPRAS!$C:$C, $A10, COMPRAS!$J:$J, "CAJON") + SUMIFS(COMPRAS!$E:$E, COMPRAS!$C:$C, $A10, COMPRAS!$J:$J, "BOLSA")) * $F10) - ((SUMIFS(prueba!$A:$A, prueba!$C:$C, $A10, prueba!$B:$B, "CAJON") + SUMIFS(prueba!$A:$A, prueba!$C:$C, $A10, prueba!$B:$B, "BOLSA")) * $F10) - MAX(0, (SUMIFS(prueba!$A:$A, prueba!$C:$C, $A10, prueba!$B:$B, "UNIDAD") + SUMIFS(prueba!$A:$A, prueba!$C:$C, $A10, prueba!$B:$B, "KG")) - (SUMIFS(COMPRAS!$E:$E, COMPRAS!$C:$C, $A10, COMPRAS!$J:$J, "UNIDAD") + SUMIFS(COMPRAS!$E:$E, COMPRAS!$C:$C, $A10, COMPRAS!$J:$J, "KG"))), 0) -> 0 | I10: =IFERROR(C10 / F10, 0) -> 0 | J10: =IFERROR(ROUNDUP((E10 / F10) * 1.1, -2),0) -> 0 | K10: =A10&B10 -> REPOLLITOS DE BRUSELASCAJON
A11: REPOLLITOS DE BRUSELAS | B11: UNIDAD | C11: =IFERROR(AVERAGEIFS(COMPRAS!$D:$D, COMPRAS!$C:$C, $A11, COMPRAS!$J:$J, $B11), 0) -> 0 | D11: 1.3 | E11: =ROUNDUP(C11 *D11, -2) -> 0 | F11: =IFERROR(AVERAGEIFS(COMPRAS!$F:$F, COMPRAS!$C:$C, $A11, COMPRAS!$J:$J, $B11), 1) -> 1 | G11: =IFERROR(SUMIFS(COMPRAS!I:I, COMPRAS!C:C, A11) * SUMIFS(COMPRAS!E:E, COMPRAS!C:C, A11) / COUNTIF(COMPRAS!C:C, A11), 0) -> 0 | H11: =MAX(0, (SUMIFS(COMPRAS!$E:$E, COMPRAS!$C:$C, $A11, COMPRAS!$J:$J, "UNIDAD") + SUMIFS(COMPRAS!$E:$E, COMPRAS!$C:$C, $A11, COMPRAS!$J:$J, "KG")) - (SUMIFS(prueba!$A:$A, prueba!$C:$C, $A11, prueba!$B:$B, "UNIDAD") + SUMIFS(prueba!$A:$A, prueba!$C:$C, $A11, prueba!$B:$B, "KG")) ) -> 0 | I11: =IFERROR(C11 / F11, 0) -> 0 | J11: =IFERROR(ROUNDUP((E11 / F11) * 1.1, -2),0) -> 0 | K11: =A11&B11 -> REPOLLITOS DE BRUSELASUNIDAD
A12: CEBOLLA DE VERDEO | B12: CAJON | C12: =IFERROR(AVERAGEIFS(COMPRAS!$D:$D, COMPRAS!$C:$C, $A12, COMPRAS!$J:$J, $B12), 0) -> 0 | D12: 1.3 | E12: =ROUNDUP(C12 *D12, -3) -> 0 | F12: =IFERROR(AVERAGEIFS(COMPRAS!$F:$F, COMPRAS!$C:$C, $A12, COMPRAS!$J:$J, $B12), 1) -> 1 | G12: =IFERROR(SUMIFS(COMPRAS!I:I, COMPRAS!C:C, A12) * SUMIFS(COMPRAS!E:E, COMPRAS!C:C, A12) / COUNTIF(COMPRAS!C:C, A12), 0) -> 0 | H12: =IFERROR( ((SUMIFS(COMPRAS!$E:$E, COMPRAS!$C:$C, $A12, COMPRAS!$J:$J, "CAJON") + SUMIFS(COMPRAS!$E:$E, COMPRAS!$C:$C, $A12, COMPRAS!$J:$J, "BOLSA")) * $F12) - ((SUMIFS(prueba!$A:$A, prueba!$C:$C, $A12, prueba!$B:$B, "CAJON") + SUMIFS(prueba!$A:$A, prueba!$C:$C, $A12, prueba!$B:$B, "BOLSA")) * $F12) - MAX(0, (SUMIFS(prueba!$A:$A, prueba!$C:$C, $A12, prueba!$B:$B, "UNIDAD") + SUMIFS(prueba!$A:$A, prueba!$C:$C, $A12, prueba!$B:$B, "KG")) - (SUMIFS(COMPRAS!$E:$E, COMPRAS!$C:$C, $A12, COMPRAS!$J:$J, "UNIDAD") + SUMIFS(COMPRAS!$E:$E, COMPRAS!$C:$C, $A12, COMPRAS!$J:$J, "KG"))), 0) -> 0 | I12: =IFERROR(C12 / F12, 0) -> 0 | J12: =IFERROR(ROUNDUP((E12 / F12) * 1.1, -2),0) -> 0 | K12: =A12&B12 -> CEBOLLA DE VERDEOCAJON
A13: CEBOLLA DE VERDEO | B13: UNIDAD | C13: =IFERROR(AVERAGEIFS(COMPRAS!$D:$D, COMPRAS!$C:$C, $A13, COMPRAS!$J:$J, $B13), 0) -> 0 | D13: 1.3 | E13: =ROUNDUP(C13 *D13, -2) -> 0 | F13: =IFERROR(AVERAGEIFS(COMPRAS!$F:$F, COMPRAS!$C:$C, $A13, COMPRAS!$J:$J, $B13), 1) -> 1 | G13: =IFERROR(SUMIFS(COMPRAS!I:I, COMPRAS!C:C, A13) * SUMIFS(COMPRAS!E:E, COMPRAS!C:C, A13) / COUNTIF(COMPRAS!C:C, A13), 0) -> 0 | H13: =MAX(0, (SUMIFS(COMPRAS!$E:$E, COMPRAS!$C:$C, $A13, COMPRAS!$J:$J, "UNIDAD") + SUMIFS(COMPRAS!$E:$E, COMPRAS!$C:$C, $A13, COMPRAS!$J:$J, "KG")) - (SUMIFS(prueba!$A:$A, prueba!$C:$C, $A13, prueba!$B:$B, "UNIDAD") + SUMIFS(prueba!$A:$A, prueba!$C:$C, $A13, prueba!$B:$B, "KG")) ) -> 0 | I13: =IFERROR(C13 / F13, 0) -> 0 | J13: =IFERROR(ROUNDUP((E13 / F13) * 1.1, -2),0) -> 0 | K13: =A13&B13 -> CEBOLLA DE VERDEOUNIDAD
A14: COLIFLOR | B14: CAJON | C14: =IFERROR(AVERAGEIFS(COMPRAS!$D:$D, COMPRAS!$C:$C, $A14, COMPRAS!$J:$J, $B14), 0) -> 0 | D14: 1.3 | E14: =ROUNDUP(C14 * D14, -3) -> 0 | F14: =IFERROR(AVERAGEIFS(COMPRAS!$F:$F, COMPRAS!$C:$C, $A14, COMPRAS!$J:$J, $B14), 1) -> 1 | G14: =IFERROR(SUMIFS(COMPRAS!I:I, COMPRAS!C:C, A14) * SUMIFS(COMPRAS!E:E, COMPRAS!C:C, A14) / COUNTIF(COMPRAS!C:C, A14), 0) -> 0 | H14: =IFERROR( ((SUMIFS(COMPRAS!$E:$E, COMPRAS!$C:$C, $A14, COMPRAS!$J:$J, "CAJON") + SUMIFS(COMPRAS!$E:$E, COMPRAS!$C:$C, $A14, COMPRAS!$J:$J, "BOLSA")) * $F14) - ((SUMIFS(prueba!$A:$A, prueba!$C:$C, $A14, prueba!$B:$B, "CAJON") + SUMIFS(prueba!$A:$A, prueba!$C:$C, $A14, prueba!$B:$B, "BOLSA")) * $F14) - MAX(0, (SUMIFS(prueba!$A:$A, prueba!$C:$C, $A14, prueba!$B:$B, "UNIDAD") + SUMIFS(prueba!$A:$A, prueba!$C:$C, $A14, prueba!$B:$B, "KG")) - (SUMIFS(COMPRAS!$E:$E, COMPRAS!$C:$C, $A14, COMPRAS!$J:$J, "UNIDAD") + SUMIFS(COMPRAS!$E:$E, COMPRAS!$C:$C, $A14, COMPRAS!$J:$J, "KG"))), 0) -> 0 | I14: =IFERROR(C14 / F14, 0) -> 0 | J14: =IFERROR(ROUNDUP((E14 / F14) * 1.1, -2),0) -> 0 | K14: =A14&B14 -> COLIFLORCAJON
A15: COLIFLOR | B15: UNIDAD | C15: =IFERROR(AVERAGEIFS(COMPRAS!$D:$D, COMPRAS!$C:$C, $A15, COMPRAS!$J:$J, $B15), 0) -> 0 | D15: 1.3 | E15: =ROUNDUP(C15 * D15, -2) -> 0 | F15: =IFERROR(AVERAGEIFS(COMPRAS!$F:$F, COMPRAS!$C:$C, $A15, COMPRAS!$J:$J, $B15), 1) -> 1 | G15: =IFERROR(SUMIFS(COMPRAS!I:I, COMPRAS!C:C, A15) * SUMIFS(COMPRAS!E:E, COMPRAS!C:C, A15) / COUNTIF(COMPRAS!C:C, A15), 0) -> 0 | H15: =MAX(0, (SUMIFS(COMPRAS!$E:$E, COMPRAS!$C:$C, $A15, COMPRAS!$J:$J, "UNIDAD") + SUMIFS(COMPRAS!$E:$E, COMPRAS!$C:$C, $A15, COMPRAS!$J:$J, "KG")) - (SUMIFS(prueba!$A:$A, prueba!$C:$C, $A15, prueba!$B:$B, "UNIDAD") + SUMIFS(prueba!$A:$A, prueba!$C:$C, $A15, prueba!$B:$B, "KG")) ) -> 0 | I15: =IFERROR(C15 / F15, 0) -> 0 | J15: =IFERROR(ROUNDUP((E15 / F15) * 1.1, -2),0) -> 0 | K15: =A15&B15 -> COLIFLORUNIDAD
A16: ESPINACA | B16: CAJON | C16: =IFERROR(AVERAGEIFS(COMPRAS!$D:$D, COMPRAS!$C:$C, $A16, COMPRAS!$J:$J, $B16), 0) -> 0 | D16: 1.3 | E16: =ROUNDUP(C16 *D16, -3) -> 0 | F16: =IFERROR(AVERAGEIFS(COMPRAS!$F:$F, COMPRAS!$C:$C, $A16, COMPRAS!$J:$J, $B16), 1) -> 1 | G16: =IFERROR(SUMIFS(COMPRAS!I:I, COMPRAS!C:C, A16) * SUMIFS(COMPRAS!E:E, COMPRAS!C:C, A16) / COUNTIF(COMPRAS!C:C, A16), 0) -> 0 | H16: =IFERROR( ((SUMIFS(COMPRAS!$E:$E, COMPRAS!$C:$C, $A16, COMPRAS!$J:$J, "CAJON") + SUMIFS(COMPRAS!$E:$E, COMPRAS!$C:$C, $A16, COMPRAS!$J:$J, "BOLSA")) * $F16) - ((SUMIFS(prueba!$A:$A, prueba!$C:$C, $A16, prueba!$B:$B, "CAJON") + SUMIFS(prueba!$A:$A, prueba!$C:$C, $A16, prueba!$B:$B, "BOLSA")) * $F16) - MAX(0, (SUMIFS(prueba!$A:$A, prueba!$C:$C, $A16, prueba!$B:$B, "UNIDAD") + SUMIFS(prueba!$A:$A, prueba!$C:$C, $A16, prueba!$B:$B, "KG")) - (SUMIFS(COMPRAS!$E:$E, COMPRAS!$C:$C, $A16, COMPRAS!$J:$J, "UNIDAD") + SUMIFS(COMPRAS!$E:$E, COMPRAS!$C:$C, $A16, COMPRAS!$J:$J, "KG"))), 0) -> 0 | I16: =IFERROR(C16 / F16, 0) -> 0 | J16: =IFERROR(ROUNDUP((E16 / F16) * 1.1, -2),0) -> 0 | K16: =A16&B16 -> ESPINACACAJON
A17: ESPINACA | B17: UNIDAD | C17: =IFERROR(AVERAGEIFS(COMPRAS!$D:$D, COMPRAS!$C:$C, $A17, COMPRAS!$J:$J, $B17), 0) -> 0 | D17: 1.3 | E17: =ROUNDUP(C17 *D17, -2) -> 0 | F17: =IFERROR(AVERAGEIFS(COMPRAS!$F:$F, COMPRAS!$C:$C, $A17, COMPRAS!$J:$J, $B17), 1) -> 1 | G17: =IFERROR(SUMIFS(COMPRAS!I:I, COMPRAS!C:C, A17) * SUMIFS(COMPRAS!E:E, COMPRAS!C:C, A17) / COUNTIF(COMPRAS!C:C, A17), 0) -> 0 | H17: =MAX(0, (SUMIFS(COMPRAS!$E:$E, COMPRAS!$C:$C, $A17, COMPRAS!$J:$J, "UNIDAD") + SUMIFS(COMPRAS!$E:$E, COMPRAS!$C:$C, $A17, COMPRAS!$J:$J, "KG")) - (SUMIFS(prueba!$A:$A, prueba!$C:$C, $A17, prueba!$B:$B, "UNIDAD") + SUMIFS(prueba!$A:$A, prueba!$C:$C, $A17, prueba!$B:$B, "KG")) ) -> 0 | I17: =IFERROR(C17 / F17, 0) -> 0 | J17: =IFERROR(ROUNDUP((E17 / F17) * 1.1, -2),0) -> 0 | K17: =A17&B17 -> ESPINACAUNIDAD
A18: LECHUGA CAPUCCINA | B18: CAJON | C18: =IFERROR(AVERAGEIFS(COMPRAS!$D:$D, COMPRAS!$C:$C, $A18, COMPRAS!$J:$J, $B18), 0) -> 0 | D18: 1.3 | E18: =ROUNDUP(C18 *D18, -3) -> 0 | F18: =IFERROR(AVERAGEIFS(COMPRAS!$F:$F, COMPRAS!$C:$C, $A18, COMPRAS!$J:$J, $B18), 1) -> 1 | G18: =IFERROR(SUMIFS(COMPRAS!I:I, COMPRAS!C:C, A18) * SUMIFS(COMPRAS!E:E, COMPRAS!C:C, A18) / COUNTIF(COMPRAS!C:C, A18), 0) -> 0 | H18: =IFERROR( ((SUMIFS(COMPRAS!$E:$E, COMPRAS!$C:$C, $A18, COMPRAS!$J:$J, "CAJON") + SUMIFS(COMPRAS!$E:$E, COMPRAS!$C:$C, $A18, COMPRAS!$J:$J, "BOLSA")) * $F18) - ((SUMIFS(prueba!$A:$A, prueba!$C:$C, $A18, prueba!$B:$B, "CAJON") + SUMIFS(prueba!$A:$A, prueba!$C:$C, $A18, prueba!$B:$B, "BOLSA")) * $F18) - MAX(0, (SUMIFS(prueba!$A:$A, prueba!$C:$C, $A18, prueba!$B:$B, "UNIDAD") + SUMIFS(prueba!$A:$A, prueba!$C:$C, $A18, prueba!$B:$B, "KG")) - (SUMIFS(COMPRAS!$E:$E, COMPRAS!$C:$C, $A18, COMPRAS!$J:$J, "UNIDAD") + SUMIFS(COMPRAS!$E:$E, COMPRAS!$C:$C, $A18, COMPRAS!$J:$J, "KG"))), 0) -> 0 | I18: =IFERROR(C18 / F18, 0) -> 0 | J18: =IFERROR(ROUNDUP((E18 / F18) * 1.1, -2),0) -> 0 | K18: =A18&B18 -> LECHUGA CAPUCCINACAJON
A19: LECHUGA CAPUCCINA | B19: KG | C19: =IFERROR(AVERAGEIFS(COMPRAS!$D:$D, COMPRAS!$C:$C, $A19, COMPRAS!$J:$J, $B19), 0) -> 0 | D19: 1.3 | E19: =ROUNDUP(C19 *D19, -2) -> 0 | F19: =IFERROR(AVERAGEIFS(COMPRAS!$F:$F, COMPRAS!$C:$C, $A19, COMPRAS!$J:$J, $B19), 1) -> 1 | G19: =IFERROR(SUMIFS(COMPRAS!I:I, COMPRAS!C:C, A19) * SUMIFS(COMPRAS!E:E, COMPRAS!C:C, A19) / COUNTIF(COMPRAS!C:C, A19), 0) -> 0 | H19: =MAX(0, (SUMIFS(COMPRAS!$E:$E, COMPRAS!$C:$C, $A19, COMPRAS!$J:$J, "UNIDAD") + SUMIFS(COMPRAS!$E:$E, COMPRAS!$C:$C, $A19, COMPRAS!$J:$J, "KG")) - (SUMIFS(prueba!$A:$A, prueba!$C:$C, $A19, prueba!$B:$B, "UNIDAD") + SUMIFS(prueba!$A:$A, prueba!$C:$C, $A19, prueba!$B:$B, "KG")) ) -> 0 | I19: =IFERROR(C19 / F19, 0) -> 0 | J19: =IFERROR(ROUNDUP((E19 / F19) * 1.1, -2),0) -> 0 | K19: =A19&B19 -> LECHUGA CAPUCCINAKG
A20: LECHUGA MORADA | B20: CAJON | C20: =IFERROR(AVERAGEIFS(COMPRAS!$D:$D, COMPRAS!$C:$C, $A20, COMPRAS!$J:$J, $B20), 0) -> 0 | D20: 1.3 | E20: =ROUNDUP(C20 *D20, -3) -> 0 | F20: =IFERROR(AVERAGEIFS(COMPRAS!$F:$F, COMPRAS!$C:$C, $A20, COMPRAS!$J:$J, $B20), 1) -> 1 | G20: =IFERROR(SUMIFS(COMPRAS!I:I, COMPRAS!C:C, A20) * SUMIFS(COMPRAS!E:E, COMPRAS!C:C, A20) / COUNTIF(COMPRAS!C:C, A20), 0) -> 0 | H20: =IFERROR( ((SUMIFS(COMPRAS!$E:$E, COMPRAS!$C:$C, $A20, COMPRAS!$J:$J, "CAJON") + SUMIFS(COMPRAS!$E:$E, COMPRAS!$C:$C, $A20, COMPRAS!$J:$J, "BOLSA")) * $F20) - ((SUMIFS(prueba!$A:$A, prueba!$C:$C, $A20, prueba!$B:$B, "CAJON") + SUMIFS(prueba!$A:$A, prueba!$C:$C, $A20, prueba!$B:$B, "BOLSA")) * $F20) - MAX(0, (SUMIFS(prueba!$A:$A, prueba!$C:$C, $A20, prueba!$B:$B, "UNIDAD") + SUMIFS(prueba!$A:$A, prueba!$C:$C, $A20, prueba!$B:$B, "KG")) - (SUMIFS(COMPRAS!$E:$E, COMPRAS!$C:$C, $A20, COMPRAS!$J:$J, "UNIDAD") + SUMIFS(COMPRAS!$E:$E, COMPRAS!$C:$C, $A20, COMPRAS!$J:$J, "KG"))), 0) -> 0 | I20: =IFERROR(C20 / F20, 0) -> 0 | J20: =IFERROR(ROUNDUP((E20 / F20) * 1.1, -2),0) -> 0 | K20: =A20&B20 -> LECHUGA MORADACAJON
A21: LECHUGA MORADA | B21: KG | C21: =IFERROR(AVERAGEIFS(COMPRAS!$D:$D, COMPRAS!$C:$C, $A21, COMPRAS!$J:$J, $B21), 0) -> 0 | D21: 1.3 | E21: =ROUNDUP(C21 *D21, -2) -> 0 | F21: =IFERROR(AVERAGEIFS(COMPRAS!$F:$F, COMPRAS!$C:$C, $A21, COMPRAS!$J:$J, $B21), 1) -> 1 | G21: =IFERROR(SUMIFS(COMPRAS!I:I, COMPRAS!C:C, A21) * SUMIFS(COMPRAS!E:E, COMPRAS!C:C, A21) / COUNTIF(COMPRAS!C:C, A21), 0) -> 0 | H21: =MAX(0, (SUMIFS(COMPRAS!$E:$E, COMPRAS!$C:$C, $A21, COMPRAS!$J:$J, "UNIDAD") + SUMIFS(COMPRAS!$E:$E, COMPRAS!$C:$C, $A21, COMPRAS!$J:$J, "KG")) - (SUMIFS(prueba!$A:$A, prueba!$C:$C, $A21, prueba!$B:$B, "UNIDAD") + SUMIFS(prueba!$A:$A, prueba!$C:$C, $A21, prueba!$B:$B, "KG")) ) -> 0 | I21: =IFERROR(C21 / F21, 0) -> 0 | J21: =IFERROR(ROUNDUP((E21 / F21) * 1.1, -2),0) -> 0 | K21: =A21&B21 -> LECHUGA MORADAKG
A22: LECHUGA CRIOLLA | B22: CAJON | C22: =IFERROR(AVERAGEIFS(COMPRAS!$D:$D, COMPRAS!$C:$C, $A22, COMPRAS!$J:$J, $B22), 0) -> 0 | D22: 1.3 | E22: =ROUNDUP(C22 *D22, -3) -> 0 | F22: =IFERROR(AVERAGEIFS(COMPRAS!$F:$F, COMPRAS!$C:$C, $A22, COMPRAS!$J:$J, $B22), 1) -> 1 | G22: =IFERROR(SUMIFS(COMPRAS!I:I, COMPRAS!C:C, A22) * SUMIFS(COMPRAS!E:E, COMPRAS!C:C, A22) / COUNTIF(COMPRAS!C:C, A22), 0) -> 0 | H22: =IFERROR( ((SUMIFS(COMPRAS!$E:$E, COMPRAS!$C:$C, $A22, COMPRAS!$J:$J, "CAJON") + SUMIFS(COMPRAS!$E:$E, COMPRAS!$C:$C, $A22, COMPRAS!$J:$J, "BOLSA")) * $F22) - ((SUMIFS(prueba!$A:$A, prueba!$C:$C, $A22, prueba!$B:$B, "CAJON") + SUMIFS(prueba!$A:$A, prueba!$C:$C, $A22, prueba!$B:$B, "BOLSA")) * $F22) - MAX(0, (SUMIFS(prueba!$A:$A, prueba!$C:$C, $A22, prueba!$B:$B, "UNIDAD") + SUMIFS(prueba!$A:$A, prueba!$C:$C, $A22, prueba!$B:$B, "KG")) - (SUMIFS(COMPRAS!$E:$E, COMPRAS!$C:$C, $A22, COMPRAS!$J:$J, "UNIDAD") + SUMIFS(COMPRAS!$E:$E, COMPRAS!$C:$C, $A22, COMPRAS!$J:$J, "KG"))), 0) -> 0 | I22: =IFERROR(C22 / F22, 0) -> 0 | J22: =IFERROR(ROUNDUP((E22 / F22) * 1.1, -2),0) -> 0 | K22: =A22&B22 -> LECHUGA CRIOLLACAJON
A23: LECHUGA CRIOLLA | B23: KG | C23: =IFERROR(AVERAGEIFS(COMPRAS!$D:$D, COMPRAS!$C:$C, $A23, COMPRAS!$J:$J, $B23), 0) -> 0 | D23: 1.3 | E23: =ROUNDUP(C23 *D23, -2) -> 0 | F23: =IFERROR(AVERAGEIFS(COMPRAS!$F:$F, COMPRAS!$C:$C, $A23, COMPRAS!$J:$J, $B23), 1) -> 1 | G23: =IFERROR(SUMIFS(COMPRAS!I:I, COMPRAS!C:C, A23) * SUMIFS(COMPRAS!E:E, COMPRAS!C:C, A23) / COUNTIF(COMPRAS!C:C, A23), 0) -> 0 | H23: =MAX(0, (SUMIFS(COMPRAS!$E:$E, COMPRAS!$C:$C, $A23, COMPRAS!$J:$J, "UNIDAD") + SUMIFS(COMPRAS!$E:$E, COMPRAS!$C:$C, $A23, COMPRAS!$J:$J, "KG")) - (SUMIFS(prueba!$A:$A, prueba!$C:$C, $A23, prueba!$B:$B, "UNIDAD") + SUMIFS(prueba!$A:$A, prueba!$C:$C, $A23, prueba!$B:$B, "KG")) ) -> 0 | I23: =IFERROR(C23 / F23, 0) -> 0 | J23: =IFERROR(ROUNDUP((E23 / F23) * 1.1, -2),0) -> 0 | K23: =A23&B23 -> LECHUGA CRIOLLAKG
A24: LECHUGA FRANCESA | B24: CAJON | C24: =IFERROR(AVERAGEIFS(COMPRAS!$D:$D, COMPRAS!$C:$C, $A24, COMPRAS!$J:$J, $B24), 0) -> 0 | D24: 1.3 | E24: =ROUNDUP(C24 *D24, -3) -> 0 | F24: =IFERROR(AVERAGEIFS(COMPRAS!$F:$F, COMPRAS!$C:$C, $A24, COMPRAS!$J:$J, $B24), 1) -> 1 | G24: =IFERROR(SUMIFS(COMPRAS!I:I, COMPRAS!C:C, A24) * SUMIFS(COMPRAS!E:E, COMPRAS!C:C, A24) / COUNTIF(COMPRAS!C:C, A24), 0) -> 0 | H24: =IFERROR( ((SUMIFS(COMPRAS!$E:$E, COMPRAS!$C:$C, $A24, COMPRAS!$J:$J, "CAJON") + SUMIFS(COMPRAS!$E:$E, COMPRAS!$C:$C, $A24, COMPRAS!$J:$J, "BOLSA")) * $F24) - ((SUMIFS(prueba!$A:$A, prueba!$C:$C, $A24, prueba!$B:$B, "CAJON") + SUMIFS(prueba!$A:$A, prueba!$C:$C, $A24, prueba!$B:$B, "BOLSA")) * $F24) - MAX(0, (SUMIFS(prueba!$A:$A, prueba!$C:$C, $A24, prueba!$B:$B, "UNIDAD") + SUMIFS(prueba!$A:$A, prueba!$C:$C, $A24, prueba!$B:$B, "KG")) - (SUMIFS(COMPRAS!$E:$E, COMPRAS!$C:$C, $A24, COMPRAS!$J:$J, "UNIDAD") + SUMIFS(COMPRAS!$E:$E, COMPRAS!$C:$C, $A24, COMPRAS!$J:$J, "KG"))), 0) -> 0 | I24: =IFERROR(C24 / F24, 0) -> 0 | J24: =IFERROR(ROUNDUP((E24 / F24) * 1.1, -2),0) -> 0 | K24: =A24&B24 -> LECHUGA FRANCESACAJON
A25: LECHUGA FRANCESA | B25: KG | C25: =IFERROR(AVERAGEIFS(COMPRAS!$D:$D, COMPRAS!$C:$C, $A25, COMPRAS!$J:$J, $B25), 0) -> 0 | D25: 1.3 | E25: =ROUNDUP(C25 *D25, -2) -> 0 | F25: =IFERROR(AVERAGEIFS(COMPRAS!$F:$F, COMPRAS!$C:$C, $A25, COMPRAS!$J:$J, $B25), 1) -> 1 | G25: =IFERROR(SUMIFS(COMPRAS!I:I, COMPRAS!C:C, A25) * SUMIFS(COMPRAS!E:E, COMPRAS!C:C, A25) / COUNTIF(COMPRAS!C:C, A25), 0) -> 0 | H25: =MAX(0, (SUMIFS(COMPRAS!$E:$E, COMPRAS!$C:$C, $A25, COMPRAS!$J:$J, "UNIDAD") + SUMIFS(COMPRAS!$E:$E, COMPRAS!$C:$C, $A25, COMPRAS!$J:$J, "KG")) - (SUMIFS(prueba!$A:$A, prueba!$C:$C, $A25, prueba!$B:$B, "UNIDAD") + SUMIFS(prueba!$A:$A, prueba!$C:$C, $A25, prueba!$B:$B, "KG")) ) -> 0 | I25: =IFERROR(C25 / F25, 0) -> 0 | J25: =IFERROR(ROUNDUP((E25 / F25) * 1.1, -2),0) -> 0 | K25: =A25&B25 -> LECHUGA FRANCESAKG
A26: LECHUGA MANTECA | B26: CAJON | C26: =IFERROR(AVERAGEIFS(COMPRAS!$D:$D, COMPRAS!$C:$C, $A26, COMPRAS!$J:$J, $B26), 0) -> 0 | D26: 1.3 | E26: =ROUNDUP(C26 * D26, -3) -> 0 | F26: =IFERROR(AVERAGEIFS(COMPRAS!$F:$F, COMPRAS!$C:$C, $A26, COMPRAS!$J:$J, $B26), 1) -> 1 | G26: =IFERROR(SUMIFS(COMPRAS!I:I, COMPRAS!C:C, A26) * SUMIFS(COMPRAS!E:E, COMPRAS!C:C, A26) / COUNTIF(COMPRAS!C:C, A26), 0) -> 0 | H26: =IFERROR( ((SUMIFS(COMPRAS!$E:$E, COMPRAS!$C:$C, $A26, COMPRAS!$J:$J, "CAJON") + SUMIFS(COMPRAS!$E:$E, COMPRAS!$C:$C, $A26, COMPRAS!$J:$J, "BOLSA")) * $F26) - ((SUMIFS(prueba!$A:$A, prueba!$C:$C, $A26, prueba!$B:$B, "CAJON") + SUMIFS(prueba!$A:$A, prueba!$C:$C, $A26, prueba!$B:$B, "BOLSA")) * $F26) - MAX(0, (SUMIFS(prueba!$A:$A, prueba!$C:$C, $A26, prueba!$B:$B, "UNIDAD") + SUMIFS(prueba!$A:$A, prueba!$C:$C, $A26, prueba!$B:$B, "KG")) - (SUMIFS(COMPRAS!$E:$E, COMPRAS!$C:$C, $A26, COMPRAS!$J:$J, "UNIDAD") + SUMIFS(COMPRAS!$E:$E, COMPRAS!$C:$C, $A26, COMPRAS!$J:$J, "KG"))), 0) -> 0 | I26: =IFERROR(C26 / F26, 0) -> 0 | J26: =IFERROR(ROUNDUP((E26 / F26) * 1.1, -2),0) -> 0 | K26: =A26&B26 -> LECHUGA MANTECACAJON
A27: LECHUGA MANTECA | B27: KG | C27: =IFERROR(AVERAGEIFS(COMPRAS!$D:$D, COMPRAS!$C:$C, $A27, COMPRAS!$J:$J, $B27), 0) -> 0 | D27: 1.3 | E27: =ROUNDUP(C27 * D27, -2) -> 0 | F27: =IFERROR(AVERAGEIFS(COMPRAS!$F:$F, COMPRAS!$C:$C, $A27, COMPRAS!$J:$J, $B27), 1) -> 1 | G27: =IFERROR(SUMIFS(COMPRAS!I:I, COMPRAS!C:C, A27) * SUMIFS(COMPRAS!E:E, COMPRAS!C:C, A27) / COUNTIF(COMPRAS!C:C, A27), 0) -> 0 | H27: =MAX(0, (SUMIFS(COMPRAS!$E:$E, COMPRAS!$C:$C, $A27, COMPRAS!$J:$J, "UNIDAD") + SUMIFS(COMPRAS!$E:$E, COMPRAS!$C:$C, $A27, COMPRAS!$J:$J, "KG")) - (SUMIFS(prueba!$A:$A, prueba!$C:$C, $A27, prueba!$B:$B, "UNIDAD") + SUMIFS(prueba!$A:$A, prueba!$C:$C, $A27, prueba!$B:$B, "KG")) ) -> 0 | I27: =IFERROR(C27 / F27, 0) -> 0 | J27: =IFERROR(ROUNDUP((E27 / F27) * 1.1, -2),0) -> 0 | K27: =A27&B27 -> LECHUGA MANTECAKG
A28: PEREJIL | B28: CAJON | C28: =IFERROR(AVERAGEIFS(COMPRAS!$D:$D, COMPRAS!$C:$C, $A28, COMPRAS!$J:$J, $B28), 0) -> 0 | D28: 1.3 | E28: =ROUNDUP(C28 *D28, -3) -> 0 | F28: =IFERROR(AVERAGEIFS(COMPRAS!$F:$F, COMPRAS!$C:$C, $A28, COMPRAS!$J:$J, $B28), 1) -> 1 | G28: =IFERROR(SUMIFS(COMPRAS!I:I, COMPRAS!C:C, A28) * SUMIFS(COMPRAS!E:E, COMPRAS!C:C, A28) / COUNTIF(COMPRAS!C:C, A28), 0) -> 0 | H28: =IFERROR( ((SUMIFS(COMPRAS!$E:$E, COMPRAS!$C:$C, $A28, COMPRAS!$J:$J, "CAJON") + SUMIFS(COMPRAS!$E:$E, COMPRAS!$C:$C, $A28, COMPRAS!$J:$J, "BOLSA")) * $F28) - ((SUMIFS(prueba!$A:$A, prueba!$C:$C, $A28, prueba!$B:$B, "CAJON") + SUMIFS(prueba!$A:$A, prueba!$C:$C, $A28, prueba!$B:$B, "BOLSA")) * $F28) - MAX(0, (SUMIFS(prueba!$A:$A, prueba!$C:$C, $A28, prueba!$B:$B, "UNIDAD") + SUMIFS(prueba!$A:$A, prueba!$C:$C, $A28, prueba!$B:$B, "KG")) - (SUMIFS(COMPRAS!$E:$E, COMPRAS!$C:$C, $A28, COMPRAS!$J:$J, "UNIDAD") + SUMIFS(COMPRAS!$E:$E, COMPRAS!$C:$C, $A28, COMPRAS!$J:$J, "KG"))), 0) -> 0 | I28: =IFERROR(C28 / F28, 0) -> 0 | J28: =IFERROR(ROUNDUP((E28 / F28) * 1.1, -2),0) -> 0 | K28: =A28&B28 -> PEREJILCAJON
A29: PEREJIL | B29: UNIDAD | C29: =IFERROR(AVERAGEIFS(COMPRAS!$D:$D, COMPRAS!$C:$C, $A29, COMPRAS!$J:$J, $B29), 0) -> 0 | D29: 1.3 | E29: =ROUNDUP(C29 *D29, -2) -> 0 | F29: =IFERROR(AVERAGEIFS(COMPRAS!$F:$F, COMPRAS!$C:$C, $A29, COMPRAS!$J:$J, $B29), 1) -> 1 | G29: =IFERROR(SUMIFS(COMPRAS!I:I, COMPRAS!C:C, A29) * SUMIFS(COMPRAS!E:E, COMPRAS!C:C, A29) / COUNTIF(COMPRAS!C:C, A29), 0) -> 0 | H29: =MAX(0, (SUMIFS(COMPRAS!$E:$E, COMPRAS!$C:$C, $A29, COMPRAS!$J:$J, "UNIDAD") + SUMIFS(COMPRAS!$E:$E, COMPRAS!$C:$C, $A29, COMPRAS!$J:$J, "KG")) - (SUMIFS(prueba!$A:$A, prueba!$C:$C, $A29, prueba!$B:$B, "UNIDAD") + SUMIFS(prueba!$A:$A, prueba!$C:$C, $A29, prueba!$B:$B, "KG")) ) -> 0 | I29: =IFERROR(C29 / F29, 0) -> 0 | J29: =IFERROR(ROUNDUP((E29 / F29) * 1.1, -2),0) -> 0 | K29: =A29&B29 -> PEREJILUNIDAD
A30: PUERRO | B30: CAJON | C30: =IFERROR(AVERAGEIFS(COMPRAS!$D:$D, COMPRAS!$C:$C, $A30, COMPRAS!$J:$J, $B30), 0) -> 0 | D30: 1.3 | E30: =ROUNDUP(C30 *D30, -3) -> 0 | F30: =IFERROR(AVERAGEIFS(COMPRAS!$F:$F, COMPRAS!$C:$C, $A30, COMPRAS!$J:$J, $B30), 1) -> 1 | G30: =IFERROR(SUMIFS(COMPRAS!I:I, COMPRAS!C:C, A30) * SUMIFS(COMPRAS!E:E, COMPRAS!C:C, A30) / COUNTIF(COMPRAS!C:C, A30), 0) -> 0 | H30: =IFERROR( ((SUMIFS(COMPRAS!$E:$E, COMPRAS!$C:$C, $A30, COMPRAS!$J:$J, "CAJON") + SUMIFS(COMPRAS!$E:$E, COMPRAS!$C:$C, $A30, COMPRAS!$J:$J, "BOLSA")) * $F30) - ((SUMIFS(prueba!$A:$A, prueba!$C:$C, $A30, prueba!$B:$B, "CAJON") + SUMIFS(prueba!$A:$A, prueba!$C:$C, $A30, prueba!$B:$B, "BOLSA")) * $F30) - MAX(0, (SUMIFS(prueba!$A:$A, prueba!$C:$C, $A30, prueba!$B:$B, "UNIDAD") + SUMIFS(prueba!$A:$A, prueba!$C:$C, $A30, prueba!$B:$B, "KG")) - (SUMIFS(COMPRAS!$E:$E, COMPRAS!$C:$C, $A30, COMPRAS!$J:$J, "UNIDAD") + SUMIFS(COMPRAS!$E:$E, COMPRAS!$C:$C, $A30, COMPRAS!$J:$J, "KG"))), 0) -> 0 | I30: =IFERROR(C30 / F30, 0) -> 0 | J30: =IFERROR(ROUNDUP((E30 / F30) * 1.1, -2),0) -> 0 | K30: =A30&B30 -> PUERROCAJON
A31: PUERRO | B31: UNIDAD | C31: =IFERROR(AVERAGEIFS(COMPRAS!$D:$D, COMPRAS!$C:$C, $A31, COMPRAS!$J:$J, $B31), 0) -> 0 | D31: 1.3 | E31: =ROUNDUP(C31 *D31, -2) -> 0 | F31: =IFERROR(AVERAGEIFS(COMPRAS!$F:$F, COMPRAS!$C:$C, $A31, COMPRAS!$J:$J, $B31), 1) -> 1 | G31: =IFERROR(SUMIFS(COMPRAS!I:I, COMPRAS!C:C, A31) * SUMIFS(COMPRAS!E:E, COMPRAS!C:C, A31) / COUNTIF(COMPRAS!C:C, A31), 0) -> 0 | H31: =MAX(0, (SUMIFS(COMPRAS!$E:$E, COMPRAS!$C:$C, $A31, COMPRAS!$J:$J, "UNIDAD") + SUMIFS(COMPRAS!$E:$E, COMPRAS!$C:$C, $A31, COMPRAS!$J:$J, "KG")) - (SUMIFS(prueba!$A:$A, prueba!$C:$C, $A31, prueba!$B:$B, "UNIDAD") + SUMIFS(prueba!$A:$A, prueba!$C:$C, $A31, prueba!$B:$B, "KG")) ) -> 0 | I31: =IFERROR(C31 / F31, 0) -> 0 | J31: =IFERROR(ROUNDUP((E31 / F31) * 1.1, -2),0) -> 0 | K31: =A31&B31 -> PUERROUNIDAD
A32: RABANITO | B32: CAJON | C32: =IFERROR(AVERAGEIFS(COMPRAS!$D:$D, COMPRAS!$C:$C, $A32, COMPRAS!$J:$J, $B32), 0) -> 0 | D32: 1.3 | E32: =ROUNDUP(C32 *D32, -3) -> 0 | F32: =IFERROR(AVERAGEIFS(COMPRAS!$F:$F, COMPRAS!$C:$C, $A32, COMPRAS!$J:$J, $B32), 1) -> 1 | G32: =IFERROR(SUMIFS(COMPRAS!I:I, COMPRAS!C:C, A32) * SUMIFS(COMPRAS!E:E, COMPRAS!C:C, A32) / COUNTIF(COMPRAS!C:C, A32), 0) -> 0 | H32: =IFERROR( ((SUMIFS(COMPRAS!$E:$E, COMPRAS!$C:$C, $A32, COMPRAS!$J:$J, "CAJON") + SUMIFS(COMPRAS!$E:$E, COMPRAS!$C:$C, $A32, COMPRAS!$J:$J, "BOLSA")) * $F32) - ((SUMIFS(prueba!$A:$A, prueba!$C:$C, $A32, prueba!$B:$B, "CAJON") + SUMIFS(prueba!$A:$A, prueba!$C:$C, $A32, prueba!$B:$B, "BOLSA")) * $F32) - MAX(0, (SUMIFS(prueba!$A:$A, prueba!$C:$C, $A32, prueba!$B:$B, "UNIDAD") + SUMIFS(prueba!$A:$A, prueba!$C:$C, $A32, prueba!$B:$B, "KG")) - (SUMIFS(COMPRAS!$E:$E, COMPRAS!$C:$C, $A32, COMPRAS!$J:$J, "UNIDAD") + SUMIFS(COMPRAS!$E:$E, COMPRAS!$C:$C, $A32, COMPRAS!$J:$J, "KG"))), 0) -> 0 | I32: =IFERROR(C32 / F32, 0) -> 0 | J32: =IFERROR(ROUNDUP((E32 / F32) * 1.1, -2),0) -> 0 | K32: =A32&B32 -> RABANITOCAJON
A33: RABANITO | B33: UNIDAD | C33: =IFERROR(AVERAGEIFS(COMPRAS!$D:$D, COMPRAS!$C:$C, $A33, COMPRAS!$J:$J, $B33), 0) -> 0 | D33: 1.3 | E33: =ROUNDUP(C33 *D33, -2) -> 0 | F33: =IFERROR(AVERAGEIFS(COMPRAS!$F:$F, COMPRAS!$C:$C, $A33, COMPRAS!$J:$J, $B33), 1) -> 1 | G33: =IFERROR(SUMIFS(COMPRAS!I:I, COMPRAS!C:C, A33) * SUMIFS(COMPRAS!E:E, COMPRAS!C:C, A33) / COUNTIF(COMPRAS!C:C, A33), 0) -> 0 | H33: =MAX(0, (SUMIFS(COMPRAS!$E:$E, COMPRAS!$C:$C, $A33, COMPRAS!$J:$J, "UNIDAD") + SUMIFS(COMPRAS!$E:$E, COMPRAS!$C:$C, $A33, COMPRAS!$J:$J, "KG")) - (SUMIFS(prueba!$A:$A, prueba!$C:$C, $A33, prueba!$B:$B, "UNIDAD") + SUMIFS(prueba!$A:$A, prueba!$C:$C, $A33, prueba!$B:$B, "KG")) ) -> 0 | I33: =IFERROR(C33 / F33, 0) -> 0 | J33: =IFERROR(ROUNDUP((E33 / F33) * 1.1, -2),0) -> 0 | K33: =A33&B33 -> RABANITOUNIDAD
A34: REPOLLO BLANCO | B34: CAJON | C34: =IFERROR(AVERAGEIFS(COMPRAS!$D:$D, COMPRAS!$C:$C, $A34, COMPRAS!$J:$J, $B34), 0) -> 0 | D34: 1.3 | E34: =ROUNDUP(C34 *D34, -3) -> 0 | F34: =IFERROR(AVERAGEIFS(COMPRAS!$F:$F, COMPRAS!$C:$C, $A34, COMPRAS!$J:$J, $B34), 1) -> 1 | G34: =IFERROR(SUMIFS(COMPRAS!I:I, COMPRAS!C:C, A34) * SUMIFS(COMPRAS!E:E, COMPRAS!C:C, A34) / COUNTIF(COMPRAS!C:C, A34), 0) -> 0 | H34: =IFERROR( ((SUMIFS(COMPRAS!$E:$E, COMPRAS!$C:$C, $A34, COMPRAS!$J:$J, "CAJON") + SUMIFS(COMPRAS!$E:$E, COMPRAS!$C:$C, $A34, COMPRAS!$J:$J, "BOLSA")) * $F34) - ((SUMIFS(prueba!$A:$A, prueba!$C:$C, $A34, prueba!$B:$B, "CAJON") + SUMIFS(prueba!$A:$A, prueba!$C:$C, $A34, prueba!$B:$B, "BOLSA")) * $F34) - MAX(0, (SUMIFS(prueba!$A:$A, prueba!$C:$C, $A34, prueba!$B:$B, "UNIDAD") + SUMIFS(prueba!$A:$A, prueba!$C:$C, $A34, prueba!$B:$B, "KG")) - (SUMIFS(COMPRAS!$E:$E, COMPRAS!$C:$C, $A34, COMPRAS!$J:$J, "UNIDAD") + SUMIFS(COMPRAS!$E:$E, COMPRAS!$C:$C, $A34, COMPRAS!$J:$J, "KG"))), 0) -> 0 | I34: =IFERROR(C34 / F34, 0) -> 0 | J34: =IFERROR(ROUNDUP((E34 / F34) * 1.1, -2),0) -> 0 | K34: =A34&B34 -> REPOLLO BLANCOCAJON
A35: REPOLLO BLANCO | B35: UNIDAD | C35: =IFERROR(AVERAGEIFS(COMPRAS!$D:$D, COMPRAS!$C:$C, $A35, COMPRAS!$J:$J, $B35), 0) -> 0 | D35: 1.3 | E35: =ROUNDUP(C35 *D35, -2) -> 0 | F35: =IFERROR(AVERAGEIFS(COMPRAS!$F:$F, COMPRAS!$C:$C, $A35, COMPRAS!$J:$J, $B35), 1) -> 1 | G35: =IFERROR(SUMIFS(COMPRAS!I:I, COMPRAS!C:C, A35) * SUMIFS(COMPRAS!E:E, COMPRAS!C:C, A35) / COUNTIF(COMPRAS!C:C, A35), 0) -> 0 | H35: =MAX(0, (SUMIFS(COMPRAS!$E:$E, COMPRAS!$C:$C, $A35, COMPRAS!$J:$J, "UNIDAD") + SUMIFS(COMPRAS!$E:$E, COMPRAS!$C:$C, $A35, COMPRAS!$J:$J, "KG")) - (SUMIFS(prueba!$A:$A, prueba!$C:$C, $A35, prueba!$B:$B, "UNIDAD") + SUMIFS(prueba!$A:$A, prueba!$C:$C, $A35, prueba!$B:$B, "KG")) ) -> 0 | I35: =IFERROR(C35 / F35, 0) -> 0 | J35: =IFERROR(ROUNDUP((E35 / F35) * 1.1, -2),0) -> 0 | K35: =A35&B35 -> REPOLLO BLANCOUNIDAD
A36: REPOLLO ROJO | B36: CAJON | C36: =IFERROR(AVERAGEIFS(COMPRAS!$D:$D, COMPRAS!$C:$C, $A36, COMPRAS!$J:$J, $B36), 0) -> 0 | D36: 1.3 | E36: =ROUNDUP(C36 *D36, -3) -> 0 | F36: =IFERROR(AVERAGEIFS(COMPRAS!$F:$F, COMPRAS!$C:$C, $A36, COMPRAS!$J:$J, $B36), 1) -> 1 | G36: =IFERROR(SUMIFS(COMPRAS!I:I, COMPRAS!C:C, A36) * SUMIFS(COMPRAS!E:E, COMPRAS!C:C, A36) / COUNTIF(COMPRAS!C:C, A36), 0) -> 0 | H36: =IFERROR( ((SUMIFS(COMPRAS!$E:$E, COMPRAS!$C:$C, $A36, COMPRAS!$J:$J, "CAJON") + SUMIFS(COMPRAS!$E:$E, COMPRAS!$C:$C, $A36, COMPRAS!$J:$J, "BOLSA")) * $F36) - ((SUMIFS(prueba!$A:$A, prueba!$C:$C, $A36, prueba!$B:$B, "CAJON") + SUMIFS(prueba!$A:$A, prueba!$C:$C, $A36, prueba!$B:$B, "BOLSA")) * $F36) - MAX(0, (SUMIFS(prueba!$A:$A, prueba!$C:$C, $A36, prueba!$B:$B, "UNIDAD") + SUMIFS(prueba!$A:$A, prueba!$C:$C, $A36, prueba!$B:$B, "KG")) - (SUMIFS(COMPRAS!$E:$E, COMPRAS!$C:$C, $A36, COMPRAS!$J:$J, "UNIDAD") + SUMIFS(COMPRAS!$E:$E, COMPRAS!$C:$C, $A36, COMPRAS!$J:$J, "KG"))), 0) -> 0 | I36: =IFERROR(C36 / F36, 0) -> 0 | J36: =IFERROR(ROUNDUP((E36 / F36) * 1.1, -2),0) -> 0 | K36: =A36&B36 -> REPOLLO ROJOCAJON
A37: REPOLLO ROJO | B37: UNIDAD | C37: =IFERROR(AVERAGEIFS(COMPRAS!$D:$D, COMPRAS!$C:$C, $A37, COMPRAS!$J:$J, $B37), 0) -> 0 | D37: 1.3 | E37: =ROUNDUP(C37 *D37, -2) -> 0 | F37: =IFERROR(AVERAGEIFS(COMPRAS!$F:$F, COMPRAS!$C:$C, $A37, COMPRAS!$J:$J, $B37), 1) -> 1 | G37: =IFERROR(SUMIFS(COMPRAS!I:I, COMPRAS!C:C, A37) * SUMIFS(COMPRAS!E:E, COMPRAS!C:C, A37) / COUNTIF(COMPRAS!C:C, A37), 0) -> 0 | H37: =MAX(0, (SUMIFS(COMPRAS!$E:$E, COMPRAS!$C:$C, $A37, COMPRAS!$J:$J, "UNIDAD") + SUMIFS(COMPRAS!$E:$E, COMPRAS!$C:$C, $A37, COMPRAS!$J:$J, "KG")) - (SUMIFS(prueba!$A:$A, prueba!$C:$C, $A37, prueba!$B:$B, "UNIDAD") + SUMIFS(prueba!$A:$A, prueba!$C:$C, $A37, prueba!$B:$B, "KG")) ) -> 0 | I37: =IFERROR(C37 / F37, 0) -> 0 | J37: =IFERROR(ROUNDUP((E37 / F37) * 1.1, -2),0) -> 0 | K37: =A37&B37 -> REPOLLO ROJOUNIDAD
A38: RUCULA | B38: CAJON | C38: =IFERROR(AVERAGEIFS(COMPRAS!$D:$D, COMPRAS!$C:$C, $A38, COMPRAS!$J:$J, $B38), 0) -> 0 | D38: 1.3 | E38: =ROUNDUP(C38 * D38, -3) -> 0 | F38: =IFERROR(AVERAGEIFS(COMPRAS!$F:$F, COMPRAS!$C:$C, $A38, COMPRAS!$J:$J, $B38), 1) -> 1 | G38: =IFERROR(SUMIFS(COMPRAS!I:I, COMPRAS!C:C, A38) * SUMIFS(COMPRAS!E:E, COMPRAS!C:C, A38) / COUNTIF(COMPRAS!C:C, A38), 0) -> 0 | H38: =IFERROR( ((SUMIFS(COMPRAS!$E:$E, COMPRAS!$C:$C, $A38, COMPRAS!$J:$J, "CAJON") + SUMIFS(COMPRAS!$E:$E, COMPRAS!$C:$C, $A38, COMPRAS!$J:$J, "BOLSA")) * $F38) - ((SUMIFS(prueba!$A:$A, prueba!$C:$C, $A38, prueba!$B:$B, "CAJON") + SUMIFS(prueba!$A:$A, prueba!$C:$C, $A38, prueba!$B:$B, "BOLSA")) * $F38) - MAX(0, (SUMIFS(prueba!$A:$A, prueba!$C:$C, $A38, prueba!$B:$B, "UNIDAD") + SUMIFS(prueba!$A:$A, prueba!$C:$C, $A38, prueba!$B:$B, "KG")) - (SUMIFS(COMPRAS!$E:$E, COMPRAS!$C:$C, $A38, COMPRAS!$J:$J, "UNIDAD") + SUMIFS(COMPRAS!$E:$E, COMPRAS!$C:$C, $A38, COMPRAS!$J:$J, "KG"))), 0) -> 0 | I38: =IFERROR(C38 / F38, 0) -> 0 | J38: =IFERROR(ROUNDUP((E38 / F38) * 1.1, -2),0) -> 0 | K38: =A38&B38 -> RUCULACAJON
A39: RUCULA | B39: UNIDAD | C39: =IFERROR(AVERAGEIFS(COMPRAS!$D:$D, COMPRAS!$C:$C, $A39, COMPRAS!$J:$J, $B39), 0) -> 0 | D39: 1.3 | E39: =ROUNDUP(C39 * D39, -2) -> 0 | F39: =IFERROR(AVERAGEIFS(COMPRAS!$F:$F, COMPRAS!$C:$C, $A39, COMPRAS!$J:$J, $B39), 1) -> 1 | G39: =IFERROR(SUMIFS(COMPRAS!I:I, COMPRAS!C:C, A39) * SUMIFS(COMPRAS!E:E, COMPRAS!C:C, A39) / COUNTIF(COMPRAS!C:C, A39), 0) -> 0 | H39: =MAX(0, (SUMIFS(COMPRAS!$E:$E, COMPRAS!$C:$C, $A39, COMPRAS!$J:$J, "UNIDAD") + SUMIFS(COMPRAS!$E:$E, COMPRAS!$C:$C, $A39, COMPRAS!$J:$J, "KG")) - (SUMIFS(prueba!$A:$A, prueba!$C:$C, $A39, prueba!$B:$B, "UNIDAD") + SUMIFS(prueba!$A:$A, prueba!$C:$C, $A39, prueba!$B:$B, "KG")) ) -> 0 | I39: =IFERROR(C39 / F39, 0) -> 0 | J39: =IFERROR(ROUNDUP((E39 / F39) * 1.1, -2),0) -> 0 | K39: =A39&B39 -> RUCULAUNIDAD
A40: BANANA ECUADOR | B40: CAJON | C40: =IFERROR(AVERAGEIFS(COMPRAS!$D:$D, COMPRAS!$C:$C, $A40, COMPRAS!$J:$J, $B40), 0) -> 0 | D40: 1.3 | E40: =ROUNDUP(C40 *D40, -3) -> 0 | F40: =IFERROR(AVERAGEIFS(COMPRAS!$F:$F, COMPRAS!$C:$C, $A40, COMPRAS!$J:$J, $B40), 1) -> 1 | G40: =IFERROR(SUMIFS(COMPRAS!I:I, COMPRAS!C:C, A40) * SUMIFS(COMPRAS!E:E, COMPRAS!C:C, A40) / COUNTIF(COMPRAS!C:C, A40), 0) -> 0 | H40: =IFERROR( ((SUMIFS(COMPRAS!$E:$E, COMPRAS!$C:$C, $A40, COMPRAS!$J:$J, "CAJON") + SUMIFS(COMPRAS!$E:$E, COMPRAS!$C:$C, $A40, COMPRAS!$J:$J, "BOLSA")) * $F40) - ((SUMIFS(prueba!$A:$A, prueba!$C:$C, $A40, prueba!$B:$B, "CAJON") + SUMIFS(prueba!$A:$A, prueba!$C:$C, $A40, prueba!$B:$B, "BOLSA")) * $F40) - MAX(0, (SUMIFS(prueba!$A:$A, prueba!$C:$C, $A40, prueba!$B:$B, "UNIDAD") + SUMIFS(prueba!$A:$A, prueba!$C:$C, $A40, prueba!$B:$B, "KG")) - (SUMIFS(COMPRAS!$E:$E, COMPRAS!$C:$C, $A40, COMPRAS!$J:$J, "UNIDAD") + SUMIFS(COMPRAS!$E:$E, COMPRAS!$C:$C, $A40, COMPRAS!$J:$J, "KG"))), 0) -> 0 | I40: =IFERROR(C40 / F40, 0) -> 0 | J40: =IFERROR(ROUNDUP((E40 / F40) * 1.1, -2),0) -> 0 | K40: =A40&B40 -> BANANA ECUADORCAJON
...

Sheet STOCK
B1: COPIAR MENSAJE ABAJO (B2)
C4: STOCK | J4: MERMA
C5: CANTIDAD | D5: UNIDAD | E5: PRODUCTO | F5: KG/UN BULTO | G5: PRECIO | H5: TOTAL | J5: CANTIDAD | K5: UNIDAD | L5: PRODCUTO | M5: VALOR
C6: 1 | D6: CAJON | E6: BANANA ECUADOR | F6: =IFERROR(VLOOKUP(E6, PRECIOS!$A$40:$I$500, 6, FALSE), 1) -> 1 | G6: =IFERROR(VLOOKUP(E6, PRECIOS!$A$40:$I$500, 9, FALSE), 0) -> 0 | H6: =C6 * IFERROR(VLOOKUP(E6, PRECIOS!$A$40:$I$500, 3, FALSE), 0) -> 0 | J6: =(C6 * F6) - IFERROR(VLOOKUP(E6, PRECIOS!$A$40:$I$500, 8, FALSE), 0) -> 1 | K6: KG | L6: BANANA ECUADOR | M6: =J6 * G6 -> 0
C7: 8 | D7: KG | E7: TOMATE REDONDO | F7: =1 -> 1 | G7: =IFERROR(VLOOKUP(E7, PRECIOS!$A$40:$I$500, 9, FALSE), 0) -> 0 | H7: =C7 * IFERROR(VLOOKUP(E7, PRECIOS!$A$40:$I$500, 3, FALSE), 0) -> 0 | J7: =(C7 * F7) - IFERROR(VLOOKUP(E7, PRECIOS!$A$40:$I$500, 8, FALSE), 0) -> 10 | K7: KG | L7: TOMATE REDONDO | M7: =J7 * G7 -> 0
C8: 2 | D8: KG | E8: CEBOLLA MAQUINADA | F8: =1 -> 1 | G8: =IFERROR(VLOOKUP(E8, PRECIOS!$A$40:$I$500, 9, FALSE), 0) -> 0 | H8: =C8 * IFERROR(VLOOKUP(E8, PRECIOS!$A$40:$I$500, 3, FALSE), 0) -> 0 | J8: =(C8 * F8) - IFERROR(VLOOKUP(E8, PRECIOS!$A$40:$I$500, 8, FALSE), 0) -> 2 | K8: KG | L8: CEBOLLA MAQUINADA | M8: =J8 * G8 -> 0

Sheet ARMADO DE COMPRA
B1: COPIAR MENSAJE ABAJO (B2)
B4: CLIENTES YA PROCESADOS | C4: GRUPO | D4: CANTIDAD | E4: UNIDAD | F4: PRODUCTO
B5: FV | C5: FRUTA | D5: 2 | E5: CAJON | F5: NARANJA JUGO COMERCIAL
B6: BRASOV | C6: HORTALIZA LIVIANA | D6: 3 | E6: CAJON | F6: TOMATE REDONDO
C7: VERDURA | D7: 12 | E7: UNIDAD | F7: APIO

Sheet CARGA DE PEDIDOS
B1: COPIAR MENSAJE ABAJO (B2)
C4: ¿LLEVA IVA? | D4: SI
C6: FV | F6: rto: | G6: =TODAY() -> 46079 | K6: COMPRA
C8: CANTIDAD | D8: UNIDAD | E8: PRODUCTO | F8: PRECIO | G8: TOTAL | H8: TOTAL + IVA | K8: COSTO | L8: TOTAL | M8: DIFERENCIA
C9: 2 | D9: CAJON | E9: TOMATE REDONDO | F9: =LET( precio_exacto, SUMIFS(PRECIOS!$E:$E, PRECIOS!$A:$A, E9, PRECIOS!$B:$B, D9), precio_unitario_cajon, SUMIFS(PRECIOS!$J:$J, PRECIOS!$A:$A, E9, PRECIOS!$B:$B, "CAJON"), precio_unitario_bolsa, SUMIFS(PRECIOS!$J:$J, PRECIOS!$A:$A, E9, PRECIOS!$B:$B, "BOLSA"), IF(precio_exacto > 0, precio_exacto, IF(precio_unitario_cajon > 0, precio_unitario_cajon, IF(precio_unitario_bolsa > 0, precio_unitario_bolsa, 0) ) ) ) -> 0 | G9: =C9*F9 -> 0 | H9: =G9*1.105 -> 0 | K9: =IFERROR( IF(OR(D9="CAJON", D9="BOLSA"), SUMIFS(PRECIOS!$C:$C, PRECIOS!$A:$A, E9, PRECIOS!$B:$B, D9), LET( stock_suelto_inicial, SUMIFS(COMPRAS!$E:$E, COMPRAS!$C:$C, E9, COMPRAS!$J:$J, "UNIDAD") + SUMIFS(COMPRAS!$E:$E, COMPRAS!$C:$C, E9, COMPRAS!$J:$J, "KG"), acumulado_anterior, SUMIFS($M8:O$9, $C8:E$9, E9), unidades_esta_venta, C9, costo_unidad_base, SUMIFS(PRECIOS!$I:$I, PRECIOS!$A:$A, E9, PRECIOS!$B:$B, "UNIDAD") + SUMIFS(PRECIOS!$I:$I, PRECIOS!$A:$A, E9, PRECIOS!$B:$B, "KG"), costo_cajon, SUMIFS(PRECIOS!$I:$I, PRECIOS!$A:$A, E9, PRECIOS!$B:$B, "CAJON"), costo_bolsa, SUMIFS(PRECIOS!$I:$I, PRECIOS!$A:$A, E9, PRECIOS!$B:$B, "BOLSA"), costo_bulto_ref, IF(costo_cajon > 0, costo_cajon, costo_bolsa), unidades_con_costo_suelto, MAX(0, MIN(unidades_esta_venta, stock_suelto_inicial - acumulado_anterior)), unidades_con_costo_bulto, unidades_esta_venta - unidades_con_costo_suelto, IF(unidades_esta_venta = 0, 0, ((unidades_con_costo_suelto * costo_unidad_base) + (unidades_con_costo_bulto * costo_bulto_ref)) / unidades_esta_venta ) ) ), 0) -> 0 | L9: =K9*C9 -> 0 | M9: =H9-L9 -> 0
C10: 2 | D10: UNIDAD | E10: APIO | F10: =LET( precio_exacto, SUMIFS(PRECIOS!$E:$E, PRECIOS!$A:$A, E10, PRECIOS!$B:$B, D10), precio_unitario_cajon, SUMIFS(PRECIOS!$J:$J, PRECIOS!$A:$A, E10, PRECIOS!$B:$B, "CAJON"), precio_unitario_bolsa, SUMIFS(PRECIOS!$J:$J, PRECIOS!$A:$A, E10, PRECIOS!$B:$B, "BOLSA"), IF(precio_exacto > 0, precio_exacto, IF(precio_unitario_cajon > 0, precio_unitario_cajon, IF(precio_unitario_bolsa > 0, precio_unitario_bolsa, 0) ) ) ) -> 0 | G10: =C10*F10 -> 0 | H10: =G10*1.105 -> 0 | K10: =IFERROR( IF(OR(D10="CAJON", D10="BOLSA"), SUMIFS(PRECIOS!$C:$C, PRECIOS!$A:$A, E10, PRECIOS!$B:$B, D10), LET( stock_suelto_inicial, SUMIFS(COMPRAS!$E:$E, COMPRAS!$C:$C, E10, COMPRAS!$J:$J, "UNIDAD") + SUMIFS(COMPRAS!$E:$E, COMPRAS!$C:$C, E10, COMPRAS!$J:$J, "KG"), acumulado_anterior, SUMIFS($M$9:O9, $C$9:E9, E10), unidades_esta_venta, C10, costo_unidad_base, SUMIFS(PRECIOS!$I:$I, PRECIOS!$A:$A, E10, PRECIOS!$B:$B, "UNIDAD") + SUMIFS(PRECIOS!$I:$I, PRECIOS!$A:$A, E10, PRECIOS!$B:$B, "KG"), costo_cajon, SUMIFS(PRECIOS!$I:$I, PRECIOS!$A:$A, E10, PRECIOS!$B:$B, "CAJON"), costo_bolsa, SUMIFS(PRECIOS!$I:$I, PRECIOS!$A:$A, E10, PRECIOS!$B:$B, "BOLSA"), costo_bulto_ref, IF(costo_cajon > 0, costo_cajon, costo_bolsa), unidades_con_costo_suelto, MAX(0, MIN(unidades_esta_venta, stock_suelto_inicial - acumulado_anterior)), unidades_con_costo_bulto, unidades_esta_venta - unidades_con_costo_suelto, IF(unidades_esta_venta = 0, 0, ((unidades_con_costo_suelto * costo_unidad_base) + (unidades_con_costo_bulto * costo_bulto_ref)) / unidades_esta_venta ) ) ), 0) -> 0 | L10: =K10*C10 -> 0 | M10: =H10-L10 -> 0
C11: 1 | D11: CAJON | E11: NARANJA JUGO COMERCIAL | F11: =LET( precio_exacto, SUMIFS(PRECIOS!$E:$E, PRECIOS!$A:$A, E11, PRECIOS!$B:$B, D11), precio_unitario_cajon, SUMIFS(PRECIOS!$J:$J, PRECIOS!$A:$A, E11, PRECIOS!$B:$B, "CAJON"), precio_unitario_bolsa, SUMIFS(PRECIOS!$J:$J, PRECIOS!$A:$A, E11, PRECIOS!$B:$B, "BOLSA"), IF(precio_exacto > 0, precio_exacto, IF(precio_unitario_cajon > 0, precio_unitario_cajon, IF(precio_unitario_bolsa > 0, precio_unitario_bolsa, 0) ) ) ) -> 0 | G11: =C11*F11 -> 0 | H11: =G11*1.105 -> 0 | K11: =IFERROR( IF(OR(D11="CAJON", D11="BOLSA"), SUMIFS(PRECIOS!$C:$C, PRECIOS!$A:$A, E11, PRECIOS!$B:$B, D11), LET( stock_suelto_inicial, SUMIFS(COMPRAS!$E:$E, COMPRAS!$C:$C, E11, COMPRAS!$J:$J, "UNIDAD") + SUMIFS(COMPRAS!$E:$E, COMPRAS!$C:$C, E11, COMPRAS!$J:$J, "KG"), acumulado_anterior, SUMIFS($M$9:O10, $C$9:E10, E11), unidades_esta_venta, C11, costo_unidad_base, SUMIFS(PRECIOS!$I:$I, PRECIOS!$A:$A, E11, PRECIOS!$B:$B, "UNIDAD") + SUMIFS(PRECIOS!$I:$I, PRECIOS!$A:$A, E11, PRECIOS!$B:$B, "KG"), costo_cajon, SUMIFS(PRECIOS!$I:$I, PRECIOS!$A:$A, E11, PRECIOS!$B:$B, "CAJON"), costo_bolsa, SUMIFS(PRECIOS!$I:$I, PRECIOS!$A:$A, E11, PRECIOS!$B:$B, "BOLSA"), costo_bulto_ref, IF(costo_cajon > 0, costo_cajon, costo_bolsa), unidades_con_costo_suelto, MAX(0, MIN(unidades_esta_venta, stock_suelto_inicial - acumulado_anterior)), unidades_con_costo_bulto, unidades_esta_venta - unidades_con_costo_suelto, IF(unidades_esta_venta = 0, 0, ((unidades_con_costo_suelto * costo_unidad_base) + (unidades_con_costo_bulto * costo_bulto_ref)) / unidades_esta_venta ) ) ), 0) -> 0 | L11: =K11*C11 -> 0 | M11: =H11-L11 -> 0
G13: =SUM(G9:G11) -> 0 | H13: =SUM(H9:H11) -> 0 | M13: =SUM(M9:M11) -> 0 | N13: =IFERROR(M13/G13, 0) -> 0
F500: =LET( precio_exacto, SUMIFS(PRECIOS!$E:$E, PRECIOS!$A:$A, E500, PRECIOS!$B:$B, D500), precio_unitario_cajon, SUMIFS(PRECIOS!$J:$J, PRECIOS!$A:$A, E500, PRECIOS!$B:$B, "CAJON"), precio_unitario_bolsa, SUMIFS(PRECIOS!$J:$J, PRECIOS!$A:$A, E500, PRECIOS!$B:$B, "BOLSA"), IF(precio_exacto > 0, precio_exacto, IF(precio_unitario_cajon > 0, precio_unitario_cajon, IF(precio_unitario_bolsa > 0, precio_unitario_bolsa, 0) ) ) ) -> 0 | G500: =C500*F500 -> 0 | H500: =G500*1.105 -> 0 | K500: =IFERROR( IF(OR(D500="CAJON", D500="BOLSA"), SUMIFS(PRECIOS!$C:$C, PRECIOS!$A:$A, E500, PRECIOS!$B:$B, D500), LET( stock_suelto_inicial, SUMIFS(COMPRAS!$E:$E, COMPRAS!$C:$C, E500, COMPRAS!$J:$J, "UNIDAD") + SUMIFS(COMPRAS!$E:$E, COMPRAS!$C:$C, E500, COMPRAS!$J:$J, "KG"), acumulado_anterior, SUMIFS($M$9:O499, $C$9:E499, E500), unidades_esta_venta, C500, costo_unidad_base, SUMIFS(PRECIOS!$I:$I, PRECIOS!$A:$A, E500, PRECIOS!$B:$B, "UNIDAD") + SUMIFS(PRECIOS!$I:$I, PRECIOS!$A:$A, E500, PRECIOS!$B:$B, "KG"), costo_cajon, SUMIFS(PRECIOS!$I:$I, PRECIOS!$A:$A, E500, PRECIOS!$B:$B, "CAJON"), costo_bolsa, SUMIFS(PRECIOS!$I:$I, PRECIOS!$A:$A, E500, PRECIOS!$B:$B, "BOLSA"), costo_bulto_ref, IF(costo_cajon > 0, costo_cajon, costo_bolsa), unidades_con_costo_suelto, MAX(0, MIN(unidades_esta_venta, stock_suelto_inicial - acumulado_anterior)), unidades_con_costo_bulto, unidades_esta_venta - unidades_con_costo_suelto, IF(unidades_esta_venta = 0, 0, ((unidades_con_costo_suelto * costo_unidad_base) + (unidades_con_costo_bulto * costo_bulto_ref)) / unidades_esta_venta ) ) ), 0) -> 0 | L500: =K500*C500 -> 0 | M500: =H500-L500 -> 0

Sheet prueba
A1: FECHA | B1: =TODAY() -> 46079
A3: FV | D3: rto: | E3: =TODAY() -> 46079 | I3: COMPRA
A5: CANTIDAD | B5: UNIDAD | C5: PRODUCTO | D5: PRECIO | E5: TOTAL | F5: TOTAL + IVA | I5: COSTO | J5: TOTAL | K5: DIFERENCIA | M5: UN/KG X PRODUCTO
A6: 2 | B6: CAJON | C6: TOMATE REDONDO | D6: =LET( precio_exacto, SUMIFS(PRECIOS!$E:$E, PRECIOS!$A:$A, C6, PRECIOS!$B:$B, B6), precio_unitario_cajon, SUMIFS(PRECIOS!$J:$J, PRECIOS!$A:$A, C6, PRECIOS!$B:$B, "CAJON"), precio_unitario_bolsa, SUMIFS(PRECIOS!$J:$J, PRECIOS!$A:$A, C6, PRECIOS!$B:$B, "BOLSA"), IF(precio_exacto > 0, precio_exacto, IF(precio_unitario_cajon > 0, precio_unitario_cajon, IF(precio_unitario_bolsa > 0, precio_unitario_bolsa, 0) ) ) ) -> 0 | E6: =A6*D6 -> 0 | F6: =E6*1.105 -> 0 | I6: =IFERROR( IF(OR(B6="CAJON", B6="BOLSA"), SUMIFS(PRECIOS!$C:$C, PRECIOS!$A:$A, C6, PRECIOS!$B:$B, B6), LET( stock_suelto_inicial, SUMIFS(COMPRAS!$E:$E, COMPRAS!$C:$C, C6, COMPRAS!$J:$J, "UNIDAD") + SUMIFS(COMPRAS!$E:$E, COMPRAS!$C:$C, C6, COMPRAS!$J:$J, "KG"), acumulado_anterior, SUMIFS($M5:M$9, $C5:C$9, C6), unidades_esta_venta, A6, costo_unidad_base, SUMIFS(PRECIOS!$I:$I, PRECIOS!$A:$A, C6, PRECIOS!$B:$B, "UNIDAD") + SUMIFS(PRECIOS!$I:$I, PRECIOS!$A:$A, C6, PRECIOS!$B:$B, "KG"), costo_cajon, SUMIFS(PRECIOS!$I:$I, PRECIOS!$A:$A, C6, PRECIOS!$B:$B, "CAJON"), costo_bolsa, SUMIFS(PRECIOS!$I:$I, PRECIOS!$A:$A, C6, PRECIOS!$B:$B, "BOLSA"), costo_bulto_ref, IF(costo_cajon > 0, costo_cajon, costo_bolsa), unidades_con_costo_suelto, MAX(0, MIN(unidades_esta_venta, stock_suelto_inicial - acumulado_anterior)), unidades_con_costo_bulto, unidades_esta_venta - unidades_con_costo_suelto, IF(unidades_esta_venta = 0, 0, ((unidades_con_costo_suelto * costo_unidad_base) + (unidades_con_costo_bulto * costo_bulto_ref)) / unidades_esta_venta ) ) ), 0) -> 0 | J6: =I6*A6 -> 0 | K6: =F6-J6 -> 0 | M6: =IF(C6="", 0, SUMIFS($M$5:M5, $C$5:C5, C6) + IF(OR(B6="UNIDAD", B6="KG"), A6, 0) ) -> 0
A7: 2 | B7: UNIDAD | C7: APIO | D7: =LET( precio_exacto, SUMIFS(PRECIOS!$E:$E, PRECIOS!$A:$A, C7, PRECIOS!$B:$B, B7), precio_unitario_cajon, SUMIFS(PRECIOS!$J:$J, PRECIOS!$A:$A, C7, PRECIOS!$B:$B, "CAJON"), precio_unitario_bolsa, SUMIFS(PRECIOS!$J:$J, PRECIOS!$A:$A, C7, PRECIOS!$B:$B, "BOLSA"), IF(precio_exacto > 0, precio_exacto, IF(precio_unitario_cajon > 0, precio_unitario_cajon, IF(precio_unitario_bolsa > 0, precio_unitario_bolsa, 0) ) ) ) -> 0 | E7: =A7*D7 -> 0 | F7: =E7*1.105 -> 0 | I7: =IFERROR( IF(OR(B7="CAJON", B7="BOLSA"), SUMIFS(PRECIOS!$C:$C, PRECIOS!$A:$A, C7, PRECIOS!$B:$B, B7), LET( stock_suelto_inicial, SUMIFS(COMPRAS!$E:$E, COMPRAS!$C:$C, C7, COMPRAS!$J:$J, "UNIDAD") + SUMIFS(COMPRAS!$E:$E, COMPRAS!$C:$C, C7, COMPRAS!$J:$J, "KG"), acumulado_anterior, SUMIFS($M6:M$9, $C6:C$9, C7), unidades_esta_venta, A7, costo_unidad_base, SUMIFS(PRECIOS!$I:$I, PRECIOS!$A:$A, C7, PRECIOS!$B:$B, "UNIDAD") + SUMIFS(PRECIOS!$I:$I, PRECIOS!$A:$A, C7, PRECIOS!$B:$B, "KG"), costo_cajon, SUMIFS(PRECIOS!$I:$I, PRECIOS!$A:$A, C7, PRECIOS!$B:$B, "CAJON"), costo_bolsa, SUMIFS(PRECIOS!$I:$I, PRECIOS!$A:$A, C7, PRECIOS!$B:$B, "BOLSA"), costo_bulto_ref, IF(costo_cajon > 0, costo_cajon, costo_bolsa), unidades_con_costo_suelto, MAX(0, MIN(unidades_esta_venta, stock_suelto_inicial - acumulado_anterior)), unidades_con_costo_bulto, unidades_esta_venta - unidades_con_costo_suelto, IF(unidades_esta_venta = 0, 0, ((unidades_con_costo_suelto * costo_unidad_base) + (unidades_con_costo_bulto * costo_bulto_ref)) / unidades_esta_venta ) ) ), 0) -> 0 | J7: =I7*A7 -> 0 | K7: =F7-J7 -> 0 | M7: =IF(C7="", 0, SUMIFS($M$5:M6, $C$5:C6, C7) + IF(OR(B7="UNIDAD", B7="KG"), A7, 0) ) -> 2
A8: 1 | B8: CAJON | C8: NARANJA JUGO COMERCIAL | D8: =LET( precio_exacto, SUMIFS(PRECIOS!$E:$E, PRECIOS!$A:$A, C8, PRECIOS!$B:$B, B8), precio_unitario_cajon, SUMIFS(PRECIOS!$J:$J, PRECIOS!$A:$A, C8, PRECIOS!$B:$B, "CAJON"), precio_unitario_bolsa, SUMIFS(PRECIOS!$J:$J, PRECIOS!$A:$A, C8, PRECIOS!$B:$B, "BOLSA"), IF(precio_exacto > 0, precio_exacto, IF(precio_unitario_cajon > 0, precio_unitario_cajon, IF(precio_unitario_bolsa > 0, precio_unitario_bolsa, 0) ) ) ) -> 0 | E8: =A8*D8 -> 0 | F8: =E8*1.105 -> 0 | I8: =IFERROR( IF(OR(B8="CAJON", B8="BOLSA"), SUMIFS(PRECIOS!$C:$C, PRECIOS!$A:$A, C8, PRECIOS!$B:$B, B8), LET( stock_suelto_inicial, SUMIFS(COMPRAS!$E:$E, COMPRAS!$C:$C, C8, COMPRAS!$J:$J, "UNIDAD") + SUMIFS(COMPRAS!$E:$E, COMPRAS!$C:$C, C8, COMPRAS!$J:$J, "KG"), acumulado_anterior, SUMIFS($M7:M$9, $C7:C$9, C8), unidades_esta_venta, A8, costo_unidad_base, SUMIFS(PRECIOS!$I:$I, PRECIOS!$A:$A, C8, PRECIOS!$B:$B, "UNIDAD") + SUMIFS(PRECIOS!$I:$I, PRECIOS!$A:$A, C8, PRECIOS!$B:$B, "KG"), costo_cajon, SUMIFS(PRECIOS!$I:$I, PRECIOS!$A:$A, C8, PRECIOS!$B:$B, "CAJON"), costo_bolsa, SUMIFS(PRECIOS!$I:$I, PRECIOS!$A:$A, C8, PRECIOS!$B:$B, "BOLSA"), costo_bulto_ref, IF(costo_cajon > 0, costo_cajon, costo_bolsa), unidades_con_costo_suelto, MAX(0, MIN(unidades_esta_venta, stock_suelto_inicial - acumulado_anterior)), unidades_con_costo_bulto, unidades_esta_venta - unidades_con_costo_suelto, IF(unidades_esta_venta = 0, 0, ((unidades_con_costo_suelto * costo_unidad_base) + (unidades_con_costo_bulto * costo_bulto_ref)) / unidades_esta_venta ) ) ), 0) -> 0 | J8: =I8*A8 -> 0 | K8: =F8-J8 -> 0 | M8: =IF(C8="", 0, SUMIFS($M$5:M7, $C$5:C7, C8) + IF(OR(B8="UNIDAD", B8="KG"), A8, 0) ) -> 0
M9: =IF(C9="", 0, SUMIFS($M$5:M8, $C$5:C8, C9) + IF(OR(B9="UNIDAD", B9="KG"), A9, 0) ) -> 0
E10: =SUM(E6:E8) -> 0 | F10: =SUM(F6:F8) -> 0 | K10: =SUM(K6:K8) -> 0 | L10: =IFERROR(K10/E10, 0) -> 0 | M10: =IF(C10="", 0, SUMIFS($M$5:M9, $C$5:C9, C10) + IF(OR(B10="UNIDAD", B10="KG"), A10, 0) ) -> 0
M11: =IF(C11="", 0, SUMIFS($M$5:M10, $C$5:C10, C11) + IF(OR(B11="UNIDAD", B11="KG"), A11, 0) ) -> 0
M12: =IF(C12="", 0, SUMIFS($M$5:M11, $C$5:C11, C12) + IF(OR(B12="UNIDAD", B12="KG"), A12, 0) ) -> 0
M13: =IF(C13="", 0, SUMIFS($M$5:M12, $C$5:C12, C13) + IF(OR(B13="UNIDAD", B13="KG"), A13, 0) ) -> 0
M14: =IF(C14="", 0, SUMIFS($M$5:M13, $C$5:C13, C14) + IF(OR(B14="UNIDAD", B14="KG"), A14, 0) ) -> 0
M15: =IF(C15="", 0, SUMIFS($M$5:M14, $C$5:C14, C15) + IF(OR(B15="UNIDAD", B15="KG"), A15, 0) ) -> 0
M16: =IF(C16="", 0, SUMIFS($M$5:M15, $C$5:C15, C16) + IF(OR(B16="UNIDAD", B16="KG"), A16, 0) ) -> 0
M17: =IF(C17="", 0, SUMIFS($M$5:M16, $C$5:C16, C17) + IF(OR(B17="UNIDAD", B17="KG"), A17, 0) ) -> 0
M18: =IF(C18="", 0, SUMIFS($M$5:M17, $C$5:C17, C18) + IF(OR(B18="UNIDAD", B18="KG"), A18, 0) ) -> 0
M19: =IF(C19="", 0, SUMIFS($M$5:M18, $C$5:C18, C19) + IF(OR(B19="UNIDAD", B19="KG"), A19, 0) ) -> 0
M20: =IF(C20="", 0, SUMIFS($M$5:M19, $C$5:C19, C20) + IF(OR(B20="UNIDAD", B20="KG"), A20, 0) ) -> 0
M21: =IF(C21="", 0, SUMIFS($M$5:M20, $C$5:C20, C21) + IF(OR(B21="UNIDAD", B21="KG"), A21, 0) ) -> 0
M22: =IF(C22="", 0, SUMIFS($M$5:M21, $C$5:C21, C22) + IF(OR(B22="UNIDAD", B22="KG"), A22, 0) ) -> 0
... M248: =IF(C248="", 0, SUMIFS($M$5:M247, $C$5:C247, C248) + IF(OR(B248="UNIDAD", B248="KG"), A248, 0) ) -> 0
