Workbook

Sheet 01-04-2026 
A3: COLEGIO SJCB - VIRREY DEL PINO 3299 | E3: rto: 15 | F3: 46113 | I3: COMPRA
A5: CANTIDAD | B5: UNIDAD | C5: PRODUCTO | D5: PRECIO | E5: TOTAL | F5: TOTAL + IVA | I5: COSTO | J5: TOTAL | K5: DIFERENCIA
A6: 4 | B6: MAPLE | C6: HUEVO N1 | D6: 4500 | E6: =A6*D6 -> 18000 | F6: =E6*1.21 -> 21780 | I6: =54000/12 -> 4500 | J6: =I6*A6 -> 18000 | K6: =F6-J6 -> 3780 | L6: =IFERROR(K6/E6, 0) -> 0.21
A7: 1 | B7: UNIDAD | C7: AJO | D7: 900 | E7: =A7*D7 -> 900 | F7: =E7*1.105 -> 994.5 | I7: 460 | J7: =I7*A7 -> 460 | K7: =F7-J7 -> 534.5 | L7: =IFERROR(K7/E7, 0) -> 0.59388889
A8: 1 | B8: UNIDAD | C8: BROCOLI | D8: 2600 | E8: =A8*D8 -> 2600 | F8: =E8*1.105 -> 2873 | I8: =18000/13 -> 1384.6154 | J8: =I8*A8 -> 1384.6154 | K8: =F8-J8 -> 1488.3846 | L8: =IFERROR(K8/E8, 0) -> 0.57245562
A9: 1 | B9: BOLSA | C9: ANCO | D9: 13000 | E9: =A9*D9 -> 13000 | F9: =E9*1.105 -> 14365 | I9: 9000 | J9: =I9*A9 -> 9000 | K9: =F9-J9 -> 5365 | L9: =IFERROR(K9/E9, 0) -> 0.41269231
A10: 2.5 | B10: KG | C10: CEBOLLA MORADA | D10: 1600 | E10: =A10*D10 -> 4000 | F10: =E10*1.105 -> 4420 | I10: =12000/15 -> 800 | J10: =I10*A10 -> 2000 | K10: =F10-J10 -> 2420 | L10: =IFERROR(K10/E10, 0) -> 0.605
A11: 0.8 | B11: KG | C11: CHAUCHA PLANA | D11: 4000 | E11: =A11*D11 -> 3200 | F11: =E11*1.105 -> 3536 | I11: =13000/8 -> 1625 | J11: =I11*A11 -> 1300 | K11: =F11-J11 -> 2236 | L11: =IFERROR(K11/E11, 0) -> 0.69875
A12: 25 | B12: UNIDAD | C12: CHOCLO | D12: 800 | E12: =A12*D12 -> 20000 | F12: =E12*1.105 -> 22100 | I12: =30000/94 -> 319.14894 | J12: =I12*A12 -> 7978.7234 | K12: =F12-J12 -> 14121.277 | L12: =IFERROR(K12/E12, 0) -> 0.70606383
A13: 2 | B13: ATADO | C13: ESPINACA | D13: 1700 | E13: =A13*D13 -> 3400 | F13: =E13*1.105 -> 3757 | I13: =12000/10 -> 1200 | J13: =I13*A13 -> 2400 | K13: =F13-J13 -> 1357 | L13: =IFERROR(K13/E13, 0) -> 0.39911765
A14: 0.5 | B14: CAJON | C14: MANZANA ROJA | D14: 58000 | E14: =A14*D14 -> 29000 | F14: =E14*1.105 -> 32045 | I14: 53000 | J14: =I14*A14 -> 26500 | K14: =F14-J14 -> 5545 | L14: =IFERROR(K14/E14, 0) -> 0.1912069
A15: 0.5 | B15: CAJON | C15: MANZANA VERDE | D15: 70000 | E15: =A15*D15 -> 35000 | F15: =E15*1.105 -> 38675 | I15: 65000 | J15: =I15*A15 -> 32500 | K15: =F15-J15 -> 6175 | L15: =IFERROR(K15/E15, 0) -> 0.17642857
A16: 1 | B16: CAJON | C16: NARANJA | D16: 25000 | E16: =A16*D16 -> 25000 | F16: =E16*1.105 -> 27625 | I16: 22000 | J16: =I16*A16 -> 22000 | K16: =F16-J16 -> 5625 | L16: =IFERROR(K16/E16, 0) -> 0.225
A17: 1 | B17: BOLSA | C17: PAPA BLANCA | D17: 23000 | E17: =A17*D17 -> 23000 | F17: =E17*1.105 -> 25415 | I17: 19000 | J17: =I17*A17 -> 19000 | K17: =F17-J17 -> 6415 | L17: =IFERROR(K17/E17, 0) -> 0.27891304
A18: 1 | B18: ATADO | C18: CIBOULETTE | D18: 3000 | E18: =A18*D18 -> 3000 | F18: =E18*1.105 -> 3315 | I18: 2000 | J18: =I18*A18 -> 2000 | K18: =F18-J18 -> 1315 | L18: =IFERROR(K18/E18, 0) -> 0.43833333
A19: 0.1 | B19: KG | C19: PEREJIL | D19: 3500 | E19: =A19*D19 -> 350 | F19: =E19*1.105 -> 386.75 | I19: 1000 | J19: =I19*A19 -> 100 | K19: =F19-J19 -> 286.75 | L19: =IFERROR(K19/E19, 0) -> 0.81928571
A20: 0.75 | B20: KG | C20: PEPINO | D20: 1500 | E20: =A20*D20 -> 1125 | F20: =E20*1.105 -> 1243.125 | I20: 1500 | J20: =I20*A20 -> 1125 | K20: =F20-J20 -> 118.125 | L20: =IFERROR(K20/E20, 0) -> 0.105
A21: 1.3 | B21: KG | C21: MORRON ROJO | D21: 3200 | E21: =A21*D21 -> 4160 | F21: =E21*1.105 -> 4596.8 | I21: 1000 | J21: =I21*A21 -> 1300 | K21: =F21-J21 -> 3296.8 | L21: =IFERROR(K21/E21, 0) -> 0.7925
A22: 0.5 | B22: KG | C22: MORRON VERDE | D22: 2400 | E22: =A22*D22 -> 1200 | F22: =E22*1.105 -> 1326 | I22: 1000 | J22: =I22*A22 -> 500 | K22: =F22-J22 -> 826 | L22: =IFERROR(K22/E22, 0) -> 0.68833333
A23: 0.5 | B23: KG | C23: MORRON AMARILLO | D23: 2800 | E23: =A23*D23 -> 1400 | F23: =E23*1.105 -> 1547 | I23: =12000/7 -> 1714.2857 | J23: =I23*A23 -> 857.14286 | K23: =F23-J23 -> 689.85714 | L23: =IFERROR(K23/E23, 0) -> 0.4927551
A24: 1.2 | B24: KG | C24: PUERRO | D24: 5000 | E24: =A24*D24 -> 6000 | F24: =E24*1.105 -> 6630 | I24: 2000 | J24: =I24*A24 -> 2400 | K24: =F24-J24 -> 4230 | L24: =IFERROR(K24/E24, 0) -> 0.705
A25: 0.6 | B25: KG | C25: REMOLACHA | D25: 2500 | E25: =A25*D25 -> 1500 | F25: =E25*1.105 -> 1657.5 | I25: =14000/11 -> 1272.7273 | J25: =I25*A25 -> 763.63636 | K25: =F25-J25 -> 893.86364 | L25: =IFERROR(K25/E25, 0) -> 0.59590909
A26: 2 | B26: KG | C26: REPOLLO BLANCO | D26: 1800 | E26: =A26*D26 -> 3600 | F26: =E26*1.105 -> 3978 | I26: 1000 | J26: =I26*A26 -> 2000 | K26: =F26-J26 -> 1978 | L26: =IFERROR(K26/E26, 0) -> 0.54944444
A27: 1.2 | B27: KG | C27: REPOLLO COLORADO | D27: 1800 | E27: =A27*D27 -> 2160 | F27: =E27*1.105 -> 2386.8 | I27: 1000 | J27: =I27*A27 -> 1200 | K27: =F27-J27 -> 1186.8 | L27: =IFERROR(K27/E27, 0) -> 0.54944444
A28: 9 | B28: KG | C28: TOMATE PERITA | D28: 2400 | E28: =A28*D28 -> 21600 | F28: =E28*1.105 -> 23868 | I28: =15000/15 -> 1000 | J28: =I28*A28 -> 9000 | K28: =F28-J28 -> 14868 | L28: =IFERROR(K28/E28, 0) -> 0.68833333
A29: 6 | B29: KG | C29: ZANAHORIA | D29: 1300 | E29: =A29*D29 -> 7800 | F29: =E29*1.105 -> 8619 | I29: 1000 | J29: =I29*A29 -> 6000 | K29: =F29-J29 -> 2619 | L29: =IFERROR(K29/E29, 0) -> 0.33576923
A30: 2 | B30: UNIDAD | C30: COLIFLOR | D30: 2800 | E30: =A30*D30 -> 5600 | F30: =E30*1.105 -> 6188 | I30: =18000/10 -> 1800 | J30: =I30*A30 -> 3600 | K30: =F30-J30 -> 2588 | L30: =IFERROR(K30/E30, 0) -> 0.46214286
A31: 0.5 | B31: ATADO | C31: CEBOLLA DE VERDEO | D31: 4500 | E31: =A31*D31 -> 2250 | F31: =E31*1.105 -> 2486.25 | I31: 1200 | J31: =I31*A31 -> 600 | K31: =F31-J31 -> 1886.25 | L31: =IFERROR(K31/E31, 0) -> 0.83833333
A32: 0.5 | B32: KG | C32: LECHUGA CRIOLLA | D32: 3200 | E32: =A32*D32 -> 1600 | F32: =E32*1.105 -> 1768 | I32: 2000 | J32: =I32*A32 -> 1000 | K32: =F32-J32 -> 768 | L32: =IFERROR(K32/E32, 0) -> 0.48
E34: =SUM(E6:E32) -> 240445 | F34: =SUM(F6:F32) -> 267581.72 | K34: =SUM(K6:K32) -> 92612.607 | L34: =K34/F34 -> 0.34610961
A37: COLEGIO WASHINGTON - LACROZE 1973 | E37: rto: 14 | F37: 46113 | I37: COMPRA
A39: CANTIDAD | B39: UNIDAD | C39: PRODUCTO | D39: PRECIO | E39: TOTAL | F39: TOTAL + IVA | I39: COSTO | J39: TOTAL | K39: DIFERENCIA
A40: 1.5 | B40: KG | C40: REMOLACHA | D40: 2500 | E40: =A40*D40 -> 3750 | F40: =E40*1.105 -> 4143.75 | I40: =14000/11 -> 1272.7273 | J40: =I40*A40 -> 1909.0909 | K40: =F40-J40 -> 2234.6591 | L40: =IFERROR(K40/E40, 0) -> 0.59590909
A41: 1 | B41: BOLSA | C41: ZANAHORIA | D41: 12000 | E41: =A41*D41 -> 12000 | F41: =E41*1.105 -> 13260 | I41: 7000 | J41: =I41*A41 -> 7000 | K41: =F41-J41 -> 6260 | L41: =IFERROR(K41/E41, 0) -> 0.52166667
A42: 1 | B42: KG | C42: MORRON ROJO | D42: 3200 | E42: =A42*D42 -> 3200 | F42: =E42*1.105 -> 3536 | I42: 1000 | J42: =I42*A42 -> 1000 | K42: =F42-J42 -> 2536 | L42: =IFERROR(K42/E42, 0) -> 0.7925
A43: 3 | B43: KG | C43: CEBOLLA MORADA | D43: 1600 | E43: =A43*D43 -> 4800 | F43: =E43*1.105 -> 5304 | I43: =12000/15 -> 800 | J43: =I43*A43 -> 2400 | K43: =F43-J43 -> 2904 | L43: =IFERROR(K43/E43, 0) -> 0.605
A44: 1.5 | B44: KG | C44: PUERRO | D44: 5000 | E44: =A44*D44 -> 7500 | F44: =E44*1.105 -> 8287.5 | I44: 2000 | J44: =I44*A44 -> 3000 | K44: =F44-J44 -> 5287.5 | L44: =IFERROR(K44/E44, 0) -> 0.705
A45: 0.5 | B45: ATADO | C45: CEBOLLA DE VERDEO | D45: 4500 | E45: =A45*D45 -> 2250 | F45: =E45*1.105 -> 2486.25 | I45: 1200 | J45: =I45*A45 -> 600 | K45: =F45-J45 -> 1886.25 | L45: =IFERROR(K45/E45, 0) -> 0.83833333
A46: 0.5 | B46: ATADO | C46: PEREJIL | D46: 3500 | E46: =A46*D46 -> 1750 | F46: =E46*1.105 -> 1933.75 | I46: 1000 | J46: =I46*A46 -> 500 | K46: =F46-J46 -> 1433.75 | L46: =IFERROR(K46/E46, 0) -> 0.81928571
A47: 5 | B47: KG | C47: TOMATE PERITA | D47: 2400 | E47: =A47*D47 -> 12000 | F47: =E47*1.105 -> 13260 | I47: =15000/15 -> 1000 | J47: =I47*A47 -> 5000 | K47: =F47-J47 -> 8260 | L47: =IFERROR(K47/E47, 0) -> 0.68833333
...

Sheet 02-04-2026 
A3: LA PIADINA | D3: rto: 32 | E3: 46114 | F3: **
A5: CANTIDAD | B5: UNIDAD | C5: PRODUCTO | D5: PRECIO | E5: TOTAL | I5: PRECIO | J5: TOTAL | K5: DIFERENCIA
A6: 1 | B6: CAJON | C6: RUCULA | D6: 13000 | E6: =A6*D6 -> 13000 | I6: 8000 | J6: =I6*A6 -> 8000 | K6: =E6-J6 -> 5000 | L6: =K6/E6 -> 0.38461538
A7: 3 | B7: ATADO | C7: ALBAHACA | D7: 1500 | E7: =A7*D7 -> 4500 | I7: 1500 | J7: =I7*A7 -> 4500 | K7: =E7-J7 -> 0 | L7: =K7/E7 -> 0
A8: 5 | B8: KG | C8: TOMATE | D8: 2200 | E8: =A8*D8 -> 11000 | I8: =14000/15 -> 933.33333 | J8: =I8*A8 -> 4666.6667 | K8: =E8-J8 -> 6333.3333 | L8: =K8/E8 -> 0.57575758
A9: 0.5 | B9: KG | C9: TOMATE CHERRY | D9: 3000 | E9: =A9*D9 -> 1500 | I9: 1000 | J9: =I9*A9 -> 500 | K9: =E9-J9 -> 1000 | L9: =K9/E9 -> 0.66666667
A10: 1 | B10: KG | C10: LECHUGA | D10: 3500 | E10: =A10*D10 -> 3500 | H10: S/C | I10: 0 | J10: =I10*A10 -> 0 | K10: =E10-J10 -> 3500 | L10: =K10/E10 -> 1
E12: =SUM(E6:E11) -> 33500 | K12: =SUM(K6:K10) -> 15833.333 | L12: =K12/E12 -> 0.47263682
A16: BRASOV | D16: rto: 27 | E16: 46114 | F16: **
A18: CANTIDAD | B18: UNIDAD | C18: PRODUCTO | D18: PRECIO | E18: TOTAL | I18: PRECIO | J18: TOTAL | K18: DIFERENCIA
A19: 4 | B19: CAJON | C19: LECHUGA FRANCESA | D19: 9000 | E19: =A19*D19 -> 36000 | I19: =18000/4 -> 4500 | J19: =I19*A19 -> 18000 | K19: =E19-J19 -> 18000 | L19: =K19/E19 -> 0.5
A20: 1 | B20: KG | C20: JENGIBRE | D20: 10000 | E20: =A20*D20 -> 10000 | I20: 8000 | J20: =I20*A20 -> 8000 | K20: =E20-J20 -> 2000 | L20: =K20/E20 -> 0.2
A21: 4 | B21: ATADO | C21: MENTA | D21: 3000 | E21: =A21*D21 -> 12000 | I21: 2000 | J21: =I21*A21 -> 8000 | K21: =E21-J21 -> 4000 | L21: =K21/E21 -> 0.33333333
A22: 3 | B22: KG | C22: LIMA | D22: 4000 | E22: =A22*D22 -> 12000 | I22: 3000 | J22: =I22*A22 -> 9000 | K22: =E22-J22 -> 3000 | L22: =K22/E22 -> 0.25
A23: 4 | B23: CAJON | C23: LIMON | D23: 28000 | E23: =A23*D23 -> 112000 | I23: 12000 | J23: =I23*A23 -> 48000 | K23: =E23-J23 -> 64000 | L23: =K23/E23 -> 0.57142857
A24: 3 | B24: CAJON | C24: NARANJA | D24: 26000 | E24: =A24*D24 -> 78000 | I24: 22000 | J24: =I24*A24 -> 66000 | K24: =E24-J24 -> 12000 | L24: =K24/E24 -> 0.15384615
A25: 2 | B25: ATADO | C25: PEREJIL | D25: 3500 | E25: =A25*D25 -> 7000 | I25: 1000 | J25: =I25*A25 -> 2000 | K25: =E25-J25 -> 5000 | L25: =K25/E25 -> 0.71428571
A26: 4 | B26: ATADO | C26: CEBOLLA DE VERDEO | D26: 4500 | E26: =A26*D26 -> 18000 | I26: 1200 | J26: =I26*A26 -> 4800 | K26: =E26-J26 -> 13200 | L26: =K26/E26 -> 0.73333333
A27: 4 | B27: UNIDAD | C27: MANGO | D27: 3000 | E27: =A27*D27 -> 12000 | I27: =20000/9 -> 2222.2222 | J27: =I27*A27 -> 8888.8889 | K27: =E27-J27 -> 3111.1111 | L27: =K27/E27 -> 0.25925926
A28: 2 | B28: ATADO | C28: PUERRO | D28: 4000 | E28: =A28*D28 -> 8000 | I28: 2000 | J28: =I28*A28 -> 4000 | K28: =E28-J28 -> 4000 | L28: =K28/E28 -> 0.5
A29: 1 | B29: CAJON | C29: TOMATE PERITA | D29: 20000 | E29: =A29*D29 -> 20000 | I29: 15000 | J29: =I29*A29 -> 15000 | K29: =E29-J29 -> 5000 | L29: =K29/E29 -> 0.25
A30: 2 | B30: KG | C30: PEPINO | D30: 1500 | E30: =A30*D30 -> 3000 | I30: 1500 | J30: =I30*A30 -> 3000 | K30: =E30-J30 -> 0 | L30: =K30/E30 -> 0
A31: 0.5 | B31: CAJA | C31: PALTA (50u) | D31: 85000 | E31: =A31*D31 -> 42500 | I31: 82000 | J31: =I31*A31 -> 41000 | K31: =E31-J31 -> 1500 | L31: =K31/E31 -> 0.035294118
E33: =SUM(E19:E31) -> 370500 | K33: =SUM(K19:K31) -> 134811.11 | L33: =K33/E33 -> 0.36386265
A36: COMO SIEMPRE LAGUNA | D36: rto: 43 | E36: 46114 | F36: **
A38: CANTIDAD | B38: UNIDAD | C38: PRODUCTO | D38: PRECIO | E38: TOTAL | I38: PRECIO | J38: TOTAL | K38: DIFERENCIA
A39: 1 | B39: ATADO | C39: APIO | D39: 2500 | E39: =A39*D39 -> 2500 | I39: 1000 | J39: =I39*A39 -> 1000 | K39: =E39-J39 -> 1500 | L39: =K39/E39 -> 0.6
A40: 1 | B40: ATADO | C40: PUERRO | D40: 5000 | E40: =A40*D40 -> 5000 | I40: 2000 | J40: =I40*A40 -> 2000 | K40: =E40-J40 -> 3000 | L40: =K40/E40 -> 0.6
A41: 2 | B41: KG | C41: CEBOLLA MORADA | D41: 1600 | E41: =A41*D41 -> 3200 | I41: 1000 | J41: =I41*A41 -> 2000 | K41: =E41-J41 -> 1200 | L41: =K41/E41 -> 0.375
A42: 8 | B42: KG | C42: TOMATE PERITA | D42: 2200 | E42: =A42*D42 -> 17600 | I42: 1000 | J42: =I42*A42 -> 8000 | K42: =E42-J42 -> 9600 | L42: =K42/E42 -> 0.54545455
A43: 1 | B43: ATADO | C43: CIBOULETTE | D43: 3000 | E43: =A43*D43 -> 3000 | I43: 2000 | J43: =I43*A43 -> 2000 | K43: =E43-J43 -> 1000 | L43: =K43/E43 -> 0.33333333
A44: 2 | B44: ATADO | C44: ALBAHACA | D44: 1500 | E44: =A44*D44 -> 3000 | I44: 1500 | J44: =I44*A44 -> 3000 | K44: =E44-J44 -> 0 | L44: =K44/E44 -> 0
A45: 3 | B45: UNIDAD | C45: MANGO | D45: 3000 | E45: =A45*D45 -> 9000 | I45: 2222 | J45: =I45*A45 -> 6666 | K45: =E45-J45 -> 2334 | L45: =K45/E45 -> 0.25933333
A46: 2 | B46: ATADO | C46: MENTA | D46: 3000 | E46: =A46*D46 -> 6000 | I46: 2000 | J46: =I46*A46 -> 4000 | K46: =E46-J46 -> 2000 | L46: =K46/E46 -> 0.33333333
A47: 6 | B47: KG | C47: LIMON | D47: 2400 | E47: =A47*D47 -> 14400 | I47: =12000/14 -> 857.14286 | J47: =I47*A47 -> 5142.8571 | K47: =E47-J47 -> 9257.1429 | L47: =K47/E47 -> 0.64285714
A48: 6 | B48: KG | C48: NARANJA | D48: 1800 | E48: =A48*D48 -> 10800 | I48: =22000/15 -> 1466.6667 | J48: =I48*A48 -> 8800 | K48: =E48-J48 -> 2000 | L48: =K48/E48 -> 0.18518519
A49: 2 | B49: UNIDAD | C49: COLIFLOR | D49: 2800 | E49: =A49*D49 -> 5600 | I49: =18000/10 -> 1800 | J49: =I49*A49 -> 3600 | K49: =E49-J49 -> 2000 | L49: =K49/E49 -> 0.35714286
A50: 1 | B50: CAJON | C50: LECHUGA MORADA | D50: 11000 | E50: =A50*D50 -> 11000 | I50: 6000 | J50: =I50*A50 -> 6000 | K50: =E50-J50 -> 5000 | L50: =K50/E50 -> 0.45454545
A51: 0.5 | B51: CAJON | C51: RUCULA | D51: 12000 | E51: =A51*D51 -> 6000 | I51: 8000 | J51: =I51*A51 -> 4000 | K51: =E51-J51 -> 2000 | L51: =K51/E51 -> 0.33333333
E53: =SUM(E39:E51) -> 97100 | K53: =SUM(K39:K52) -> 40891.143 | L53: =K53/E53 -> 0.42112403
...

Sheet 06-04-2026 
A3: COLEGIO SJCB - VIRREY DEL PINO 3299 | E3: rto: 16 | F3: 46118 | I3: COMPRA
A5: CANTIDAD | B5: UNIDAD | C5: PRODUCTO | D5: PRECIO | E5: TOTAL | F5: TOTAL + IVA | I5: COSTO | J5: TOTAL | K5: DIFERENCIA
A6: 1 | B6: ATADO | C6: ALBAHACA | D6: 1500 | E6: =A6*D6 -> 1500 | F6: =E6*1.21 -> 1815 | I6: 1500 | J6: =I6*A6 -> 1500 | K6: =F6-J6 -> 315 | L6: =IFERROR(K6/E6, 0) -> 0.21
A7: 1 | B7: KG | C7: FRUTILLA | D7: 11000 | E7: =A7*D7 -> 11000 | F7: =E7*1.21 -> 13310 | I7: =38000/4 -> 9500 | J7: =I7*A7 -> 9500 | K7: =F7-J7 -> 3810 | L7: =IFERROR(K7/E7, 0) -> 0.34636364
A8: 1 | B8: ATADO | C8: CILANTRO | D8: 3000 | E8: =A8*D8 -> 3000 | F8: =E8*1.21 -> 3630 | I8: 500 | J8: =I8*A8 -> 500 | K8: =F8-J8 -> 3130 | L8: =IFERROR(K8/E8, 0) -> 1.0433333
A9: 1.5 | B9: KG | C9: LECHUGA CRIOLLA | D9: 3200 | E9: =A9*D9 -> 4800 | F9: =E9*1.21 -> 5808 | I9: =10000/4 -> 2500 | J9: =I9*A9 -> 3750 | K9: =F9-J9 -> 2058 | L9: =IFERROR(K9/E9, 0) -> 0.42875
A10: 5 | B10: ATADO | C10: RUCULA | D10: 600 | E10: =A10*D10 -> 3000 | F10: =E10*1.21 -> 3630 | I10: =5000/24 -> 208.33333 | J10: =I10*A10 -> 1041.6667 | K10: =F10-J10 -> 2588.3333 | L10: =IFERROR(K10/E10, 0) -> 0.86277778
A11: 5 | B11: KG | C11: BANANA | D11: 3000 | E11: =A11*D11 -> 15000 | F11: =E11*1.21 -> 18150 | I11: =32000/18 -> 1777.7778 | J11: =I11*A11 -> 8888.8889 | K11: =F11-J11 -> 9261.1111 | L11: =IFERROR(K11/E11, 0) -> 0.61740741
E13: =SUM(E6:E11) -> 38300 | F13: =SUM(F6:F11) -> 46343 | K13: =SUM(K6:K11) -> 21162.444 | L13: =K13/F13 -> 0.45664813
A18: COLEGIO ST. MATTHEWS - MOLDES 1469, BELGRANO | E18: rto: 16 | F18: 46118 | I18: COMPRA
A20: CANTIDAD | B20: UNIDAD | C20: PRODUCTO | D20: PRECIO | E20: TOTAL | F20: TOTAL + IVA | I20: COSTO | J20: TOTAL | K20: DIFERENCIA
A21: 3 | B21: BOLSA | C21: PAPA BLANCA | D21: 23000 | E21: =A21*D21 -> 69000 | F21: =E21*1.105 -> 76245 | I21: 18000 | J21: =I21*A21 -> 54000 | K21: =F21-J21 -> 22245 | L21: =IFERROR(K21/E21, 0) -> 0.3223913
A22: 1 | B22: BOLSA | C22: BATATA | D22: 16000 | E22: =A22*D22 -> 16000 | F22: =E22*1.105 -> 17680 | I22: 12000 | J22: =I22*A22 -> 12000 | K22: =F22-J22 -> 5680 | L22: =IFERROR(K22/E22, 0) -> 0.355
A23: 1 | B23: BOLSA | C23: ZANAHORIA | D23: 12000 | E23: =A23*D23 -> 12000 | F23: =E23*1.105 -> 13260 | I23: 7000 | J23: =I23*A23 -> 7000 | K23: =F23-J23 -> 6260 | L23: =IFERROR(K23/E23, 0) -> 0.52166667
A24: 8 | B24: KG | C24: TOMATE PERITA | D24: 2400 | E24: =A24*D24 -> 19200 | F24: =E24*1.105 -> 21216 | I24: 1666 | J24: =I24*A24 -> 13328 | K24: =F24-J24 -> 7888 | L24: =IFERROR(K24/E24, 0) -> 0.41083333
A25: 3 | B25: KG | C25: CEBOLLA MORADA | D25: 1600 | E25: =A25*D25 -> 4800 | F25: =E25*1.105 -> 5304 | I25: 1000 | J25: =I25*A25 -> 3000 | K25: =F25-J25 -> 2304 | L25: =IFERROR(K25/E25, 0) -> 0.48
A26: 2 | B26: KG | C26: CEBOLLA | D26: 800 | E26: =A26*D26 -> 1600 | F26: =E26*1.105 -> 1768 | I26: =10000/15 -> 666.66667 | J26: =I26*A26 -> 1333.3333 | K26: =F26-J26 -> 434.66667 | L26: =IFERROR(K26/E26, 0) -> 0.27166667
A27: 2 | B27: KG | C27: CHAUCHA | D27: 4000 | E27: =A27*D27 -> 8000 | F27: =E27*1.105 -> 8840 | I27: =18000/8 -> 2250 | J27: =I27*A27 -> 4500 | K27: =F27-J27 -> 4340 | L27: =IFERROR(K27/E27, 0) -> 0.5425
A28: 2 | B28: KG | C28: ZUCCINI | D28: 1400 | E28: =A28*D28 -> 2800 | F28: =E28*1.105 -> 3094 | I28: 1000 | J28: =I28*A28 -> 2000 | K28: =F28-J28 -> 1094 | L28: =IFERROR(K28/E28, 0) -> 0.39071429
A29: 1 | B29: KG | C29: REMOLACHA | D29: 2500 | E29: =A29*D29 -> 2500 | F29: =E29*1.105 -> 2762.5 | I29: 1400 | J29: =I29*A29 -> 1400 | K29: =F29-J29 -> 1362.5 | L29: =IFERROR(K29/E29, 0) -> 0.545
A30: 3 | B30: UNIDAD | C30: BROCOLI | D30: 2600 | E30: =A30*D30 -> 7800 | F30: =E30*1.105 -> 8619 | I30: =15000/8 -> 1875 | J30: =I30*A30 -> 5625 | K30: =F30-J30 -> 2994 | L30: =IFERROR(K30/E30, 0) -> 0.38384615
A31: 2 | B31: KG | C31: ZAPALLITO REDONDO | D31: 1400 | E31: =A31*D31 -> 2800 | F31: =E31*1.105 -> 3094 | I31: =16000/15 -> 1066.6667 | J31: =I31*A31 -> 2133.3333 | K31: =F31-J31 -> 960.66667 | L31: =IFERROR(K31/E31, 0) -> 0.34309524
A32: 2 | B32: KG | C32: MORRON ROJO | D32: 3200 | E32: =A32*D32 -> 6400 | F32: =E32*1.105 -> 7072 | I32: =15000/7 -> 2142.8571 | J32: =I32*A32 -> 4285.7143 | K32: =F32-J32 -> 2786.2857 | L32: =IFERROR(K32/E32, 0) -> 0.43535714
A33: 1 | B33: KG | C33: MORRON VERDE | D33: 2400 | E33: =A33*D33 -> 2400 | F33: =E33*1.105 -> 2652 | I33: =15000/7 -> 2142.8571 | J33: =I33*A33 -> 2142.8571 | K33: =F33-J33 -> 509.14286 | L33: =IFERROR(K33/E33, 0) -> 0.21214286
A34: 1 | B34: KG | C34: REPOLLO COLORADO | D34: 1800 | E34: =A34*D34 -> 1800 | F34: =E34*1.105 -> 1989 | I34: 1000 | J34: =I34*A34 -> 1000 | K34: =F34-J34 -> 989 | L34: =IFERROR(K34/E34, 0) -> 0.54944444
A35: 1.8 | B35: KG | C35: REPOLLO BLANCO | D35: 1800 | E35: =A35*D35 -> 3240 | F35: =E35*1.105 -> 3580.2 | I35: 1000 | J35: =I35*A35 -> 1800 | K35: =F35-J35 -> 1780.2 | L35: =IFERROR(K35/E35, 0) -> 0.54944444
A36: 1 | B36: KG | C36: PEPINO | D36: 1500 | E36: =A36*D36 -> 1500 | F36: =E36*1.105 -> 1657.5 | I36: 1500 | J36: =I36*A36 -> 1500 | K36: =F36-J36 -> 157.5 | L36: =IFERROR(K36/E36, 0) -> 0.105
A37: 20 | B37: ATADO | C37: RUCULA | D37: 600 | E37: =A37*D37 -> 12000 | F37: =E37*1.105 -> 13260 | I37: 208 | J37: =I37*A37 -> 4160 | K37: =F37-J37 -> 9100 | L37: =IFERROR(K37/E37, 0) -> 0.75833333
A38: 2 | B38: KG | C38: LECHUGA CRIOLLA | D38: 3200 | E38: =A38*D38 -> 6400 | F38: =E38*1.105 -> 7072 | I38: =10000/4 -> 2500 | J38: =I38*A38 -> 5000 | K38: =F38-J38 -> 2072 | L38: =IFERROR(K38/E38, 0) -> 0.32375
A39: 10 | B39: ATADO | C39: ESPINACA | D39: 1700 | E39: =A39*D39 -> 17000 | F39: =E39*1.105 -> 18785 | I39: 1200 | J39: =I39*A39 -> 12000 | K39: =F39-J39 -> 6785 | L39: =IFERROR(K39/E39, 0) -> 0.39911765
A40: 1 | B40: ATADO | C40: CILANTRO | D40: 3000 | E40: =A40*D40 -> 3000 | F40: =E40*1.105 -> 3315 | I40: 500 | J40: =I40*A40 -> 500 | K40: =F40-J40 -> 2815 | L40: =IFERROR(K40/E40, 0) -> 0.93833333
A41: 1 | B41: ATADO | C41: CIBOULETTE | D41: 3000 | E41: =A41*D41 -> 3000 | F41: =E41*1.105 -> 3315 | I41: 2000 | J41: =I41*A41 -> 2000 | K41: =F41-J41 -> 1315 | L41: =IFERROR(K41/E41, 0) -> 0.43833333
A42: 2 | B42: ATADO | C42: ALBAHACA | D42: 1500 | E42: =A42*D42 -> 3000 | F42: =E42*1.105 -> 3315 | I42: 1500 | J42: =I42*A42 -> 3000 | K42: =F42-J42 -> 315 | L42: =IFERROR(K42/E42, 0) -> 0.105
A43: 3 | B43: UNIDAD | C43: PALTA | D43: 1600 | E43: =A43*D43 -> 4800 | F43: =E43*1.105 -> 5304 | I43: 1078 | J43: =I43*A43 -> 3234 | K43: =F43-J43 -> 2070 | L43: =IFERROR(K43/E43, 0) -> 0.43125
A44: 0.8 | B44: KG | C44: TOMATE CHERRY | D44: 3000 | E44: =A44*D44 -> 2400 | F44: =E44*1.105 -> 2652 | I44: =13000/7 -> 1857.1429 | J44: =I44*A44 -> 1485.7143 | K44: =F44-J44 -> 1166.2857 | L44: =IFERROR(K44/E44, 0) -> 0.48595238
A45: 0.5 | B45: ATADO | C45: PEREJIL | D45: 3500 | E45: =A45*D45 -> 1750 | F45: =E45*1.105 -> 1933.75 | I45: 1500 | J45: =I45*A45 -> 750 | K45: =F45-J45 -> 1183.75 | L45: =IFERROR(K45/E45, 0) -> 0.67642857
A46: 0.5 | B46: ATADO | C46: CEBOLLA DE VERDEO | D46: 4500 | E46: =A46*D46 -> 2250 | F46: =E46*1.105 -> 2486.25 | I46: 1200 | J46: =I46*A46 -> 600 | K46: =F46-J46 -> 1886.25 | L46: =IFERROR(K46/E46, 0) -> 0.83833333
A47: 1 | B47: ATADO | C47: APIO | D47: 2500 | E47: =A47*D47 -> 2500 | F47: =E47*1.105 -> 2762.5 | I47: 1000 | J47: =I47*A47 -> 1000 | K47: =F47-J47 -> 1762.5 | L47: =IFERROR(K47/E47, 0) -> 0.705
A48: 3 | B48: CAJON | C48: NARANJA | D48: 26000 | E48: =A48*D48 -> 78000 | F48: =E48*1.105 -> 86190 | I48: 22000 | J48: =I48*A48 -> 66000 | K48: =F48-J48 -> 20190 | L48: =IFERROR(K48/E48, 0) -> 0.25884615
A49: 7 | B49: KG | C49: POMELO | D49: 3200 | E49: =A49*D49 -> 22400 | F49: =E49*1.105 -> 24752 | I49: =32000/15 -> 2133.3333 | J49: =I49*A49 -> 14933.333 | K49: =F49-J49 -> 9818.6667 | L49: =IFERROR(K49/E49, 0) -> 0.43833333
...

Sheet 07-04-2026 
A3: COLEGIO WASHINGTON - LACROZE 1973 | E3: rto: 15 | F3: 46119 | I3: COMPRA
A5: CANTIDAD | B5: UNIDAD | C5: PRODUCTO | D5: PRECIO | E5: TOTAL | F5: TOTAL + IVA | I5: COSTO | J5: TOTAL | K5: DIFERENCIA
A6: 1 | B6: BOLSA | C6: ANCO | D6: 13000 | E6: =A6*D6 -> 13000 | F6: =E6*1.105 -> 14365 | I6: 7000 | J6: =I6*A6 -> 7000 | K6: =F6-J6 -> 7365 | L6: =IFERROR(K6/E6, 0) -> 0.56653846
A7: 2 | B7: KG | C7: ANCO | D7: 1000 | E7: =A7*D7 -> 2000 | F7: =E7*1.105 -> 2210 | I7: =7000/15 -> 466.66667 | J7: =I7*A7 -> 933.33333 | K7: =F7-J7 -> 1276.6667 | L7: =IFERROR(K7/E7, 0) -> 0.63833333
A8: 1 | B8: BOLSA | C8: BATATA | D8: 16000 | E8: =A8*D8 -> 16000 | F8: =E8*1.105 -> 17680 | I8: 12000 | J8: =I8*A8 -> 12000 | K8: =F8-J8 -> 5680 | L8: =IFERROR(K8/E8, 0) -> 0.355
A9: 5 | B9: BOLSA | C9: PAPA BLANCA | D9: 23000 | E9: =A9*D9 -> 115000 | F9: =E9*1.105 -> 127075 | I9: 17500 | J9: =I9*A9 -> 87500 | K9: =F9-J9 -> 39575 | L9: =IFERROR(K9/E9, 0) -> 0.34413043
A10: 1.5 | B10: BOLSA | C10: ZANAHORIA | D10: 12000 | E10: =A10*D10 -> 18000 | F10: =E10*1.105 -> 19890 | I10: 7000 | J10: =I10*A10 -> 10500 | K10: =F10-J10 -> 9390 | L10: =IFERROR(K10/E10, 0) -> 0.52166667
A11: 3 | B11: UNIDAD | C11: COLIFLOR | D11: 2800 | E11: =A11*D11 -> 8400 | F11: =E11*1.105 -> 9282 | I11: =16000/10 -> 1600 | J11: =I11*A11 -> 4800 | K11: =F11-J11 -> 4482 | L11: =IFERROR(K11/E11, 0) -> 0.53357143
A12: 3.5 | B12: KG | C12: CEBOLLA MORADA | D12: 1600 | E12: =A12*D12 -> 5600 | F12: =E12*1.105 -> 6188 | I12: 1000 | J12: =I12*A12 -> 3500 | K12: =F12-J12 -> 2688 | L12: =IFERROR(K12/E12, 0) -> 0.48
A13: 1 | B13: KG | C13: CEBOLLA | D13: 800 | E13: =A13*D13 -> 800 | F13: =E13*1.105 -> 884 | I13: =10000/15 -> 666.66667 | J13: =I13*A13 -> 666.66667 | K13: =F13-J13 -> 217.33333 | L13: =IFERROR(K13/E13, 0) -> 0.27166667
A14: 2 | B14: UNIDAD | C14: AJO | D14: 900 | E14: =A14*D14 -> 1800 | F14: =E14*1.105 -> 1989 | I14: 460 | J14: =I14*A14 -> 920 | K14: =F14-J14 -> 1069 | L14: =IFERROR(K14/E14, 0) -> 0.59388889
A15: 3.75 | B15: KG | C15: REPOLLO BLANCO | D15: 1800 | E15: =A15*D15 -> 6750 | F15: =E15*1.105 -> 7458.75 | I15: 1000 | J15: =I15*A15 -> 3750 | K15: =F15-J15 -> 3708.75 | L15: =IFERROR(K15/E15, 0) -> 0.54944444
A16: 3 | B16: KG | C16: REPOLLO COLORADO | D16: 1800 | E16: =A16*D16 -> 5400 | F16: =E16*1.105 -> 5967 | I16: 1000 | J16: =I16*A16 -> 3000 | K16: =F16-J16 -> 2967 | L16: =IFERROR(K16/E16, 0) -> 0.54944444
A17: 1 | B17: KG | C17: ZUCCINI | D17: 1400 | E17: =A17*D17 -> 1400 | F17: =E17*1.105 -> 1547 | I17: =12000/14 -> 857.14286 | J17: =I17*A17 -> 857.14286 | K17: =F17-J17 -> 689.85714 | L17: =IFERROR(K17/E17, 0) -> 0.4927551
A18: 0.5 | B18: KG | C18: BERENJENA | D18: 1500 | E18: =A18*D18 -> 750 | F18: =E18*1.105 -> 828.75 | I18: =10000/8 -> 1250 | J18: =I18*A18 -> 625 | K18: =F18-J18 -> 203.75 | L18: =IFERROR(K18/E18, 0) -> 0.27166667
A19: 0.5 | B19: KG | C19: APIO | D19: 2500 | E19: =A19*D19 -> 1250 | F19: =E19*1.105 -> 1381.25 | I19: =9000/8 -> 1125 | J19: =I19*A19 -> 562.5 | K19: =F19-J19 -> 818.75 | L19: =IFERROR(K19/E19, 0) -> 0.655
A20: 1 | B20: ATADO | C20: PEREJIL | D20: 3500 | E20: =A20*D20 -> 3500 | F20: =E20*1.105 -> 3867.5 | I20: 1500 | J20: =I20*A20 -> 1500 | K20: =F20-J20 -> 2367.5 | L20: =IFERROR(K20/E20, 0) -> 0.67642857
A21: 1 | B21: ATADO | C21: CIBOULETTE | D21: 3000 | E21: =A21*D21 -> 3000 | F21: =E21*1.105 -> 3315 | I21: 2000 | J21: =I21*A21 -> 2000 | K21: =F21-J21 -> 1315 | L21: =IFERROR(K21/E21, 0) -> 0.43833333
A22: 1 | B22: ATADO | C22: CILANTRO | D22: 3000 | E22: =A22*D22 -> 3000 | F22: =E22*1.105 -> 3315 | I22: 2000 | J22: =I22*A22 -> 2000 | K22: =F22-J22 -> 1315 | L22: =IFERROR(K22/E22, 0) -> 0.43833333
A23: 0.5 | B23: KG | C23: CEBOLLA DE VERDEO | D23: 4500 | E23: =A23*D23 -> 2250 | F23: =E23*1.105 -> 2486.25 | I23: 2000 | J23: =I23*A23 -> 1000 | K23: =F23-J23 -> 1486.25 | L23: =IFERROR(K23/E23, 0) -> 0.66055556
A24: 2 | B24: ATADO | C24: ALBAHACA | D24: 1500 | E24: =A24*D24 -> 3000 | F24: =E24*1.105 -> 3315 | I24: 1000 | J24: =I24*A24 -> 2000 | K24: =F24-J24 -> 1315 | L24: =IFERROR(K24/E24, 0) -> 0.43833333
A25: 1 | B25: KG | C25: REMOLACHA | D25: 2500 | E25: =A25*D25 -> 2500 | F25: =E25*1.105 -> 2762.5 | I25: =14000/9 -> 1555.5556 | J25: =I25*A25 -> 1555.5556 | K25: =F25-J25 -> 1206.9444 | L25: =IFERROR(K25/E25, 0) -> 0.48277778
A26: 1 | B26: UNIDAD | C26: BROCOLI | D26: 2600 | E26: =A26*D26 -> 2600 | F26: =E26*1.105 -> 2873 | I26: =15000/8 -> 1875 | J26: =I26*A26 -> 1875 | K26: =F26-J26 -> 998 | L26: =IFERROR(K26/E26, 0) -> 0.38384615
A27: 0.7 | B27: KG | C27: TOMATE CHERRY | D27: 3000 | E27: =A27*D27 -> 2100 | F27: =E27*1.105 -> 2320.5 | I27: =7000/6 -> 1166.6667 | J27: =I27*A27 -> 816.66667 | K27: =F27-J27 -> 1503.8333 | L27: =IFERROR(K27/E27, 0) -> 0.71611111
A28: 16 | B28: KG | C28: TOMATE PERITA | D28: 2400 | E28: =A28*D28 -> 38400 | F28: =E28*1.105 -> 42432 | I28: =25000/15 -> 1666.6667 | J28: =I28*A28 -> 26666.667 | K28: =F28-J28 -> 15765.333 | L28: =IFERROR(K28/E28, 0) -> 0.41055556
A29: 4 | B29: KG | C29: LECHUGA CRIOLLA | D29: 4000 | E29: =A29*D29 -> 16000 | F29: =E29*1.105 -> 17680 | I29: =18000/4 -> 4500 | J29: =I29*A29 -> 18000 | K29: =F29-J29 -> -320 | L29: =IFERROR(K29/E29, 0) -> -0.02
A30: 25 | B30: ATADO | C30: RUCULA | D30: 600 | E30: =A30*D30 -> 15000 | F30: =E30*1.105 -> 16575 | I30: =8000/24 -> 333.33333 | J30: =I30*A30 -> 8333.3333 | K30: =F30-J30 -> 8241.6667 | L30: =IFERROR(K30/E30, 0) -> 0.54944444
A31: 9 | B31: ATADO | C31: ESPINACA | D31: 1700 | E31: =A31*D31 -> 15300 | F31: =E31*1.105 -> 16906.5 | I31: =13000/12 -> 1083.3333 | J31: =I31*A31 -> 9750 | K31: =F31-J31 -> 7156.5 | L31: =IFERROR(K31/E31, 0) -> 0.4677451
A32: 0.1 | B32: KG | C32: LIMON | D32: 2400 | E32: =A32*D32 -> 240 | F32: =E32*1.105 -> 265.2 | I32: =20000/15 -> 1333.3333 | J32: =I32*A32 -> 133.33333 | K32: =F32-J32 -> 131.86667 | L32: =IFERROR(K32/E32, 0) -> 0.54944444
A33: 5 | B33: KG | C33: POMELO | D33: 3200 | E33: =A33*D33 -> 16000 | F33: =E33*1.105 -> 17680 | I33: =32000/15 -> 2133.3333 | J33: =I33*A33 -> 10666.667 | K33: =F33-J33 -> 7013.3333 | L33: =IFERROR(K33/E33, 0) -> 0.43833333
A34: 5 | B34: KG | C34: ZAPALLITO REDONDO | D34: 1400 | E34: =A34*D34 -> 7000 | F34: =E34*1.105 -> 7735 | I34: =15000/14 -> 1071.4286 | J34: =I34*A34 -> 5357.1429 | K34: =F34-J34 -> 2377.8571 | L34: =IFERROR(K34/E34, 0) -> 0.33969388
A35: 2 | B35: CAJON | C35: NARANJA | D35: 26000 | E35: =A35*D35 -> 52000 | F35: =E35*1.105 -> 57460 | I35: 25000 | J35: =I35*A35 -> 50000 | K35: =F35-J35 -> 7460 | L35: =IFERROR(K35/E35, 0) -> 0.14346154
A36: 1 | B36: CAJON | C36: MANZANA ROJA | D36: 60000 | E36: =A36*D36 -> 60000 | F36: =E36*1.105 -> 66300 | I36: 50000 | J36: =I36*A36 -> 50000 | K36: =F36-J36 -> 16300 | L36: =IFERROR(K36/E36, 0) -> 0.27166667
A37: 4 | B37: KG | C37: MANZANA VERDE | D37: 4500 | E37: =A37*D37 -> 18000 | F37: =E37*1.105 -> 19890 | I37: =65000/17 -> 3823.5294 | J37: =I37*A37 -> 15294.118 | K37: =F37-J37 -> 4595.8824 | L37: =IFERROR(K37/E37, 0) -> 0.2553268
A38: 5 | B38: KG | C38: CHAUCHA | D38: 4000 | E38: =A38*D38 -> 20000 | F38: =E38*1.105 -> 22100 | I38: =18000/8 -> 2250 | J38: =I38*A38 -> 11250 | K38: =F38-J38 -> 10850 | L38: =IFERROR(K38/E38, 0) -> 0.5425
A39: 1.8 | B39: KG | C39: CHAUCHA PLANA | D39: 4000 | E39: =A39*D39 -> 7200 | F39: =E39*1.105 -> 7956 | I39: 2250 | J39: =I39*A39 -> 4050 | K39: =F39-J39 -> 3906 | L39: =IFERROR(K39/E39, 0) -> 0.5425
A40: 4 | B40: KG | C40: MORRON ROJO | D40: 3200 | E40: =A40*D40 -> 12800 | F40: =E40*1.105 -> 14144 | I40: =20000/7 -> 2857.1429 | J40: =I40*A40 -> 11428.571 | K40: =F40-J40 -> 2715.4286 | L40: =IFERROR(K40/E40, 0) -> 0.21214286
A41: 2 | B41: KG | C41: MORRON AMARILLO | D41: 2800 | E41: =A41*D41 -> 5600 | F41: =E41*1.105 -> 6188 | I41: =15000/7 -> 2142.8571 | J41: =I41*A41 -> 4285.7143 | K41: =F41-J41 -> 1902.2857 | L41: =IFERROR(K41/E41, 0) -> 0.33969388
A42: 2 | B42: KG | C42: MORRON VERDE | D42: 2400 | E42: =A42*D42 -> 4800 | F42: =E42*1.105 -> 5304 | I42: =12000/7 -> 1714.2857 | J42: =I42*A42 -> 3428.5714 | K42: =F42-J42 -> 1875.4286 | L42: =IFERROR(K42/E42, 0) -> 0.39071429
A43: 0.5 | B43: CAJON | C43: HUEVO N1 | D43: 54000 | E43: =A43*D43 -> 27000 | F43: =E43*1.21 -> 32670 | I43: 50000 | J43: =I43*A43 -> 25000 | K43: =F43-J43 -> 7670 | L43: =IFERROR(K43/E43, 0) -> 0.28407407
...

Sheet 08-04-2026 
A3: COLEGIO SAN MARCOS | SAN ISIDRO | E3: rto: 13 | F3: 46120 | I3: COMPRA
A5: CANTIDAD | B5: UNIDAD | C5: PRODUCTO | D5: PRECIO | E5: TOTAL | F5: TOTAL + IVA | I5: COSTO | J5: TOTAL | K5: DIFERENCIA
A6: 1 | B6: CAJON | C6: TOMATE PERITA | D6: 36000 | E6: =A6*D6 -> 36000 | F6: =E6*1.105 -> 39780 | I6: 22000 | J6: =I6*A6 -> 22000 | K6: =F6-J6 -> 17780 | L6: =IFERROR(K6/E6, 0) -> 0.49388889
A7: 1 | B7: CAJON | C7: LECHUGA CRIOLLA | D7: 20000 | E7: =A7*D7 -> 20000 | F7: =E7*1.105 -> 22100 | I7: 17000 | J7: =I7*A7 -> 17000 | K7: =F7-J7 -> 5100 | L7: =IFERROR(K7/E7, 0) -> 0.255
A8: 1 | B8: CAJON | C8: RUCULA | D8: 13000 | E8: =A8*D8 -> 13000 | F8: =E8*1.105 -> 14365 | I8: 10000 | J8: =I8*A8 -> 10000 | K8: =F8-J8 -> 4365 | L8: =IFERROR(K8/E8, 0) -> 0.33576923
A9: 3 | B9: BOLSA | C9: PAPA BLANCA | D9: 25000 | E9: =A9*D9 -> 75000 | F9: =E9*1.105 -> 82875 | I9: 20000 | J9: =I9*A9 -> 60000 | K9: =F9-J9 -> 22875 | L9: =IFERROR(K9/E9, 0) -> 0.305
A10: 4.2 | B10: KG | C10: REPOLLO BLANCO | D10: 1800 | E10: =A10*D10 -> 7560 | F10: =E10*1.105 -> 8353.8 | I10: 1000 | J10: =I10*A10 -> 4200 | K10: =F10-J10 -> 4153.8 | L10: =IFERROR(K10/E10, 0) -> 0.54944444
A11: 3.45 | B11: KG | C11: REPOLLO COLORADO | D11: 1800 | E11: =A11*D11 -> 6210 | F11: =E11*1.105 -> 6862.05 | I11: 1000 | J11: =I11*A11 -> 3450 | K11: =F11-J11 -> 3412.05 | L11: =IFERROR(K11/E11, 0) -> 0.54944444
A12: 2 | B12: KG | C12: ZAPALLITO REDONDO | D12: 1400 | E12: =A12*D12 -> 2800 | F12: =E12*1.105 -> 3094 | I12: =15000/14 -> 1071.4286 | J12: =I12*A12 -> 2142.8571 | K12: =F12-J12 -> 951.14286 | L12: =IFERROR(K12/E12, 0) -> 0.33969388
A13: 3 | B13: KG | C13: MORRON ROJO | D13: 3200 | E13: =A13*D13 -> 9600 | F13: =E13*1.105 -> 10608 | I13: =14000/7 -> 2000 | J13: =I13*A13 -> 6000 | K13: =F13-J13 -> 4608 | L13: =IFERROR(K13/E13, 0) -> 0.48
A14: 2 | B14: KG | C14: MORRON VERDE | D14: 2400 | E14: =A14*D14 -> 4800 | F14: =E14*1.105 -> 5304 | I14: =13000/7 -> 1857.1429 | J14: =I14*A14 -> 3714.2857 | K14: =F14-J14 -> 1589.7143 | L14: =IFERROR(K14/E14, 0) -> 0.33119048
A15: 2 | B15: KG | C15: MORRON AMARILLO | D15: 2800 | E15: =A15*D15 -> 5600 | F15: =E15*1.105 -> 6188 | I15: =15000/7 -> 2142.8571 | J15: =I15*A15 -> 4285.7143 | K15: =F15-J15 -> 1902.2857 | L15: =IFERROR(K15/E15, 0) -> 0.33969388
A16: 1 | B16: KG | C16: BERENJENA | D16: 2000 | E16: =A16*D16 -> 2000 | F16: =E16*1.105 -> 2210 | I16: =10000/7 -> 1428.5714 | J16: =I16*A16 -> 1428.5714 | K16: =F16-J16 -> 781.42857 | L16: =IFERROR(K16/E16, 0) -> 0.39071429
A17: 1 | B17: ATADO | C17: CEBOLLA DE VERDEO | D17: 4500 | E17: =A17*D17 -> 4500 | F17: =E17*1.105 -> 4972.5 | I17: 2000 | J17: =I17*A17 -> 2000 | K17: =F17-J17 -> 2972.5 | L17: =IFERROR(K17/E17, 0) -> 0.66055556
A18: 3 | B18: UNIDAD | C18: PALTA | D18: 1600 | E18: =A18*D18 -> 4800 | F18: =E18*1.105 -> 5304 | I18: =85000/70 -> 1214.2857 | J18: =I18*A18 -> 3642.8571 | K18: =F18-J18 -> 1661.1429 | L18: =IFERROR(K18/E18, 0) -> 0.34607143
A19: 1 | B19: ATADO | C19: CILANTRO | D19: 3000 | E19: =A19*D19 -> 3000 | F19: =E19*1.105 -> 3315 | I19: 2000 | J19: =I19*A19 -> 2000 | K19: =F19-J19 -> 1315 | L19: =IFERROR(K19/E19, 0) -> 0.43833333
A20: 2 | B20: ATADO | C20: PEREJIL | D20: 3500 | E20: =A20*D20 -> 7000 | F20: =E20*1.105 -> 7735 | I20: 1500 | J20: =I20*A20 -> 3000 | K20: =F20-J20 -> 4735 | L20: =IFERROR(K20/E20, 0) -> 0.67642857
A21: 2 | B21: UNIDAD | C21: AJO | D21: 900 | E21: =A21*D21 -> 1800 | F21: =E21*1.105 -> 1989 | I21: 460 | J21: =I21*A21 -> 920 | K21: =F21-J21 -> 1069 | L21: =IFERROR(K21/E21, 0) -> 0.59388889
A22: 0.5 | B22: KG | C22: PEPINO | D22: 1500 | E22: =A22*D22 -> 750 | F22: =E22*1.105 -> 828.75 | I22: =8000/14 -> 571.42857 | J22: =I22*A22 -> 285.71429 | K22: =F22-J22 -> 543.03571 | L22: =IFERROR(K22/E22, 0) -> 0.72404762
A23: 2 | B23: KG | C23: ZUCCINI | D23: 1400 | E23: =A23*D23 -> 2800 | F23: =E23*1.105 -> 3094 | I23: =12000/14 -> 857.14286 | J23: =I23*A23 -> 1714.2857 | K23: =F23-J23 -> 1379.7143 | L23: =IFERROR(K23/E23, 0) -> 0.4927551
A24: 6 | B24: KG | C24: CEBOLLA | D24: 1200 | E24: =A24*D24 -> 7200 | F24: =E24*1.105 -> 7956 | I24: =12000/15 -> 800 | J24: =I24*A24 -> 4800 | K24: =F24-J24 -> 3156 | L24: =IFERROR(K24/E24, 0) -> 0.43833333
A25: 3 | B25: KG | C25: CEBOLLA MORADA | D25: 1600 | E25: =A25*D25 -> 4800 | F25: =E25*1.105 -> 5304 | I25: 1000 | J25: =I25*A25 -> 3000 | K25: =F25-J25 -> 2304 | L25: =IFERROR(K25/E25, 0) -> 0.48
A26: 1 | B26: ATADO | C26: ALBAHACA | D26: 1500 | E26: =A26*D26 -> 1500 | F26: =E26*1.105 -> 1657.5 | I26: 1000 | J26: =I26*A26 -> 1000 | K26: =F26-J26 -> 657.5 | L26: =IFERROR(K26/E26, 0) -> 0.43833333
A27: 5 | B27: UNIDAD | C27: BROCOLI | D27: 3000 | E27: =A27*D27 -> 15000 | F27: =E27*1.105 -> 16575 | I27: =18000/8 -> 2250 | J27: =I27*A27 -> 11250 | K27: =F27-J27 -> 5325 | L27: =IFERROR(K27/E27, 0) -> 0.355
A28: 1 | B28: CAJON | C28: MANZANA ROJA | D28: 60000 | E28: =A28*D28 -> 60000 | F28: =E28*1.105 -> 66300 | I28: 50000 | J28: =I28*A28 -> 50000 | K28: =F28-J28 -> 16300 | L28: =IFERROR(K28/E28, 0) -> 0.27166667
A29: 1 | B29: CAJON | C29: MANZANA VERDE | D29: 72000 | E29: =A29*D29 -> 72000 | F29: =E29*1.105 -> 79560 | I29: 65000 | J29: =I29*A29 -> 65000 | K29: =F29-J29 -> 14560 | L29: =IFERROR(K29/E29, 0) -> 0.20222222
A30: 2 | B30: CAJON | C30: NARANJA | D30: 28000 | E30: =A30*D30 -> 56000 | F30: =E30*1.105 -> 61880 | I30: 24000 | J30: =I30*A30 -> 48000 | K30: =F30-J30 -> 13880 | L30: =IFERROR(K30/E30, 0) -> 0.24785714
A31: 10 | B31: KG | C31: PERA | D31: 3000 | E31: =A31*D31 -> 30000 | F31: =E31*1.105 -> 33150 | I31: =20000/9 -> 2222.2222 | J31: =I31*A31 -> 22222.222 | K31: =F31-J31 -> 10927.778 | L31: =IFERROR(K31/E31, 0) -> 0.36425926
A32: 15.4 | B32: KG | C32: BANANA | D32: 3000 | E32: =A32*D32 -> 46200 | F32: =E32*1.105 -> 51051 | I32: =36000/17 -> 2117.6471 | J32: =I32*A32 -> 32611.765 | K32: =F32-J32 -> 18439.235 | L32: =IFERROR(K32/E32, 0) -> 0.39911765
A33: 4 | B33: KG | C33: POMELO | D33: 3200 | E33: =A33*D33 -> 12800 | F33: =E33*1.105 -> 14144 | I33: =32000/15 -> 2133.3333 | J33: =I33*A33 -> 8533.3333 | K33: =F33-J33 -> 5610.6667 | L33: =IFERROR(K33/E33, 0) -> 0.43833333
A34: 0.5 | B34: CAJON | C34: HUEVO N1 | D34: 54000 | E34: =A34*D34 -> 27000 | F34: =E34*1.21 -> 32670 | I34: 50000 | J34: =I34*A34 -> 25000 | K34: =F34-J34 -> 7670 | L34: =IFERROR(K34/E34, 0) -> 0.28407407
E36: =SUM(E6:E34) -> 539720 | F36: =SUM(F6:F34) -> 599225.6 | K36: =SUM(K6:K34) -> 180023.99 | L36: =K36/F36 -> 0.30042774
A42: COLEGIO SWORM JUNIOR COLLAGE | PACHECO | E42: rto: 12 | F42: 46120 | I42: COMPRA
A44: CANTIDAD | B44: UNIDAD | C44: PRODUCTO | D44: PRECIO | E44: TOTAL | F44: TOTAL + IVA | I44: COSTO | J44: TOTAL | K44: DIFERENCIA
A45: 10 | B45: KG | C45: TOMATE PERITA | D45: 2400 | E45: =A45*D45 -> 24000 | F45: =E45*1.105 -> 26520 | I45: =22000/15 -> 1466.6667 | J45: =I45*A45 -> 14666.667 | K45: =F45-J45 -> 11853.333 | L45: =IFERROR(K45/E45, 0) -> 0.49388889
A46: 6 | B46: ATADO | C46: ESPINACA | D46: 1700 | E46: =A46*D46 -> 10200 | F46: =E46*1.105 -> 11271 | I46: =13000/12 -> 1083.3333 | J46: =I46*A46 -> 6500 | K46: =F46-J46 -> 4771 | L46: =IFERROR(K46/E46, 0) -> 0.4677451
A47: 2 | B47: UNIDAD | C47: BROCOLI | D47: 3000 | E47: =A47*D47 -> 6000 | F47: =E47*1.105 -> 6630 | I47: =18000/8 -> 2250 | J47: =I47*A47 -> 4500 | K47: =F47-J47 -> 2130 | L47: =IFERROR(K47/E47, 0) -> 0.355
A48: 1.5 | B48: KG | C48: MORRON ROJO | D48: 3200 | E48: =A48*D48 -> 4800 | F48: =E48*1.105 -> 5304 | I48: =14000/7 -> 2000 | J48: =I48*A48 -> 3000 | K48: =F48-J48 -> 2304 | L48: =IFERROR(K48/E48, 0) -> 0.48
A49: 10 | B49: ATADO | C49: RUCULA | D49: 600 | E49: =A49*D49 -> 6000 | F49: =E49*1.105 -> 6630 | I49: =10000/24 -> 416.66667 | J49: =I49*A49 -> 4166.6667 | K49: =F49-J49 -> 2463.3333 | L49: =IFERROR(K49/E49, 0) -> 0.41055556
A50: 3 | B50: KG | C50: ZAPALLITO REDONDO | D50: 1400 | E50: =A50*D50 -> 4200 | F50: =E50*1.105 -> 4641 | I50: =15000/14 -> 1071.4286 | J50: =I50*A50 -> 3214.2857 | K50: =F50-J50 -> 1426.7143 | L50: =IFERROR(K50/E50, 0) -> 0.33969388
...

Sheet 09-04-2026 
A3: COLCAR | E3: rto: 16 | F3: 46121 | I3: COMPRA
A5: CANTIDAD | B5: UNIDAD | C5: PRODUCTO | D5: PRECIO | E5: TOTAL | F5: TOTAL + IVA | I5: COSTO | J5: TOTAL | K5: DIFERENCIA
A6: 3 | B6: BOLSA | C6: CEBOLLA | D6: 14000 | E6: =A6*D6 -> 42000 | F6: =E6*1.105 -> 46410 | I6: 10000 | J6: =I6*A6 -> 30000 | K6: =F6-J6 -> 16410 | L6: =IFERROR(K6/E6, 0) -> 0.39071429
A7: 2 | B7: CAJON | C7: MORRON ROJO | D7: 18000 | E7: =A7*D7 -> 36000 | F7: =E7*1.105 -> 39780 | I7: 15000 | J7: =I7*A7 -> 30000 | K7: =F7-J7 -> 9780 | L7: =IFERROR(K7/E7, 0) -> 0.27166667
A8: 4 | B8: BOLSA | C8: ZANAHORIA INDUSTRIAL | D8: 16000 | E8: =A8*D8 -> 64000 | F8: =E8*1.105 -> 70720 | I8: 10000 | J8: =I8*A8 -> 40000 | K8: =F8-J8 -> 30720 | L8: =IFERROR(K8/E8, 0) -> 0.48
A9: 2 | B9: CAJON | C9: ZAPALLITO REDONDO | D9: 28000 | E9: =A9*D9 -> 56000 | F9: =E9*1.105 -> 61880 | I9: 25000 | J9: =I9*A9 -> 50000 | K9: =F9-J9 -> 11880 | L9: =IFERROR(K9/E9, 0) -> 0.21214286
A10: 2 | B10: BOLSA | C10: ANCO | D10: 13000 | E10: =A10*D10 -> 26000 | F10: =E10*1.105 -> 28730 | I10: 8000 | J10: =I10*A10 -> 16000 | K10: =F10-J10 -> 12730 | L10: =IFERROR(K10/E10, 0) -> 0.48961538
A11: 2 | B11: BOLSA | C11: BATATA | D11: 16000 | E11: =A11*D11 -> 32000 | F11: =E11*1.105 -> 35360 | I11: 11000 | J11: =I11*A11 -> 22000 | K11: =F11-J11 -> 13360 | L11: =IFERROR(K11/E11, 0) -> 0.4175
A12: 2 | B12: CAJON | C12: REMOLACHA | D12: 17000 | E12: =A12*D12 -> 34000 | F12: =E12*1.105 -> 37570 | I12: 14000 | J12: =I12*A12 -> 28000 | K12: =F12-J12 -> 9570 | L12: =IFERROR(K12/E12, 0) -> 0.28147059
A13: 4 | B13: CAJON | C13: ACELGA | D13: 11000 | E13: =A13*D13 -> 44000 | F13: =E13*1.105 -> 48620 | I13: 7000 | J13: =I13*A13 -> 28000 | K13: =F13-J13 -> 20620 | L13: =IFERROR(K13/E13, 0) -> 0.46863636
A14: 8 | B14: BOLSA | C14: PAPA CEPILLADA | D14: 15000 | E14: =A14*D14 -> 120000 | F14: =E14*1.105 -> 132600 | I14: 11500 | J14: =I14*A14 -> 92000 | K14: =F14-J14 -> 40600 | L14: =IFERROR(K14/E14, 0) -> 0.33833333
A15: 1 | B15: CAJON | C15: TOMATE | D15: 12000 | E15: =A15*D15 -> 12000 | F15: =E15*1.105 -> 13260 | I15: 8000 | J15: =I15*A15 -> 8000 | K15: =F15-J15 -> 5260 | L15: =IFERROR(K15/E15, 0) -> 0.43833333
A16: 1 | B16: CAJON | C16: CHOCLO | D16: 16000 | E16: =A16*D16 -> 16000 | F16: =E16*1.105 -> 17680 | I16: 13000 | J16: =I16*A16 -> 13000 | K16: =F16-J16 -> 4680 | L16: =IFERROR(K16/E16, 0) -> 0.2925
A17: 3 | B17: CAJON | C17: MANDARINA | D17: 20000 | E17: =A17*D17 -> 60000 | F17: =E17*1.105 -> 66300 | I17: 13000 | J17: =I17*A17 -> 39000 | K17: =F17-J17 -> 27300 | L17: =IFERROR(K17/E17, 0) -> 0.455
A18: 0.5 | B18: CAJON | C18: HUEVO N2 | D18: 50000 | E18: =A18*D18 -> 25000 | F18: =E18*1.21 -> 30250 | I18: 50000 | J18: =I18*A18 -> 25000 | K18: =F18-J18 -> 5250 | L18: =IFERROR(K18/E18, 0) -> 0.21
E20: =SUM(E6:E18) -> 567000 | F20: =SUM(F6:F18) -> 629160 | K20: =SUM(K6:K18) -> 208160 | L20: =K20/F20 -> 0.33085384
A26: FV | E26: rto: 252 | F26: 46121 | I26: COMPRA
A28: CANTIDAD | B28: UNIDAD | C28: PRODUCTO | D28: PRECIO | E28: TOTAL | F28: TOTAL + IVA | I28: COSTO | J28: TOTAL | K28: DIFERENCIA
A29: 4 | B29: CAJON | C29: BANANA | D29: 40000 | E29: =A29*D29 -> 160000 | F29: =E29*1.105 -> 176800 | I29: 36000 | J29: =I29*A29 -> 144000 | K29: =F29-J29 -> 32800 | L29: =IFERROR(K29/E29, 0) -> 0.205
A30: 4 | B30: CAJON | C30: NARANJA | D30: 26000 | E30: =A30*D30 -> 104000 | F30: =E30*1.105 -> 114920 | I30: 24000 | J30: =I30*A30 -> 96000 | K30: =F30-J30 -> 18920 | L30: =IFERROR(K30/E30, 0) -> 0.18192308
A31: 2 | B31: CAJA | C31: MANZANA GRANNY | D31: 60000 | E31: =A31*D31 -> 120000 | F31: =E31*1.105 -> 132600 | I31: 20000 | J31: =I31*A31 -> 40000 | K31: =F31-J31 -> 92600 | L31: =IFERROR(K31/E31, 0) -> 0.77166667
A32: 2 | B32: CAJA | C32: PERA | D32: 25000 | E32: =A32*D32 -> 50000 | F32: =E32*1.105 -> 55250 | I32: =17000 -> 17000 | J32: =I32*A32 -> 34000 | K32: =F32-J32 -> 21250 | L32: =IFERROR(K32/E32, 0) -> 0.425
A33: 3 | B33: CAJA | C33: MANZNA RED | D33: 45000 | E33: =A33*D33 -> 135000 | F33: =E33*1.105 -> 149175 | I33: =88000/3 -> 29333.333 | J33: =I33*A33 -> 88000 | K33: =F33-J33 -> 61175 | L33: =IFERROR(K33/E33, 0) -> 0.45314815
A34: 1 | B34: CAJON | C34: BANANA | D34: 40000 | E34: =A34*D34 -> 40000 | F34: =E34*1.105 -> 44200 | G34: BOLSA | J34: =I34*A34 -> 0 | K34: =F34-J34 -> 44200 | L34: =IFERROR(K34/E34, 0) -> 1.105
A35: 1 | B35: CAJON | C35: NARANJA | D35: 26000 | E35: =A35*D35 -> 26000 | F35: =E35*1.105 -> 28730 | G35: BOLSA | J35: =I35*A35 -> 0 | K35: =F35-J35 -> 28730 | L35: =IFERROR(K35/E35, 0) -> 1.105
A36: 1 | B36: CAJON | C36: MANZANA GRANNY | D36: 60000 | E36: =A36*D36 -> 60000 | F36: =E36*1.105 -> 66300 | G36: BOLSA | J36: =I36*A36 -> 0 | K36: =F36-J36 -> 66300 | L36: =IFERROR(K36/E36, 0) -> 1.105
A37: 1 | B37: CAJON | C37: PERA | D37: 25000 | E37: =A37*D37 -> 25000 | F37: =E37*1.105 -> 27625 | G37: BOLSA | J37: =I37*A37 -> 0 | K37: =F37-J37 -> 27625 | L37: =IFERROR(K37/E37, 0) -> 1.105
A38: 1 | B38: CAJON | C38: MANZANA | D38: 45000 | E38: =A38*D38 -> 45000 | F38: =E38*1.105 -> 49725 | G38: BOLSA | J38: =I38*A38 -> 0 | K38: =F38-J38 -> 49725 | L38: =IFERROR(K38/E38, 0) -> 1.105
E40: =SUM(E29:E38) -> 765000 | F40: =SUM(F29:F38) -> 845325 | K40: =SUM(K29:K38) -> 443325 | L40: =K40/F40 -> 0.52444326
A43: COLEGIO SJCB - VIRREY DEL PINO 3299 | E43: rto: 18 | F43: 46121 | I43: COMPRA
A45: CANTIDAD | B45: UNIDAD | C45: PRODUCTO | D45: PRECIO | E45: TOTAL | F45: TOTAL + IVA | I45: COSTO | J45: TOTAL | K45: DIFERENCIA
A46: 1 | B46: BOLSA | C46: PAPA LAVADA | D46: 25000 | E46: =A46*D46 -> 25000 | F46: =E46*1.105 -> 27625 | I46: 20000 | J46: =I46*A46 -> 20000 | K46: =F46-J46 -> 7625 | L46: =IFERROR(K46/E46, 0) -> 0.305
A47: 0.5 | B47: CAJON | C47: NARANJA JUGO | D47: 28000 | E47: =A47*D47 -> 14000 | F47: =E47*1.105 -> 15470 | I47: 24000 | J47: =I47*A47 -> 12000 | K47: =F47-J47 -> 3470 | L47: =IFERROR(K47/E47, 0) -> 0.24785714
E49: =SUM(E46:E47) -> 39000 | F49: =SUM(F46:F47) -> 43095 | K49: =SUM(K46:K47) -> 11095 | L49: =K49/F49 -> 0.25745446
A52: CATERING | D52: rto: 19 | E52: 46273
A54: CANTIDAD | B54: UNIDAD | C54: PRODUCTO | D54: PRECIO | E54: TOTAL | I54: PRECIO | J54: TOTAL | K54: DIFERENCIA
A55: 2 | B55: ATADO | C55: VERDEO | D55: 3500 | E55: =A55*D55 -> 7000 | I55: 2000 | J55: =I55*A55 -> 4000 | K55: =E55-J55 -> 3000 | L55: =K55/E55 -> 0.42857143
A56: 1 | B56: CAJON | C56: BERENJENA | D56: 10000 | E56: =A56*D56 -> 10000 | I56: 6000 | J56: =I56*A56 -> 6000 | K56: =E56-J56 -> 4000 | L56: =K56/E56 -> 0.4
A57: 3 | B57: CAJON | C57: BROCOLI | D57: 18000 | E57: =A57*D57 -> 54000 | I57: 15000 | J57: =I57*A57 -> 45000 | K57: =E57-J57 -> 9000 | L57: =K57/E57 -> 0.16666667
A58: 2 | B58: BOLSA | C58: ZANAHORIA INDUSTRIAL | D58: 14000 | E58: =A58*D58 -> 28000 | I58: 10000 | J58: =I58*A58 -> 20000 | K58: =E58-J58 -> 8000 | L58: =K58/E58 -> 0.28571429
...

Sheet 10-04-2026
A3: COLEGIO SJCB - VIRREY DEL PINO 3299 | C3: rto: 19 | D3: 10-Apr | G3: COMPRA
A5: CANTIDAD | B5: UNIDAD | C5: PRODUCTO | D5: PRECIO | E5: TOTAL | F5: TOTAL + IVA | I5: COSTO | J5: TOTAL | K5: DIFERENCIA
A6: 0.20 | B6: KG | C6: CEBOLLA DE VERDEO | D6: $ 4,500.00 | E6: $ 900.00 | F6: $ 994.50 | I6: $ 1,500.00 | J6: $ 300.00 | K6: $ 694.50 | L6: 77.17%
A7: 1.00 | B7: ATADO | C7: ALBAHACA | D7: $ 1,500.00 | E7: $ 1,500.00 | F7: $ 1,657.50 | I7: $ 666.00 | J7: $ 666.00 | K7: $ 991.50 | L7: 66.10%
A8: 4.00 | B8: KG | C8: BANANA | D8: $ 3,000.00 | E8: $ 12,000.00 | F8: $ 13,260.00 | I8: $ 2,120.00 | J8: $ 8,480.00 | K8: $ 4,780.00 | L8: 39.83%
A9: 2.00 | B9: UNIDAD | C9: BROCOLI | D9: $ 3,200.00 | E9: $ 6,400.00 | F9: $ 7,072.00 | I9: $ 2,250.00 | J9: $ 4,500.00 | K9: $ 2,572.00 | L9: 40.19%
A10: 1.00 | B10: BOLSA | C10: CALABAZA | D10: $ 13,000.00 | E10: $ 13,000.00 | F10: $ 14,365.00 | I10: $ 8,000.00 | J10: $ 8,000.00 | K10: $ 6,365.00 | L10: 48.96%
A11: 1.50 | B11: KG | C11: CEBOLLA MORADA | D11: $ 1,600.00 | E11: $ 2,400.00 | F11: $ 2,652.00 | I11: $ 1,000.00 | J11: $ 1,500.00 | K11: $ 1,152.00 | L11: 48.00%
A12: 0.60 | B12: KG | C12: CHAMPIGNON | D12: $ 21,000.00 | E12: $ 12,600.00 | F12: $ 13,923.00 | I12: $ 16,000.00 | J12: $ 9,600.00 | K12: $ 4,323.00 | L12: 34.31%
A13: 1.00 | B13: KG | C13: CHAUCHA PLANA | D13: $ 4,000.00 | E13: $ 4,000.00 | F13: $ 4,420.00 | I13: $ 1,720.00 | J13: $ 1,720.00 | K13: $ 2,700.00 | L13: 67.50%
A14: 5.00 | B14: ATADO | C14: ESPINACA | D14: $ 1,700.00 | E14: $ 8,500.00 | F14: $ 9,392.50 | I14: $ 1,200.00 | J14: $ 6,000.00 | K14: $ 3,392.50 | L14: 39.91%
A15: 1.00 | B15: KG | C15: FRUTILLA | D15: $ 11,000.00 | E15: $ 11,000.00 | F15: $ 12,155.00 | I15: $ 10,000.00 | J15: $ 10,000.00 | K15: $ 2,155.00 | L15: 19.59%
A16: 4.00 | B16: KG | C16: MANDARINA | D16: $ 1,200.00 | E16: $ 4,800.00 | F16: $ 5,304.00 | I16: $ 640.00 | J16: $ 2,560.00 | K16: $ 2,744.00 | L16: 57.17%
A17: 0.50 | B17: CAJON | C17: MANZANA ROJA | D17: $ 60,000.00 | E17: $ 30,000.00 | F17: $ 33,150.00 | I17: $ 50,000.00 | J17: $ 25,000.00 | K17: $ 8,150.00 | L17: 27.17%
... A36: 1.50 | B36: KG | C36: LECHUGA CRIOLLA | D36: $ 6,000.00 | E36: $ 9,000.00 | F36: $ 9,945.00 | I36: $ 5,000.00 | J36: $ 7,500.00 | K36: $ 2,445.00 | L36: 27.17%
E38: $ 318,200.00 | F38: $ 351,611.00 | K38: $ 120,016.67 | L38: 34.13%
A43: COLEGIO ST. MATTHEWS - MOLDES 1469, BELGRANO | C43: rto: 17 | D43: 10-Apr | G43: COMPRA
A45: CANTIDAD | B45: UNIDAD | C45: PRODUCTO | D45: PRECIO | E45: TOTAL | F45: TOTAL + IVA | I45: COSTO | J45: TOTAL | K45: DIFERENCIA
A46: 2.00 | B46: BOLSA | C46: PAPA BLANCA | D46: $ 25,000.00 | E46: $ 50,000.00 | F46: $ 55,250.00 | I46: $ 19,500.00 | J46: $ 39,000.00 | K46: $ 16,250.00 | L46: 32.50%
A47: 1.00 | B47: BOLSA | C47: ZANAHORIA | D47: $ 12,000.00 | E47: $ 12,000.00 | F47: $ 13,260.00 | I47: $ 7,000.00 | J47: $ 7,000.00 | K47: $ 6,260.00 | L47: 52.17%
A48: 8.00 | B48: KG | C48: TOMATE PERITA | D48: $ 2,400.00 | E48: $ 19,200.00 | F48: $ 21,216.00 | I48: $ 1,350.00 | J48: $ 10,800.00 | K48: $ 10,416.00 | L48: 54.25%
A49: 4.00 | B49: KG | C49: ZAPALLITO REDONDO | D49: $ 2,400.00 | E49: $ 9,600.00 | F49: $ 10,608.00 | I49: $ 1,650.00 | J49: $ 6,600.00 | K49: $ 4,008.00 | L49: 41.75%
A50: 6.00 | B50: ATADO | C50: ESPINACA | D50: $ 1,700.00 | E50: $ 10,200.00 | F50: $ 11,271.00 | I50: $ 1,200.00 | J50: $ 7,200.00 | K50: $ 4,071.00 | L50: 39.91%
A51: 1.00 | B51: KG | C51: MORRON ROJO | D51: $ 3,200.00 | E51: $ 3,200.00 | F51: $ 3,536.00 | I51: $ 1,860.00 | J51: $ 1,860.00 | K51: $ 1,676.00 | L51: 52.38%
A52: 0.50 | B52: KG | C52: MORRON VERDE | D52: $ 2,400.00 | E52: $ 1,200.00 | F52: $ 1,326.00 | I52: $ 1,450.00 | J52: $ 725.00 | K52: $ 601.00 | L52: 50.08%
A53: 1.00 | B53: KG | C53: CHAUCHA PLANA | D53: $ 4,000.00 | E53: $ 4,000.00 | F53: $ 4,420.00 | I53: $ 1,720.00 | J53: $ 1,720.00 | K53: $ 2,700.00 | L53: 67.50%
A54: 1.00 | B54: KG | C54: BERENJENA | D54: $ 2,000.00 | E54: $ 2,000.00 | F54: $ 2,210.00 | I54: $ 850.00 | J54: $ 850.00 | K54: $ 1,360.00 | L54: 68.00%
A55: 1.00 | B55: KG | C55: ZUCCINI | D55: $ 2,600.00 | E55: $ 2,600.00 | F55: $ 2,873.00 | I55: $ 2,150.00 | J55: $ 2,150.00 | K55: $ 723.00 | L55: 27.81%
A56: 10.00 | B56: ATADO | C56: RUCULA | D56: $ 600.00 | E56: $ 6,000.00 | F56: $ 6,630.00 | I56: $ 375.00 | J56: $ 3,750.00 | K56: $ 2,880.00 | L56: 48.00%
A57: 0.40 | B57: KG | C57: CHAMPIGNON | D57: $ 21,000.00 | E57: $ 8,400.00 | F57: $ 9,282.00 | I57: $ 16,000.00 | J57: $ 6,400.00 | K57: $ 2,882.00 | L57: 34.31%
... A63: 1.00 | B63: KG | C63: FRUTILLA | D63: $ 11,000.00 | E63: $ 11,000.00 | F63: $ 12,155.00 | I63: $ 10,000.00 | J63: $ 10,000.00 | K63: $ 2,155.00 | L63: 19.59%
E65: $ 210,300.00 | F65: $ 232,381.50 | K65: $ 79,436.50 | L65: 34.18%
A68: COLEGIO SAN JAVIER - JOSE A CABRERA 5901 | C68: rto: 17 | D68: 10-Apr | G68: COMPRA
A70: CANTIDAD | B70: UNIDAD | C70: PRODUCTO | D70: PRECIO | E70: TOTAL | F70: TOTAL + IVA | I70: COSTO | J70: TOTAL | K70: DIFERENCIA
A71: 2.00 | B71: UNIDAD | C71: AJO | D71: $ 900.00 | E71: $ 1,800.00 | F71: $ 1,989.00 | I71: $ 460.00 | J71: $ 920.00 | K71: $ 1,069.00 | L71: 59.39%
A72: 1.00 | B72: ATADO | C72: ALBAHACA | D72: $ 1,500.00 | E72: $ 1,500.00 | F72: $ 1,657.50 | I72: $ 666.00 | J72: $ 666.00 | K72: $ 991.50 | L72: 66.10%
A73: 5.00 | B73: KG | C73: BANANA | D73: $ 3,000.00 | E73: $ 15,000.00 | F73: $ 16,575.00 | I73: $ 2,120.00 | J73: $ 10,600.00 | K73: $ 5,975.00 | L73: 39.83%
A74: 2.00 | B74: KG | C74: BATATA | D74: $ 1,600.00 | E74: $ 3,200.00 | F74: $ 3,536.00 | I74: $ 1,200.00 | J74: $ 2,400.00 | K74: $ 1,136.00 | L74: 35.50%
A75: 1.00 | B75: UNIDAD | C75: BROCOLI | D75: $ 3,200.00 | E75: $ 3,200.00 | F75: $ 3,536.00 | I75: $ 2,250.00 | J75: $ 2,250.00 | K75: $ 1,286.00 | L75: 40.19%
A76: 2.00 | B76: BOLSA | C76: PAPA BLANCA | D76: $ 25,000.00 | E76: $ 50,000.00 | F76: $ 55,250.00 | I76: $ 19,500.00 | J76: $ 39,000.00 | K76: $ 16,250.00 | L76: 32.50%
...

Sheet 13-04-2026 
A4: LA MARQUESA | D4: rto: 28 | E4: 46125
A6: CANTIDAD | B6: UNIDAD | C6: PRODUCTO | D6: PRECIO | E6: TOTAL | I6: PRECIO | J6: TOTAL | K6: DIFERENCIA
A7: 1 | B7: ATADO | C7: ALBAHACA | D7: 1500 | E7: =A7*D7 -> 1500 | I7: =10000/12 -> 833.33333 | J7: =I7*A7 -> 833.33333 | K7: =E7-J7 -> 666.66667 | L7: =K7/E7 -> 0.44444444
A8: 2 | B8: KG | C8: BANANA ECUADOR | D8: 3000 | E8: =A8*D8 -> 6000 | I8: =28000/17 -> 1647.0588 | J8: =I8*A8 -> 3294.1176 | K8: =E8-J8 -> 2705.8824 | L8: =K8/E8 -> 0.45098039
A9: 0.5 | B9: KG | C9: CHAMPIGNON | D9: 21000 | E9: =A9*D9 -> 10500 | I9: =16000 -> 16000 | J9: =I9*A9 -> 8000 | K9: =E9-J9 -> 2500 | L9: =K9/E9 -> 0.23809524
A10: 1 | B10: CAJON | C10: ESPINACA | D10: 17000 | E10: =A10*D10 -> 17000 | I10: 13000 | J10: =I10*A10 -> 13000 | K10: =E10-J10 -> 4000 | L10: =K10/E10 -> 0.23529412
A11: 3 | B11: CAJON | C11: HUEVO | D11: 55000 | E11: =A11*D11 -> 165000 | I11: 50000 | J11: =I11*A11 -> 150000 | K11: =E11-J11 -> 15000 | L11: =K11/E11 -> 0.090909091
A12: 0.5 | B12: KG | C12: JENGIBRE | D12: 11000 | E12: =A12*D12 -> 5500 | I12: 7000 | J12: =I12*A12 -> 3500 | K12: =E12-J12 -> 2000 | L12: =K12/E12 -> 0.36363636
A13: 1 | B13: KG | C13: KIWI | D13: 8600 | E13: =A13*D13 -> 8600 | I13: 6100 | J13: =I13*A13 -> 6100 | K13: =E13-J13 -> 2500 | L13: =K13/E13 -> 0.29069767
A14: 2 | B14: KG | C14: LIMA | D14: 4000 | E14: =A14*D14 -> 8000 | I14: 2000 | J14: =I14*A14 -> 4000 | K14: =E14-J14 -> 4000 | L14: =K14/E14 -> 0.5
A15: 1 | B15: CAJON | C15: LIMON | D15: 28000 | E15: =A15*D15 -> 28000 | I15: 16000 | J15: =I15*A15 -> 16000 | K15: =E15-J15 -> 12000 | L15: =K15/E15 -> 0.42857143
A16: 1 | B16: KG | C16: MANZANA VERDE | D16: 4500 | E16: =A16*D16 -> 4500 | I16: =60000/17 -> 3529.4118 | J16: =I16*A16 -> 3529.4118 | K16: =E16-J16 -> 970.58824 | L16: =K16/E16 -> 0.21568627
A17: 1 | B17: CAJON | C17: NARANJA | D17: 27000 | E17: =A17*D17 -> 27000 | I17: 16000 | J17: =I17*A17 -> 16000 | K17: =E17-J17 -> 11000 | L17: =K17/E17 -> 0.40740741
A18: 4 | B18: ATADO | C18: PUERRO | D18: 5000 | E18: =A18*D18 -> 20000 | I18: 2000 | J18: =I18*A18 -> 8000 | K18: =E18-J18 -> 12000 | L18: =K18/E18 -> 0.6
A19: 0.5 | B19: CAJON | C19: TOMATE REDONDO | D19: 14000 | E19: =A19*D19 -> 7000 | I19: =7000 -> 7000 | J19: =I19*A19 -> 3500 | K19: =E19-J19 -> 3500 | L19: =K19/E19 -> 0.5
A20: 3 | B20: KG | C20: ANCO | D20: 1000 | E20: =A20*D20 -> 3000 | I20: =8000/15 -> 533.33333 | J20: =I20*A20 -> 1600 | K20: =E20-J20 -> 1400 | L20: =K20/E20 -> 0.46666667
A21: 1 | B21: KG | C21: CIRUELA | D21: 4500 | E21: =A21*D21 -> 4500 | I21: =12120/3 -> 4040 | J21: =I21*A21 -> 4040 | K21: =E21-J21 -> 460 | L21: =K21/E21 -> 0.10222222
E23: =SUM(E7:E21) -> 316100 | K23: =SUM(K7:K21) -> 74703.137 | L23: =K23/E23 -> 0.23632755
A26: QUINQUELA | D26: rto: 12 | E26: 46125
A28: CANTIDAD | B28: UNIDAD | C28: PRODUCTO | D28: PRECIO | E28: TOTAL | I28: PRECIO | J28: TOTAL | K28: DIFERENCIA
A29: 1 | B29: ATADO | C29: ALBAHACA | D29: 1500 | E29: =A29*D29 -> 1500 | I29: =10000/12 -> 833.33333 | J29: =I29*A29 -> 833.33333 | K29: =E29-J29 -> 666.66667 | L29: =K29/E29 -> 0.44444444
A30: 2 | B30: KG | C30: BANANA ECUADOR | D30: 3000 | E30: =A30*D30 -> 6000 | I30: =28000/17 -> 1647.0588 | J30: =I30*A30 -> 3294.1176 | K30: =E30-J30 -> 2705.8824 | L30: =K30/E30 -> 0.45098039
A31: 1 | B31: KG | C31: MANZANA VERDE | D31: 4500 | E31: =A31*D31 -> 4500 | I31: =60000/17 -> 3529.4118 | J31: =I31*A31 -> 3529.4118 | K31: =E31-J31 -> 970.58824 | L31: =K31/E31 -> 0.21568627
A32: 1 | B32: ATADO | C32: MENTA | D32: 3000 | E32: =A32*D32 -> 3000 | I32: 2000 | J32: =I32*A32 -> 2000 | K32: =E32-J32 -> 1000 | L32: =K32/E32 -> 0.33333333
A33: 1 | B33: CAJON | C33: NARANJA | D33: 27000 | E33: =A33*D33 -> 27000 | I33: 16000 | J33: =I33*A33 -> 16000 | K33: =E33-J33 -> 11000 | L33: =K33/E33 -> 0.40740741
A34: 1 | B34: KG | C34: RABANITO | D34: 1000 | E34: =A34*D34 -> 1000 | I34: =2000/3 -> 666.66667 | J34: =I34*A34 -> 666.66667 | K34: =E34-J34 -> 333.33333 | L34: =K34/E34 -> 0.33333333
E36: =SUM(E29:E34) -> 43000 | K36: =SUM(K29:K34) -> 16676.471 | L36: =K36/E36 -> 0.3878249
A40: COMO SIEMPRE LAGUNA | D40: rto: 46 | E40: 46125
A42: CANTIDAD | B42: UNIDAD | C42: PRODUCTO | D42: PRECIO | E42: TOTAL | I42: PRECIO | J42: TOTAL | K42: DIFERENCIA
A43: 10 | B43: KG | C43: LIMON | D43: 2400 | E43: =A43*D43 -> 24000 | I43: =16000/14 -> 1142.8571 | J43: =I43*A43 -> 11428.571 | K43: =E43-J43 -> 12571.429 | L43: =K43/E43 -> 0.52380952
A44: 10 | B44: KG | C44: NARANJA | D44: 1800 | E44: =A44*D44 -> 18000 | I44: =16000/15 -> 1066.6667 | J44: =I44*A44 -> 10666.667 | K44: =E44-J44 -> 7333.3333 | L44: =K44/E44 -> 0.40740741
A45: 8 | B45: KG | C45: POMELO | D45: 3000 | E45: =A45*D45 -> 24000 | I45: =32000/15 -> 2133.3333 | J45: =I45*A45 -> 17066.667 | K45: =E45-J45 -> 6933.3333 | L45: =K45/E45 -> 0.28888889
A46: 3 | B46: CAJON | C46: ESPINACA | D46: 17000 | E46: =A46*D46 -> 51000 | I46: 13000 | J46: =I46*A46 -> 39000 | K46: =E46-J46 -> 12000 | L46: =K46/E46 -> 0.23529412
A47: 6 | B47: KG | C47: TOMATE PERITA | D47: 2200 | E47: =A47*D47 -> 13200 | I47: =11000/15 -> 733.33333 | J47: =I47*A47 -> 4400 | K47: =E47-J47 -> 8800 | L47: =K47/E47 -> 0.66666667
A48: 2 | B48: BOLSA | C48: PAPA BLANCA | D48: 25000 | E48: =A48*D48 -> 50000 | I48: 18000 | J48: =I48*A48 -> 36000 | K48: =E48-J48 -> 14000 | L48: =K48/E48 -> 0.28
A49: 1.5 | B49: KG | C49: LECHUGA FRANCESA | D49: 4000 | E49: =A49*D49 -> 6000 | I49: 2000 | J49: =I49*A49 -> 3000 | K49: =E49-J49 -> 3000 | L49: =K49/E49 -> 0.5
A50: 7 | B50: KG | C50: ZANAHORIA | D50: 1300 | E50: =A50*D50 -> 9100 | I50: 750 | J50: =I50*A50 -> 5250 | K50: =E50-J50 -> 3850 | L50: =K50/E50 -> 0.42307692
A51: 1 | B51: ATADO | C51: APIO | D51: 2500 | E51: =A51*D51 -> 2500 | I51: =9000/8 -> 1125 | J51: =I51*A51 -> 1125 | K51: =E51-J51 -> 1375 | L51: =K51/E51 -> 0.55
A52: 3 | B52: KG | C52: BONIATO | D52: 2400 | E52: =A52*D52 -> 7200 | I52: =20000/11 -> 1818.1818 | J52: =I52*A52 -> 5454.5455 | K52: =E52-J52 -> 1745.4545 | L52: =K52/E52 -> 0.24242424
A53: 3 | B53: UNIDAD | C53: MANGO | D53: 3000 | E53: =A53*D53 -> 9000 | I53: =14000/10 -> 1400 | J53: =I53*A53 -> 4200 | K53: =E53-J53 -> 4800 | L53: =K53/E53 -> 0.53333333
...

Sheet 14-04-2026 
A3: COLEGIO WASHINGTON - LACROZE 1973 | E3: rto: 17 | F3: 46126 | I3: COMPRA
A5: CANTIDAD | B5: UNIDAD | C5: PRODUCTO | D5: PRECIO | E5: TOTAL | F5: TOTAL + IVA | I5: COSTO | J5: TOTAL | K5: DIFERENCIA
A6: 3 | B6: BOLSA | C6: PAPA BLANCA | D6: 25000 | E6: =A6*D6 -> 75000 | F6: =E6*1.105 -> 82875 | I6: 18000 | J6: =I6*A6 -> 54000 | K6: =F6-J6 -> 28875 | L6: =IFERROR(K6/E6, 0) -> 0.385
A7: 1 | B7: BOLSA | C7: CALABAZA | D7: 13000 | E7: =A7*D7 -> 13000 | F7: =E7*1.105 -> 14365 | I7: 8000 | J7: =I7*A7 -> 8000 | K7: =F7-J7 -> 6365 | L7: =IFERROR(K7/E7, 0) -> 0.48961538
A8: 1 | B8: BOLSA | C8: ZANAHORIA | D8: 12000 | E8: =A8*D8 -> 12000 | F8: =E8*1.105 -> 13260 | I8: 7000 | J8: =I8*A8 -> 7000 | K8: =F8-J8 -> 6260 | L8: =IFERROR(K8/E8, 0) -> 0.52166667
A9: 4 | B9: KG | C9: BATATA | D9: 1600 | E9: =A9*D9 -> 6400 | F9: =E9*1.105 -> 7072 | I9: =12000/11 -> 1090.9091 | J9: =I9*A9 -> 4363.6364 | K9: =F9-J9 -> 2708.3636 | L9: =IFERROR(K9/E9, 0) -> 0.42318182
A10: 5 | B10: KG | C10: CEBOLLA MORADA | D10: 1600 | E10: =A10*D10 -> 8000 | F10: =E10*1.105 -> 8840 | I10: 1000 | J10: =I10*A10 -> 5000 | K10: =F10-J10 -> 3840 | L10: =IFERROR(K10/E10, 0) -> 0.48
A11: 3 | B11: KG | C11: CEBOLLA | D11: 1200 | E11: =A11*D11 -> 3600 | F11: =E11*1.105 -> 3978 | I11: =13000/16 -> 812.5 | J11: =I11*A11 -> 2437.5 | K11: =F11-J11 -> 1540.5 | L11: =IFERROR(K11/E11, 0) -> 0.42791667
A12: 1 | B12: UNIDAD | C12: AJO | D12: 900 | E12: =A12*D12 -> 900 | F12: =E12*1.105 -> 994.5 | I12: 460 | J12: =I12*A12 -> 460 | K12: =F12-J12 -> 534.5 | L12: =IFERROR(K12/E12, 0) -> 0.59388889
A13: 5 | B13: KG | C13: ZAPALLITO REDONDO | D13: 2600 | E13: =A13*D13 -> 13000 | F13: =E13*1.105 -> 14365 | I13: =25000/14 -> 1785.7143 | J13: =I13*A13 -> 8928.5714 | K13: =F13-J13 -> 5436.4286 | L13: =IFERROR(K13/E13, 0) -> 0.41818681
A14: 5 | B14: KG | C14: POMELO | D14: 3000 | E14: =A14*D14 -> 15000 | F14: =E14*1.105 -> 16575 | I14: =32000/15 -> 2133.3333 | J14: =I14*A14 -> 10666.667 | K14: =F14-J14 -> 5908.3333 | L14: =IFERROR(K14/E14, 0) -> 0.39388889
A15: 16 | B15: KG | C15: TOMATE PERITA | D15: 1600 | E15: =A15*D15 -> 25600 | F15: =E15*1.105 -> 28288 | I15: =12000/15 -> 800 | J15: =I15*A15 -> 12800 | K15: =F15-J15 -> 15488 | L15: =IFERROR(K15/E15, 0) -> 0.605
A16: 3 | B16: UNIDAD | C16: PALTA | D16: 1000 | E16: =A16*D16 -> 3000 | F16: =E16*1.105 -> 3315 | I16: =20000/50 -> 400 | J16: =I16*A16 -> 1200 | K16: =F16-J16 -> 2115 | L16: =IFERROR(K16/E16, 0) -> 0.705
A17: 3 | B17: ATADO | C17: KALE | D17: 2000 | E17: =A17*D17 -> 6000 | F17: =E17*1.105 -> 6630 | I17: 1000 | J17: =I17*A17 -> 3000 | K17: =F17-J17 -> 3630 | L17: =IFERROR(K17/E17, 0) -> 0.605
A18: 0.5 | B18: ATADO | C18: PUERRO | D18: 5000 | E18: =A18*D18 -> 2500 | F18: =E18*1.105 -> 2762.5 | I18: 2500 | J18: =I18*A18 -> 1250 | K18: =F18-J18 -> 1512.5 | L18: =IFERROR(K18/E18, 0) -> 0.605
A19: 1 | B19: ATADO | C19: ALBAHACA | D19: 1500 | E19: =A19*D19 -> 1500 | F19: =E19*1.105 -> 1657.5 | I19: 1000 | J19: =I19*A19 -> 1000 | K19: =F19-J19 -> 657.5 | L19: =IFERROR(K19/E19, 0) -> 0.43833333
A20: 1 | B20: ATADO | C20: CILANTRO | D20: 3000 | E20: =A20*D20 -> 3000 | F20: =E20*1.105 -> 3315 | I20: =2500/6 -> 416.66667 | J20: =I20*A20 -> 416.66667 | K20: =F20-J20 -> 2898.3333 | L20: =IFERROR(K20/E20, 0) -> 0.96611111
